Workbook
Name AsOfMonth: Assumptions!$C$6
Name breakeven_gap: Scenarios!$C$44
Name breakeven_revenue: Scenarios!$C$45
Name breakeven_uplift: Scenarios!$C$46
Name breakeven_volume: Scenarios!$C$47
Name bridge_ebitda: PVM!$F$84:$F$91
Name bridge_gm: PVM!$C$84:$C$89
Name budget_bias: Forecast!$D$110
Name budget_wape: Forecast!$D$109
Name ch_cube_years: Channels!$C$34:$E$38
Name ch_cube_yoy: Channels!$F$34:$H$38
Name ch_formulas: Channels!$C$6:$P$9
Name ch_total: Channels!$C$10:$P$10
Name checks_status: Checks!$G$6:$G$36
Name checks_summary: Checks!$B$2
Name cover_answers: Cover!$C$12:$C$16
Name ctrl_sales_revenue: Checks!$D$43
Name ctrl_sales_rows: Checks!$D$41
Name ctrl_sales_units: Checks!$D$42
Name dash_commentary: Dashboard!$B$11:$B$15
Name dash_movers: Dashboard!$B$57:$J$61
Name dash_scenarios: Dashboard!$K$57:$S$60
Name DAYSOF: _xlfn.LAMBDA(_xlpm.balance,_xlpm.flow,_xlpm.days,IF(_xlpm.flow=0,0,_xlpm.balance/_xlpm.flow*_xlpm.days))
Name FAVVAR: _xlfn.LAMBDA(_xlpm.actual,_xlpm.plan,_xlpm.is_cost,IF(_xlpm.is_cost,_xlpm.plan-_xlpm.actual,_xlpm.actual-_xlpm.plan))
Name fc_basis: Forecast!$B$6:$M$11
Name fc_cogs: Forecast!$D$57:$O$62
Name fc_ets: Forecast!$D$116:$O$116
Name fc_ets_gap: Forecast!$P$117
Name fc_freight: Forecast!$D$67:$O$72
Name fc_opex: Forecast!$D$85:$O$88
Name fc_opex_basis: Forecast!$B$16:$E$19
Name fc_opex0: Forecast!$D$77:$O$80
Name fc_revenue: Forecast!$D$47:$O$52
Name fc_u0: Forecast!$D$27:$O$32
Name fc_units: Forecast!$D$37:$O$42
Name FiscalYear: Assumptions!$C$7
Name FYStart: Assumptions!$C$8
Name ISCLOSED: _xlfn.LAMBDA(_xlpm.month,_xlpm.month<=AsOfMonth)
Name kpi_breakeven: Dashboard!$N$5
Name kpi_ccc: Dashboard!$Q$5
Name kpi_ebitda_fy: Dashboard!$K$5
Name kpi_ebitda_ytd: Dashboard!$H$5
Name kpi_gm_pct_ytd: Dashboard!$E$5
Name kpi_revenue_ytd: Dashboard!$B$5
Name LastDataMonth: Assumptions!$C$15
Name MONEY: _xlfn.LAMBDA(_xlpm.x,IF(ABS(_xlpm.x)>=999500,TEXT(_xlpm.x/1000000,"$#,##0.0")&"M",TEXT(_xlpm.x/1000,"$#,##0")&"K"))
Name MonthsClosed: Assumptions!$C$9
Name pnl_budget: PnL!$D$24:$O$37
Name pnl_fy_budget: PnL!$P$24:$P$37
Name pnl_fy_outlook: PnL!$P$7:$P$20
Name pnl_fy_py: PnL!$P$41:$P$54
Name pnl_fy_variance: PnL!$P$58:$P$71
Name pnl_months: PnL!$D$4:$O$4
Name pnl_outlook: PnL!$D$7:$O$20
Name pnl_py: PnL!$D$41:$O$54
Name pnl_summary: PnL!$P$7:$AB$20
Name pnl_variance: PnL!$D$58:$O$71
Name pvm_by_category: PVM!$B$64:$J$69
Name pvm_by_channel: PVM!$B$75:$J$78
Name pvm_month: PVM!$B$6:$W$29

Sheet Cover
B2: Kestrel Bay Provisions
B3: ="FY"&FiscalYear&" financial planning & analysis model" -> FY2026 financial planning & analysis model
B4: Budget vs actual · price-volume-mix · rolling 8+4 forecast · scenarios · working capital · channel economics
B6: A fictional BC specialty-food distributor: 24 products, 4 channels, 3 regions, 32 months of synthetic data. Every figure is a live formula, Power Query step or DAX measure over the source tables. Nothing is pasted in.
B7: Built by Kush Patel · github.com/KushPatel29/excel-fpa-model
B9: Model status | C9: =checks_summary -> All 31 checks pass | D9: Open the checks →
B11: Five questions it answers, live from the model
B12: Are we on budget, and if not, why? | C12: {="YTD revenue "&TEXT(PnL!Z8,"+0.0%;-0.0%")&" against budget, EBITDA "&TEXT(PnL!Z19,"+0.0%;-0.0%")&". Biggest gross-margin drag: "&INDEX({"volume","mix","price","unit cost"},_xlfn.XMATCH(MIN(PVM!P59:S59),PVM!P59:S59))&"."} -> YTD revenue +3.6% against budget, EBITDA -13.2%. Biggest gross-margin drag: unit cost. | D12: PVM →
B13: Where will the year land? | C13: {="EBITDA "&MONEY(PnL!P19)&" on the "&ScenarioName&" scenario, against a budget of "&MONEY(PnL!Q19)&"."} -> EBITDA $2.3M on the Base scenario, against a budget of $2.7M. | D13: Forecast →
B14: What would it take to hit budget? | C14: =IF(breakeven_gap>0,"A "&TEXT(breakeven_uplift,"0.0%")&" price rise on the open months, or "&TEXT(breakeven_volume,"0%")&" more volume.","Nothing: the outlook is at or above budget.") -> A 2.6% price rise on the open months, or 11% more volume. | D14: Scenarios →
B15: Where is cash tied up? | C15: {="A "&TEXT(WorkingCapital!O15,"0.0")&"-day cash cycle; "&MONEY(wc_at_risk_value)&" of stock sits above its shelf-life risk line."} -> A 20.6-day cash cycle; $58K of stock sits above its shelf-life risk line. | D15: WorkingCapital →
B16: Which channels earn the growth? | C16: {=_xlfn.LET(_xlpm.c,Channels!B6:B9,_xlpm.g,Channels!M6:M9,_xlpm.j,Channels!J6:J9,_xlpm.k,_xlfn.XMATCH(MAX(_xlpm.g),_xlpm.g),INDEX(_xlpm.c,_xlpm.k)&" grew cases most ("&TEXT(MAX(_xlpm.g),"+0%")&" vs budget) at "&TEXT(INDEX(_xlpm.j,_xlpm.k),"$0.00")&" contribution a case; "&INDEX(_xlpm.c,_xlfn.XMATCH(MAX(_xlpm.j),_xlpm.j))&" earns most, "&TEXT(MAX(_xlpm.j),"$0.00")&".")} -> Grocery Retail grew cases most (+16% vs budget) at $21.58 contribution a case; Online Direct earns most, $50.91. | D16: Channels →
B18: Sheets
B19: Sheet | C19: What it shows | D19: Excel on show
B20: Dashboard | C20: One page for the board: KPIs, bridges, scenarios and a written summary that rewrites itself. | D20: Formula-driven narrative, waterfall and combo charts, sparklines, LET, SORTBY, named LAMBDAs
B21: PnL | C21: Monthly P&L: outlook (actuals + forecast), budget, prior year, variances, YTD. | D21: SUMIFS over tables, FAVVAR / SAFEDIV LAMBDAs, conditional formatting, sparklines
B22: PVM | C22: Price-volume-mix on 24 segments; gross-margin and EBITDA bridges. | D22: Exact four-effect decomposition, XMATCH driver tags, waterfall
B23: Forecast | C23: 8+4 driver forecast by category, budget accuracy, statistical cross-check. | D23: XLOOKUP, WAPE and bias, FORECAST.ETS
B24: Scenarios | C24: Base / upside / downside, price × volume grid, tornado, gap to budget. | D24: What-if data tables (1- and 2-variable), data validation, SORTBY + HSTACK
B25: WorkingCapital | C25: DSO, DIO, DPO and the cash cycle; stock against shelf life. | D25: DAYSOF LAMBDA, trailing windows, data bars, risk flags
B26: Channels | C26: Channel economics by formula and by data model, reconciled. | D26: Power Pivot + DAX (TREATAS), PivotTable with slicers, CUBEVALUE
B27: Checks | C27: 31 controls that prove the model ties out. | D27: Reconciliations with a tolerance
B28: Assumptions | C28: Every input and scenario driver in one place. | D28: Named inputs, validation
B29: PQ_Budget | C29: The budget, unpivoted and priced. | D29: Power Query (M): unpivot, merges, types
B30: Data_Sales | C30: Source tables, loaded unchanged from the CSVs. | D30: Excel tables, structured references
B32: How to use it
B33: 1 Pick a scenario | C33: Scenarios!C4. Every sheet, chart and sentence follows.
B34: 2 Test your own view | C34: Price and volume overlays in Scenarios!C5:C6, on top of the scenario.
B35: 3 Re-cut from an earlier close | C35: Change the as-of month on Assumptions, then Data > Refresh All.
B36: 4 Explore the data model | C36: The slicers on Channels filter a PivotTable built on DAX measures.
B38: Conventions
B39: 0.015 | C39: Input: blue on yellow. Change these; everything else is calculated.
B40: 1234 | C40: Calculated: black. Links from another sheet are green on Scenarios.
B41: Forecast month | C41: Blue shading marks forecast months; unshaded months are actuals.
B42: +1,234 (1,234) | C42: Variances are signed so favourable is positive (green) and unfavourable is in brackets (red), for revenue and cost lines alike.

Sheet Dashboard
B1: ="Kestrel Bay Provisions: FY"&FiscalYear&" performance and outlook" -> Kestrel Bay Provisions: FY2026 performance and outlook
B2: ="Actuals through "&TEXT(AsOfMonth,"mmmm yyyy")&IF(MonthsClosed<12," · forecast "&TEXT(EDATE(AsOfMonth,1),"mmmm")&" to December","")&" · scenario: "&ScenarioName&" · "&checks_summary -> Actuals through August 2026 · forecast September to December · scenario: Base · All 31 checks pass
B4: REVENUE, YEAR TO DATE | E4: GROSS MARGIN %, YTD | H4: EBITDA, YEAR TO DATE | K4: EBITDA, FULL-YEAR OUTLOOK | N4: PRICE RISE TO REACH BUDGET | Q4: CASH CONVERSION CYCLE
B5: =PnL!W8 -> 31533631 | E5: =PnL!W11 -> 0.25853248 | H5: =PnL!W19 -> 1525950.5 | K5: =PnL!P19 -> 2319179.9 | N5: =breakeven_uplift -> 0.02598493 | Q5: =WorkingCapital!O15 -> 20.640439
B6: =PnL!Y8 -> 1110250.1 | E6: =PnL!Y11*100 -> -1.0002666 | H6: =PnL!Y19 -> -231735.84 | K6: =PnL!R19 -> -412477.17 | N6: ="on the "&(12-MonthsClosed)&" open months" -> on the 4 open months | Q6: =WorkingCapital!O15-WorkingCapital!C15 -> 1.8371229
K7: ="scenario: "&ScenarioName -> scenario: Base
B8: ="vs prior year "&TEXT(PnL!AB8,"+0.0%;-0.0%") -> vs prior year +10.9% | E8: ="budget "&TEXT(PnL!X11,"0.0%") -> budget 26.9% | H8: ="margin "&TEXT(PnL!W20,"0.0%")&" vs "&TEXT(PnL!X20,"0.0%")&" budget" -> margin 4.8% vs 5.8% budget | K8: {="budget "&MONEY(PnL!Q19)} -> budget $2.7M | N8: ="or "&TEXT(breakeven_volume,"0%")&" more volume" -> or 11% more volume | Q8: {=_xlfn.LET(_xlpm.u,WorkingCapital!G38:G43,_xlpm.c,WorkingCapital!B38:B43,INDEX(_xlpm.c,_xlfn.XMATCH(MAX(_xlpm.u),_xlpm.u))&": "&TEXT(MAX(_xlpm.u),"0%")&" of shelf life")} -> Cheese & Dairy: 58% of shelf life
B10: What the numbers say
B11: {="Revenue is "&MONEY(ABS(PnL!Y8))&IF(PnL!Y8>=0," ahead of"," behind")&" budget through "&TEXT(AsOfMonth,"mmmm")&" ("&TEXT(PnL!Z8,"+0.0%;-0.0%")&"), yet EBITDA is "&MONEY(ABS(PnL!Y19))&IF(PnL!Y19>=0," ahead"," behind")&" ("&TEXT(PnL!Z19,"+0.0%;-0.0%")&")."&IF(AND(PnL!Y8>0,PnL!Y19<0)," The growth has not reached the bottom line.","")} -> Revenue is $1.1M ahead of budget through August (+3.6%), yet EBITDA is $232K behind (-13.2%). The growth has not reached the bottom line.
B12: {=_xlfn.LET(_xlpm.v,PVM!C70,_xlpm.m,PVM!D70,_xlpm.pr,PVM!E70,_xlpm.c,PVM!F70,_xlpm.chm,PVM!D75:D78,_xlpm.chn,PVM!B75:B78,_xlpm.mixch,INDEX(_xlpm.chn,_xlfn.XMATCH(MIN(_xlpm.chm),_xlpm.chm)),_xlpm.low,INDEX(Channels!B6:B9,_xlfn.XMATCH(MIN(Channels!J6:J9),Channels!J6:J9)),_xlpm.cc,PVM!$F$64:$F$69,_xlpm.cp,PVM!$E$64:$E$69,_xlpm.cn,PVM!$B$64:$B$69,_xlpm.k,_xlfn.XMATCH(MIN(_xlpm.cc),_xlpm.cc),"Gross margin, year to date: volume "&SIGNMONEY(_xlpm.v)&", price "&SIGNMONEY(_xlpm.pr)&", mix "&SIGNMONEY(_xlpm.m)&", unit cost "&SIGNMONEY(_xlpm.c)&". Mix is negative because volume shifted toward "&_xlpm.mixch&IF(_xlpm.mixch=_xlpm.low,", the channel that earns least per case","")&"; "&INDEX(_xlpm.cn,_xlpm.k)&" costs rose"&IF(INDEX(_xlpm.cc,_xlpm.k)+INDEX(_xlpm.cp,_xlpm.k)<0," faster than its prices.","."))} -> Gross margin, year to date: volume +$290K, price +$238K, mix −$173K, unit cost −$372K. Mix is negative because volume shifted toward Grocery Retail, the channel that earns least per case; Beef costs rose faster than its prices.
B13: {="Below gross margin, freight "&SIGNMONEY(PnL!Y12)&" and operating expenses "&SIGNMONEY(PnL!Y18)&" (mostly "&INDEX(TRIM(PnL!B14:B17),_xlfn.XMATCH(MIN(PnL!Y14:Y17),PnL!Y14:Y17))&") leave EBITDA at "&MONEY(PnL!W19)&" against a budget of "&MONEY(PnL!X19)&"."} -> Below gross margin, freight −$36K and operating expenses −$178K (mostly Warehouse & Logistics) leave EBITDA at $1.5M against a budget of $1.8M.
B14: {=IF(breakeven_gap>0,"Full year on the "&ScenarioName&" scenario: EBITDA "&MONEY(PnL!P19)&" against a budget of "&MONEY(PnL!Q19)&". Closing the "&MONEY(breakeven_gap)&" gap takes a "&TEXT(breakeven_uplift,"0.0%")&" price rise on the "&(12-MonthsClosed)&" open months, or "&TEXT(breakeven_volume,"0%")&" more volume: price is the realistic lever.","Full year on the "&ScenarioName&" scenario: EBITDA "&MONEY(PnL!P19)&", "&MONEY(-breakeven_gap)&" above budget.")} -> Full year on the Base scenario: EBITDA $2.3M against a budget of $2.7M. Closing the $412K gap takes a 2.6% price rise on the 4 open months, or 11% more volume: price is the realistic lever.
B15: ="Cash: DSO "&TEXT(WorkingCapital!O12,"0")&" days, DIO "&TEXT(WorkingCapital!O13,"0")&", DPO "&TEXT(WorkingCapital!O14,"0")&", a "&TEXT(WorkingCapital!O15,"0.0")&"-day cycle. "&WorkingCapital!B46 -> Cash: DSO 32 days, DIO 16, DPO 27, a 20.6-day cycle. Cheese & Dairy holds 52 days of stock, 58% of its 90-day shelf life: $58K of it sits above the 50% risk line, stock that needs a markdown or a slower buy before it becomes a write-off.
B55: Largest gross-margin movers against budget, year to date | K55: Full year by scenario
B56: Segment | G56: Main driver | J56: GM vs budget | K56: Scenario | M56: Revenue | O56: EBITDA | Q56: Margin | S56: vs budget
B57: {=_xlfn.LET(_xlpm.seg,PVM!$B$35:$B$58&" · "&PVM!$C$35:$C$58,_xlpm.v,PVM!$U$35:$U$58,INDEX(_xlfn.SORTBY(_xlpm.seg,ABS(_xlpm.v),-1),ROWS(B$57:B57)))} -> Beef · Restaurants | G57: {=_xlfn.LET(_xlpm.d,PVM!$W$35:$W$58,_xlpm.v,PVM!$U$35:$U$58,INDEX(_xlfn.SORTBY(_xlpm.d,ABS(_xlpm.v),-1),ROWS(G$57:G57)))} -> Unit cost | J57: {=_xlfn.LET(_xlpm.v,PVM!$U$35:$U$58,INDEX(_xlfn.SORTBY(_xlpm.v,ABS(_xlpm.v),-1),ROWS(J$57:J57)))} -> -151620.28 | K57: =Scenarios!B18 -> Base | M57: =Scenarios!C18 -> 47407338 | O57: =Scenarios!E18 -> 2319179.9 | Q57: =Scenarios!F18 -> 0.048920272 | S57: =Scenarios!G18 -> -412477.17
B58: {=_xlfn.LET(_xlpm.seg,PVM!$B$35:$B$58&" · "&PVM!$C$35:$C$58,_xlpm.v,PVM!$U$35:$U$58,INDEX(_xlfn.SORTBY(_xlpm.seg,ABS(_xlpm.v),-1),ROWS(B$57:B58)))} -> Seafood · Grocery Retail | G58: {=_xlfn.LET(_xlpm.d,PVM!$W$35:$W$58,_xlpm.v,PVM!$U$35:$U$58,INDEX(_xlfn.SORTBY(_xlpm.d,ABS(_xlpm.v),-1),ROWS(G$57:G58)))} -> Price | J58: {=_xlfn.LET(_xlpm.v,PVM!$U$35:$U$58,INDEX(_xlfn.SORTBY(_xlpm.v,ABS(_xlpm.v),-1),ROWS(J$57:J58)))} -> 71982.43 | K58: =Scenarios!B19 -> Upside | M58: =Scenarios!C19 -> 48128798 | O58: =Scenarios!E19 -> 2836094 | Q58: =Scenarios!F19 -> 0.058927173 | S58: =Scenarios!G19 -> 104436.97
B59: {=_xlfn.LET(_xlpm.seg,PVM!$B$35:$B$58&" · "&PVM!$C$35:$C$58,_xlpm.v,PVM!$U$35:$U$58,INDEX(_xlfn.SORTBY(_xlpm.seg,ABS(_xlpm.v),-1),ROWS(B$57:B59)))} -> Beef · Hotels & Institutions | G59: {=_xlfn.LET(_xlpm.d,PVM!$W$35:$W$58,_xlpm.v,PVM!$U$35:$U$58,INDEX(_xlfn.SORTBY(_xlpm.d,ABS(_xlpm.v),-1),ROWS(G$57:G59)))} -> Unit cost | J59: {=_xlfn.LET(_xlpm.v,PVM!$U$35:$U$58,INDEX(_xlfn.SORTBY(_xlpm.v,ABS(_xlpm.v),-1),ROWS(J$57:J59)))} -> -59108 | K59: =Scenarios!B20 -> Downside | M59: =Scenarios!C20 -> 46620002 | O59: =Scenarios!E20 -> 1656743 | Q59: =Scenarios!F20 -> 0.035537171 | S59: =Scenarios!G20 -> -1074914
B60: {=_xlfn.LET(_xlpm.seg,PVM!$B$35:$B$58&" · "&PVM!$C$35:$C$58,_xlpm.v,PVM!$U$35:$U$58,INDEX(_xlfn.SORTBY(_xlpm.seg,ABS(_xlpm.v),-1),ROWS(B$57:B60)))} -> Poultry · Grocery Retail | G60: {=_xlfn.LET(_xlpm.d,PVM!$W$35:$W$58,_xlpm.v,PVM!$U$35:$U$58,INDEX(_xlfn.SORTBY(_xlpm.d,ABS(_xlpm.v),-1),ROWS(G$57:G60)))} -> Volume | J60: {=_xlfn.LET(_xlpm.v,PVM!$U$35:$U$58,INDEX(_xlfn.SORTBY(_xlpm.v,ABS(_xlpm.v),-1),ROWS(J$57:J60)))} -> 51866.77 | K60: Budget | M60: =Scenarios!C21 -> 45768802 | O60: =Scenarios!E21 -> 2731657 | Q60: =Scenarios!F21 -> 0.059683822
B61: {=_xlfn.LET(_xlpm.seg,PVM!$B$35:$B$58&" · "&PVM!$C$35:$C$58,_xlpm.v,PVM!$U$35:$U$58,INDEX(_xlfn.SORTBY(_xlpm.seg,ABS(_xlpm.v),-1),ROWS(B$57:B61)))} -> Seafood · Restaurants | G61: {=_xlfn.LET(_xlpm.d,PVM!$W$35:$W$58,_xlpm.v,PVM!$U$35:$U$58,INDEX(_xlfn.SORTBY(_xlpm.d,ABS(_xlpm.v),-1),ROWS(G$57:G61)))} -> Price | J61: {=_xlfn.LET(_xlpm.v,PVM!$U$35:$U$58,INDEX(_xlfn.SORTBY(_xlpm.v,ABS(_xlpm.v),-1),ROWS(J$57:J61)))} -> 51479
B62: Kestrel Bay Provisions is fictional and every figure is synthetic. Built in Excel by Kush Patel: github.com/KushPatel29/excel-fpa-model
B68: Chart data: the charts above read these cells, which read the model.
B71: Month | C71: Actual | D71: Forecast | E71: Budget | F71: Prior year
B72: {=TRANSPOSE(TEXT(pnl_months,"mmm"))} -> Jan | C72: {=TRANSPOSE(IF(pnl_months<=AsOfMonth,PnL!$D$8:$O$8,""))} -> 3392254.2 | D72: {=TRANSPOSE(IF(pnl_months>AsOfMonth,PnL!$D$8:$O$8,""))} | E72: {=TRANSPOSE(PnL!$D$25:$O$25)} -> 3439390.9 | F72: {=TRANSPOSE(PnL!$D$42:$O$42)} -> 3218241.6
B73: Feb | C73: 3483944 | E73: 3351624.8 | F73: 3130900.3
B74: Mar | C74: 3722609.1 | E74: 3562620.3 | F74: 3334202.5
B75: Apr | C75: 3897955.2 | E75: 3745449.1 | F75: 3503499.3
B76: May | C76: 4188761.9 | E76: 4031810.3 | F76: 3770601.9
B77: Jun | C77: 4343870.5 | E77: 4156915.1 | F77: 3886478.4
B78: Jul | C78: 4313685.7 | E78: 4127204 | F78: 3854332.6
B79: Aug | C79: 4190550.5 | E79: 4008366.5 | F79: 3747572.4
B80: Sep | D80: 3894907.9 | E80: 3766953.7 | F80: 3522865.4
B81: Oct | D81: 3843015.5 | E81: 3712316.4 | F81: 3470892.5
B82: Nov | D82: 3886984.6 | E82: 3756857.5 | F82: 3514051.6
B83: Dec | D83: 4248799 | E83: 4109293.5 | F83: 3837508.8
B86: =PVM!E84 -> Budget EBITDA | C86: =PVM!F84 -> 1757686.4
B87: =PVM!E85 -> Volume | C87: =PVM!F85 -> 289952.84
B88: =PVM!E86 -> Mix | C88: =PVM!F86 -> -173287.14
B89: =PVM!E87 -> Price | C89: =PVM!F87 -> 238025.89
B90: =PVM!E88 -> Unit cost | C90: =PVM!F88 -> -371970.8
...

Sheet PnL
B1: ="Profit and loss, FY"&FiscalYear&": outlook against budget and prior year" -> Profit and loss, FY2026: outlook against budget and prior year
B2: ="Actuals through "&TEXT(AsOfMonth,"mmmm yyyy")&", forecast after (shaded). Scenario: "&ScenarioName&". Favourable variances are positive; unfavourable ones in brackets." -> Actuals through August 2026, forecast after (shaded). Scenario: Base. Favourable variances are positive; unfavourable ones in brackets.
B4: Month | D4: =FYStart -> 46023 | E4: =EDATE(D4,1) -> 46054 | F4: =EDATE(E4,1) -> 46082 | G4: =EDATE(F4,1) -> 46113 | H4: =EDATE(G4,1) -> 46143 | I4: =EDATE(H4,1) -> 46174 | J4: =EDATE(I4,1) -> 46204 | K4: =EDATE(J4,1) -> 46235 | L4: =EDATE(K4,1) -> 46266 | ... O4: =EDATE(N4,1) -> 46357 | P4: FY outlook | Q4: FY budget | R4: Fav / (unfav) | S4: Var % | T4: Prior year | U4: vs PY | V4: Trend | W4: YTD actual | X4: YTD budget | Y4: Fav / (unfav) | Z4: Var % | AA4: YTD prior year | AB4: YTD vs PY
D5: {=IF(ISCLOSED(D$4),"Actual","Forecast")} -> Actual | E5: {=IF(ISCLOSED(E$4),"Actual","Forecast")} -> Actual | F5: {=IF(ISCLOSED(F$4),"Actual","Forecast")} -> Actual | G5: {=IF(ISCLOSED(G$4),"Actual","Forecast")} -> Actual | H5: {=IF(ISCLOSED(H$4),"Actual","Forecast")} -> Actual | I5: {=IF(ISCLOSED(I$4),"Actual","Forecast")} -> Actual | J5: {=IF(ISCLOSED(J$4),"Actual","Forecast")} -> Actual | K5: {=IF(ISCLOSED(K$4),"Actual","Forecast")} -> Actual | ... O5: {=IF(ISCLOSED(O$4),"Actual","Forecast")} -> Forecast | P5: all 12 months | W5: ="Jan–"&TEXT(AsOfMonth,"mmm") -> Jan–Aug
B6: Outlook: actuals to the as-of month, driver forecast after
B7: Cases sold | D7: {=IF(ISCLOSED(D$4),SUMIFS(tbl_Sales[units],tbl_Sales[month],D$4),Forecast!D$43)} -> 23802 | E7: {=IF(ISCLOSED(E$4),SUMIFS(tbl_Sales[units],tbl_Sales[month],E$4),Forecast!E$43)} -> 24533 | F7: {=IF(ISCLOSED(F$4),SUMIFS(tbl_Sales[units],tbl_Sales[month],F$4),Forecast!F$43)} -> 26034 | G7: {=IF(ISCLOSED(G$4),SUMIFS(tbl_Sales[units],tbl_Sales[month],G$4),Forecast!G$43)} -> 27099 | H7: {=IF(ISCLOSED(H$4),SUMIFS(tbl_Sales[units],tbl_Sales[month],H$4),Forecast!H$43)} -> 28691 | I7: {=IF(ISCLOSED(I$4),SUMIFS(tbl_Sales[units],tbl_Sales[month],I$4),Forecast!I$43)} -> 29597 | J7: {=IF(ISCLOSED(J$4),SUMIFS(tbl_Sales[units],tbl_Sales[month],J$4),Forecast!J$43)} -> 29433 | K7: {=IF(ISCLOSED(K$4),SUMIFS(tbl_Sales[units],tbl_Sales[month],K$4),Forecast!K$43)} -> 28815 | ... O7: {=IF(ISCLOSED(O$4),SUMIFS(tbl_Sales[units],tbl_Sales[month],O$4),Forecast!O$43)} -> 29931.599 | P7: =SUM(D7:O7) -> 329092.52 | Q7: =P24 -> 317860 | R7: =P7-Q7 -> 11232.521 | S7: {=SAFEDIV(R7,ABS(Q7))} -> 0.035337951 | T7: =P41 -> 309144 | U7: {=SAFEDIV(P7-T7,ABS(T7))} -> 0.064528249 | W7: =SUMIFS(D7:O7,$D$4:$O$4,"<="&AsOfMonth) -> 218004 | X7: =SUMIFS(D24:O24,$D$4:$O$4,"<="&AsOfMonth) -> 210532 | Y7: =W7-X7 -> 7472 | Z7: {=SAFEDIV(Y7,ABS(X7))} -> 0.035491042 | AA7: =SUMIFS(D41:O41,$D$4:$O$4,"<="&AsOfMonth) -> 204784 | AB7: {=SAFEDIV(W7-AA7,ABS(AA7))} -> 0.064555825
B8: Revenue | D8: {=IF(ISCLOSED(D$4),SUMIFS(tbl_Sales[net_revenue],tbl_Sales[month],D$4),Forecast!D$53)} -> 3392254.2 | E8: {=IF(ISCLOSED(E$4),SUMIFS(tbl_Sales[net_revenue],tbl_Sales[month],E$4),Forecast!E$53)} -> 3483944 | F8: {=IF(ISCLOSED(F$4),SUMIFS(tbl_Sales[net_revenue],tbl_Sales[month],F$4),Forecast!F$53)} -> 3722609.1 | G8: {=IF(ISCLOSED(G$4),SUMIFS(tbl_Sales[net_revenue],tbl_Sales[month],G$4),Forecast!G$53)} -> 3897955.2 | H8: {=IF(ISCLOSED(H$4),SUMIFS(tbl_Sales[net_revenue],tbl_Sales[month],H$4),Forecast!H$53)} -> 4188761.9 | I8: {=IF(ISCLOSED(I$4),SUMIFS(tbl_Sales[net_revenue],tbl_Sales[month],I$4),Forecast!I$53)} -> 4343870.5 | J8: {=IF(ISCLOSED(J$4),SUMIFS(tbl_Sales[net_revenue],tbl_Sales[month],J$4),Forecast!J$53)} -> 4313685.7 | K8: {=IF(ISCLOSED(K$4),SUMIFS(tbl_Sales[net_revenue],tbl_Sales[month],K$4),Forecast!K$53)} -> 4190550.5 | ... O8: {=IF(ISCLOSED(O$4),SUMIFS(tbl_Sales[net_revenue],tbl_Sales[month],O$4),Forecast!O$53)} -> 4248799 | P8: =SUM(D8:O8) -> 47407338 | Q8: =P25 -> 45768802 | R8: {=FAVVAR(P8,Q8,FALSE)} -> 1638536.2 | S8: {=SAFEDIV(R8,ABS(Q8))} -> 0.035800285 | T8: =P42 -> 42791147 | U8: {=SAFEDIV(P8-T8,ABS(T8))} -> 0.10787724 | W8: =SUMIFS(D8:O8,$D$4:$O$4,"<="&AsOfMonth) -> 31533631 | X8: =SUMIFS(D25:O25,$D$4:$O$4,"<="&AsOfMonth) -> 30423381 | Y8: {=FAVVAR(W8,X8,FALSE)} -> 1110250.1 | Z8: {=SAFEDIV(Y8,ABS(X8))} -> 0.036493316 | AA8: =SUMIFS(D42:O42,$D$4:$O$4,"<="&AsOfMonth) -> 28445829 | AB8: {=SAFEDIV(W8-AA8,ABS(AA8))} -> 0.10855026
B9: Cost of goods sold | D9: {=IF(ISCLOSED(D$4),SUMIFS(tbl_Sales[cogs],tbl_Sales[month],D$4),Forecast!D$63)} -> 2470958.3 | E9: {=IF(ISCLOSED(E$4),SUMIFS(tbl_Sales[cogs],tbl_Sales[month],E$4),Forecast!E$63)} -> 2555340.9 | F9: {=IF(ISCLOSED(F$4),SUMIFS(tbl_Sales[cogs],tbl_Sales[month],F$4),Forecast!F$63)} -> 2733364.1 | G9: {=IF(ISCLOSED(G$4),SUMIFS(tbl_Sales[cogs],tbl_Sales[month],G$4),Forecast!G$63)} -> 2871704.4 | H9: {=IF(ISCLOSED(H$4),SUMIFS(tbl_Sales[cogs],tbl_Sales[month],H$4),Forecast!H$63)} -> 3130924.7 | I9: {=IF(ISCLOSED(I$4),SUMIFS(tbl_Sales[cogs],tbl_Sales[month],I$4),Forecast!I$63)} -> 3251870.7 | J9: {=IF(ISCLOSED(J$4),SUMIFS(tbl_Sales[cogs],tbl_Sales[month],J$4),Forecast!J$63)} -> 3230095.7 | K9: {=IF(ISCLOSED(K$4),SUMIFS(tbl_Sales[cogs],tbl_Sales[month],K$4),Forecast!K$63)} -> 3136904.4 | ... O9: {=IF(ISCLOSED(O$4),SUMIFS(tbl_Sales[cogs],tbl_Sales[month],O$4),Forecast!O$63)} -> 3121278.3 | P9: =SUM(D9:O9) -> 35106482 | Q9: =P26 -> 33378999 | R9: {=FAVVAR(P9,Q9,TRUE)} -> -1727483.4 | S9: {=SAFEDIV(R9,ABS(Q9))} -> -0.051753601 | T9: =P43 -> 31512171 | U9: {=SAFEDIV(P9-T9,ABS(T9))} -> 0.11406104 | W9: =SUMIFS(D9:O9,$D$4:$O$4,"<="&AsOfMonth) -> 23381163 | X9: =SUMIFS(D26:O26,$D$4:$O$4,"<="&AsOfMonth) -> 22253634 | Y9: {=FAVVAR(W9,X9,TRUE)} -> -1127529.3 | Z9: {=SAFEDIV(Y9,ABS(X9))} -> -0.050667198 | AA9: =SUMIFS(D43:O43,$D$4:$O$4,"<="&AsOfMonth) -> 21010123 | AB9: {=SAFEDIV(W9-AA9,ABS(AA9))} -> 0.11285227
B10: Gross margin | D10: =D8-D9 -> 921295.89 | E10: =E8-E9 -> 928603.04 | F10: =F8-F9 -> 989245.02 | G10: =G8-G9 -> 1026250.9 | H10: =H8-H9 -> 1057837.2 | I10: =I8-I9 -> 1091999.8 | J10: =J8-J9 -> 1083590 | K10: =K8-K9 -> 1053646.1 | ... O10: =O8-O9 -> 1127520.7 | P10: =SUM(D10:O10) -> 12300856 | Q10: =P27 -> 12389803 | R10: {=FAVVAR(P10,Q10,FALSE)} -> -88947.21 | S10: {=SAFEDIV(R10,ABS(Q10))} -> -0.0071790655 | T10: =P44 -> 11278976 | U10: {=SAFEDIV(P10-T10,ABS(T10))} -> 0.090600427 | W10: =SUMIFS(D10:O10,$D$4:$O$4,"<="&AsOfMonth) -> 8152467.9 | X10: =SUMIFS(D27:O27,$D$4:$O$4,"<="&AsOfMonth) -> 8169747.1 | Y10: {=FAVVAR(W10,X10,FALSE)} -> -17279.22 | Z10: {=SAFEDIV(Y10,ABS(X10))} -> -0.0021150251 | AA10: =SUMIFS(D44:O44,$D$4:$O$4,"<="&AsOfMonth) -> 7435705.8 | AB10: {=SAFEDIV(W10-AA10,ABS(AA10))} -> 0.096394629
B11: Gross margin % | D11: {=SAFEDIV(D10,D8)} -> 0.2715881 | E11: {=SAFEDIV(E10,E8)} -> 0.26653788 | F11: {=SAFEDIV(F10,F8)} -> 0.2657397 | G11: {=SAFEDIV(G10,G8)} -> 0.26327928 | H11: {=SAFEDIV(H10,H8)} -> 0.25254174 | I11: {=SAFEDIV(I10,I8)} -> 0.25138866 | J11: {=SAFEDIV(J10,J8)} -> 0.25119817 | K11: {=SAFEDIV(K10,K8)} -> 0.25143381 | ... P11: {=SAFEDIV(P10,P8)} -> 0.25947156 | Q11: =P28 -> 0.27070412 | R11: =P11-Q11 -> -0.011232559 | T11: =P45 -> 0.263582 | U11: =P11-T11 -> -0.0041104352 | W11: {=SAFEDIV(W10,W8)} -> 0.25853248 | X11: {=SAFEDIV(X10,X8)} -> 0.26853515 | Y11: =W11-X11 -> -0.010002666 | AA11: {=SAFEDIV(AA10,AA8)} -> 0.26139881 | AB11: =W11-AA11 -> -0.0028663272
B12: Freight | D12: {=IF(ISCLOSED(D$4),SUMIFS(tbl_Sales[freight],tbl_Sales[month],D$4),Forecast!D$73)} -> 79628.36 | E12: {=IF(ISCLOSED(E$4),SUMIFS(tbl_Sales[freight],tbl_Sales[month],E$4),Forecast!E$73)} -> 80812.44 | F12: {=IF(ISCLOSED(F$4),SUMIFS(tbl_Sales[freight],tbl_Sales[month],F$4),Forecast!F$73)} -> 85861.18 | G12: {=IF(ISCLOSED(G$4),SUMIFS(tbl_Sales[freight],tbl_Sales[month],G$4),Forecast!G$73)} -> 89538.75 | H12: {=IF(ISCLOSED(H$4),SUMIFS(tbl_Sales[freight],tbl_Sales[month],H$4),Forecast!H$73)} -> 95117.83 | I12: {=IF(ISCLOSED(I$4),SUMIFS(tbl_Sales[freight],tbl_Sales[month],I$4),Forecast!I$73)} -> 97563.18 | J12: {=IF(ISCLOSED(J$4),SUMIFS(tbl_Sales[freight],tbl_Sales[month],J$4),Forecast!J$73)} -> 97225.71 | K12: {=IF(ISCLOSED(K$4),SUMIFS(tbl_Sales[freight],tbl_Sales[month],K$4),Forecast!K$73)} -> 94942.85 | ... O12: {=IF(ISCLOSED(O$4),SUMIFS(tbl_Sales[freight],tbl_Sales[month],O$4),Forecast!O$73)} -> 98731.859 | P12: =SUM(D12:O12) -> 1087116.2 | Q12: =P29 -> 1033566.9 | R12: {=FAVVAR(P12,Q12,TRUE)} -> -53549.279 | S12: {=SAFEDIV(R12,ABS(Q12))} -> -0.051810172 | T12: =P46 -> 986287.3 | U12: {=SAFEDIV(P12-T12,ABS(T12))} -> 0.10223074 | W12: =SUMIFS(D12:O12,$D$4:$O$4,"<="&AsOfMonth) -> 720690.3 | X12: =SUMIFS(D29:O29,$D$4:$O$4,"<="&AsOfMonth) -> 684420.25 | Y12: {=FAVVAR(W12,X12,TRUE)} -> -36270.05 | Z12: {=SAFEDIV(Y12,ABS(X12))} -> -0.052993829 | AA12: =SUMIFS(D46:O46,$D$4:$O$4,"<="&AsOfMonth) -> 653290.26 | AB12: {=SAFEDIV(W12-AA12,ABS(AA12))} -> 0.10317013
B13: Contribution | D13: =D10-D12 -> 841667.53 | E13: =E10-E12 -> 847790.6 | F13: =F10-F12 -> 903383.84 | G13: =G10-G12 -> 936712.1 | H13: =H10-H12 -> 962719.41 | I13: =I10-I12 -> 994436.61 | J13: =J10-J12 -> 986364.26 | K13: =K10-K12 -> 958703.23 | ... O13: =O10-O12 -> 1028788.9 | P13: =SUM(D13:O13) -> 11213740 | Q13: =P30 -> 11356237 | R13: {=FAVVAR(P13,Q13,FALSE)} -> -142496.49 | S13: {=SAFEDIV(R13,ABS(Q13))} -> -0.012547862 | T13: =P47 -> 10292689 | U13: {=SAFEDIV(P13-T13,ABS(T13))} -> 0.089485964 | W13: =SUMIFS(D13:O13,$D$4:$O$4,"<="&AsOfMonth) -> 7431777.6 | X13: =SUMIFS(D30:O30,$D$4:$O$4,"<="&AsOfMonth) -> 7485326.9 | Y13: {=FAVVAR(W13,X13,FALSE)} -> -53549.27 | Z13: {=SAFEDIV(Y13,ABS(X13))} -> -0.0071538987 | AA13: =SUMIFS(D47:O47,$D$4:$O$4,"<="&AsOfMonth) -> 6782415.5 | AB13: {=SAFEDIV(W13-AA13,ABS(AA13))} -> 0.095742005
B14: Sales & Marketing | D14: {=IF(ISCLOSED(D$4),SUMIFS(tbl_Opex[amount],tbl_Opex[month],D$4,tbl_Opex[dept],TRIM($B14),tbl_Opex[scenario],"Actual"),_xlfn.XLOOKUP(TRIM($B14),Forecast!$B$85:$B$88,Forecast!D$85:D$88))} -> 200502.67 | E14: {=IF(ISCLOSED(E$4),SUMIFS(tbl_Opex[amount],tbl_Opex[month],E$4,tbl_Opex[dept],TRIM($B14),tbl_Opex[scenario],"Actual"),_xlfn.XLOOKUP(TRIM($B14),Forecast!$B$85:$B$88,Forecast!E$85:E$88))} -> 197737.12 | F14: {=IF(ISCLOSED(F$4),SUMIFS(tbl_Opex[amount],tbl_Opex[month],F$4,tbl_Opex[dept],TRIM($B14),tbl_Opex[scenario],"Actual"),_xlfn.XLOOKUP(TRIM($B14),Forecast!$B$85:$B$88,Forecast!F$85:F$88))} -> 196749.42 | G14: {=IF(ISCLOSED(G$4),SUMIFS(tbl_Opex[amount],tbl_Opex[month],G$4,tbl_Opex[dept],TRIM($B14),tbl_Opex[scenario],"Actual"),_xlfn.XLOOKUP(TRIM($B14),Forecast!$B$85:$B$88,Forecast!G$85:G$88))} -> 199514.98 | H14: {=IF(ISCLOSED(H$4),SUMIFS(tbl_Opex[amount],tbl_Opex[month],H$4,tbl_Opex[dept],TRIM($B14),tbl_Opex[scenario],"Actual"),_xlfn.XLOOKUP(TRIM($B14),Forecast!$B$85:$B$88,Forecast!H$85:H$88))} -> 199712.52 | I14: {=IF(ISCLOSED(I$4),SUMIFS(tbl_Opex[amount],tbl_Opex[month],I$4,tbl_Opex[dept],TRIM($B14),tbl_Opex[scenario],"Actual"),_xlfn.XLOOKUP(TRIM($B14),Forecast!$B$85:$B$88,Forecast!I$85:I$88))} -> 198922.36 | J14: {=IF(ISCLOSED(J$4),SUMIFS(tbl_Opex[amount],tbl_Opex[month],J$4,tbl_Opex[dept],TRIM($B14),tbl_Opex[scenario],"Actual"),_xlfn.XLOOKUP(TRIM($B14),Forecast!$B$85:$B$88,Forecast!J$85:J$88))} -> 194971.57 | K14: {=IF(ISCLOSED(K$4),SUMIFS(tbl_Opex[amount],tbl_Opex[month],K$4,tbl_Opex[dept],TRIM($B14),tbl_Opex[scenario],"Actual"),_xlfn.XLOOKUP(TRIM($B14),Forecast!$B$85:$B$88,Forecast!K$85:K$88))} -> 194971.57 | ... O14: {=IF(ISCLOSED(O$4),SUMIFS(tbl_Opex[amount],tbl_Opex[month],O$4,tbl_Opex[dept],TRIM($B14),tbl_Opex[scenario],"Actual"),_xlfn.XLOOKUP(TRIM($B14),Forecast!$B$85:$B$88,Forecast!O$85:O$88))} -> 197885.28 | P14: =SUM(D14:O14) -> 2374623.3 | Q14: =P31 -> 2419456.7 | R14: {=FAVVAR(P14,Q14,TRUE)} -> 44833.365 | S14: {=SAFEDIV(R14,ABS(Q14))} -> 0.018530344 | T14: =P48 -> 2348987.1 | U14: {=SAFEDIV(P14-T14,ABS(T14))} -> 0.010913732 | W14: =SUMIFS(D14:O14,$D$4:$O$4,"<="&AsOfMonth) -> 1583082.2 | X14: =SUMIFS(D31:O31,$D$4:$O$4,"<="&AsOfMonth) -> 1612971.1 | Y14: {=FAVVAR(W14,X14,TRUE)} -> 29888.91 | Z14: {=SAFEDIV(Y14,ABS(X14))} -> 0.018530344 | AA14: =SUMIFS(D48:O48,$D$4:$O$4,"<="&AsOfMonth) -> 1565404.3 | AB14: {=SAFEDIV(W14-AA14,ABS(AA14))} -> 0.011292872
B15: Warehouse & Logistics | D15: {=IF(ISCLOSED(D$4),SUMIFS(tbl_Opex[amount],tbl_Opex[month],D$4,tbl_Opex[dept],TRIM($B15),tbl_Opex[scenario],"Actual"),_xlfn.XLOOKUP(TRIM($B15),Forecast!$B$85:$B$88,Forecast!D$85:D$88))} -> 300283.93 | E15: {=IF(ISCLOSED(E$4),SUMIFS(tbl_Opex[amount],tbl_Opex[month],E$4,tbl_Opex[dept],TRIM($B15),tbl_Opex[scenario],"Actual"),_xlfn.XLOOKUP(TRIM($B15),Forecast!$B$85:$B$88,Forecast!E$85:E$88))} -> 302071.33 | F15: {=IF(ISCLOSED(F$4),SUMIFS(tbl_Opex[amount],tbl_Opex[month],F$4,tbl_Opex[dept],TRIM($B15),tbl_Opex[scenario],"Actual"),_xlfn.XLOOKUP(TRIM($B15),Forecast!$B$85:$B$88,Forecast!F$85:F$88))} -> 301177.63 | G15: {=IF(ISCLOSED(G$4),SUMIFS(tbl_Opex[amount],tbl_Opex[month],G$4,tbl_Opex[dept],TRIM($B15),tbl_Opex[scenario],"Actual"),_xlfn.XLOOKUP(TRIM($B15),Forecast!$B$85:$B$88,Forecast!G$85:G$88))} -> 298496.52 | H15: {=IF(ISCLOSED(H$4),SUMIFS(tbl_Opex[amount],tbl_Opex[month],H$4,tbl_Opex[dept],TRIM($B15),tbl_Opex[scenario],"Actual"),_xlfn.XLOOKUP(TRIM($B15),Forecast!$B$85:$B$88,Forecast!H$85:H$88))} -> 295517.51 | I15: {=IF(ISCLOSED(I$4),SUMIFS(tbl_Opex[amount],tbl_Opex[month],I$4,tbl_Opex[dept],TRIM($B15),tbl_Opex[scenario],"Actual"),_xlfn.XLOOKUP(TRIM($B15),Forecast!$B$85:$B$88,Forecast!I$85:I$88))} -> 293730.11 | J15: {=IF(ISCLOSED(J$4),SUMIFS(tbl_Opex[amount],tbl_Opex[month],J$4,tbl_Opex[dept],TRIM($B15),tbl_Opex[scenario],"Actual"),_xlfn.XLOOKUP(TRIM($B15),Forecast!$B$85:$B$88,Forecast!J$85:J$88))} -> 299986.03 | K15: {=IF(ISCLOSED(K$4),SUMIFS(tbl_Opex[amount],tbl_Opex[month],K$4,tbl_Opex[dept],TRIM($B15),tbl_Opex[scenario],"Actual"),_xlfn.XLOOKUP(TRIM($B15),Forecast!$B$85:$B$88,Forecast!K$85:K$88))} -> 296709.12 | ... O15: {=IF(ISCLOSED(O$4),SUMIFS(tbl_Opex[amount],tbl_Opex[month],O$4,tbl_Opex[dept],TRIM($B15),tbl_Opex[scenario],"Actual"),_xlfn.XLOOKUP(TRIM($B15),Forecast!$B$85:$B$88,Forecast!O$85:O$88))} -> 316406.31 | P15: =SUM(D15:O15) -> 3617777.9 | Q15: =P32 -> 3344994.8 | R15: {=FAVVAR(P15,Q15,TRUE)} -> -272783.05 | S15: {=SAFEDIV(R15,ABS(Q15))} -> -0.081549619 | T15: =P49 -> 3247567.7 | U15: {=SAFEDIV(P15-T15,ABS(T15))} -> 0.11399611 | W15: =SUMIFS(D15:O15,$D$4:$O$4,"<="&AsOfMonth) -> 2387972.2 | X15: =SUMIFS(D32:O32,$D$4:$O$4,"<="&AsOfMonth) -> 2207917.4 | Y15: {=FAVVAR(W15,X15,TRUE)} -> -180054.82 | Z15: {=SAFEDIV(Y15,ABS(X15))} -> -0.081549619 | AA15: =SUMIFS(D49:O49,$D$4:$O$4,"<="&AsOfMonth) -> 2141596.6 | AB15: {=SAFEDIV(W15-AA15,ABS(AA15))} -> 0.11504295
B16: General & Admin | D16: {=IF(ISCLOSED(D$4),SUMIFS(tbl_Opex[amount],tbl_Opex[month],D$4,tbl_Opex[dept],TRIM($B16),tbl_Opex[scenario],"Actual"),_xlfn.XLOOKUP(TRIM($B16),Forecast!$B$85:$B$88,Forecast!D$85:D$88))} -> 183249.47 | E16: {=IF(ISCLOSED(E$4),SUMIFS(tbl_Opex[amount],tbl_Opex[month],E$4,tbl_Opex[dept],TRIM($B16),tbl_Opex[scenario],"Actual"),_xlfn.XLOOKUP(TRIM($B16),Forecast!$B$85:$B$88,Forecast!E$85:E$88))} -> 180152.81 | F16: {=IF(ISCLOSED(F$4),SUMIFS(tbl_Opex[amount],tbl_Opex[month],F$4,tbl_Opex[dept],TRIM($B16),tbl_Opex[scenario],"Actual"),_xlfn.XLOOKUP(TRIM($B16),Forecast!$B$85:$B$88,Forecast!F$85:F$88))} -> 184342.41 | G16: {=IF(ISCLOSED(G$4),SUMIFS(tbl_Opex[amount],tbl_Opex[month],G$4,tbl_Opex[dept],TRIM($B16),tbl_Opex[scenario],"Actual"),_xlfn.XLOOKUP(TRIM($B16),Forecast!$B$85:$B$88,Forecast!G$85:G$88))} -> 184888.88 | H16: {=IF(ISCLOSED(H$4),SUMIFS(tbl_Opex[amount],tbl_Opex[month],H$4,tbl_Opex[dept],TRIM($B16),tbl_Opex[scenario],"Actual"),_xlfn.XLOOKUP(TRIM($B16),Forecast!$B$85:$B$88,Forecast!H$85:H$88))} -> 184524.56 | I16: {=IF(ISCLOSED(I$4),SUMIFS(tbl_Opex[amount],tbl_Opex[month],I$4,tbl_Opex[dept],TRIM($B16),tbl_Opex[scenario],"Actual"),_xlfn.XLOOKUP(TRIM($B16),Forecast!$B$85:$B$88,Forecast!I$85:I$88))} -> 184888.88 | J16: {=IF(ISCLOSED(J$4),SUMIFS(tbl_Opex[amount],tbl_Opex[month],J$4,tbl_Opex[dept],TRIM($B16),tbl_Opex[scenario],"Actual"),_xlfn.XLOOKUP(TRIM($B16),Forecast!$B$85:$B$88,Forecast!J$85:J$88))} -> 183431.63 | K16: {=IF(ISCLOSED(K$4),SUMIFS(tbl_Opex[amount],tbl_Opex[month],K$4,tbl_Opex[dept],TRIM($B16),tbl_Opex[scenario],"Actual"),_xlfn.XLOOKUP(TRIM($B16),Forecast!$B$85:$B$88,Forecast!K$85:K$88))} -> 183431.63 | ... O16: {=IF(ISCLOSED(O$4),SUMIFS(tbl_Opex[amount],tbl_Opex[month],O$4,tbl_Opex[dept],TRIM($B16),tbl_Opex[scenario],"Actual"),_xlfn.XLOOKUP(TRIM($B16),Forecast!$B$85:$B$88,Forecast!O$85:O$88))} -> 183613.78 | P16: =SUM(D16:O16) -> 2203365.4 | Q16: =P33 -> 2160809.3 | R16: {=FAVVAR(P16,Q16,TRUE)} -> -42556.125 | S16: {=SAFEDIV(R16,ABS(Q16))} -> -0.019694531 | T16: =P50 -> 2097873.1 | U16: {=SAFEDIV(P16-T16,ABS(T16))} -> 0.05028536 | W16: =SUMIFS(D16:O16,$D$4:$O$4,"<="&AsOfMonth) -> 1468910.3 | X16: =SUMIFS(D33:O33,$D$4:$O$4,"<="&AsOfMonth) -> 1440539.5 | Y16: {=FAVVAR(W16,X16,TRUE)} -> -28370.75 | Z16: {=SAFEDIV(Y16,ABS(X16))} -> -0.019694531 | AA16: =SUMIFS(D50:O50,$D$4:$O$4,"<="&AsOfMonth) -> 1396947.8 | AB16: {=SAFEDIV(W16-AA16,ABS(AA16))} -> 0.051514072
B17: Technology | D17: {=IF(ISCLOSED(D$4),SUMIFS(tbl_Opex[amount],tbl_Opex[month],D$4,tbl_Opex[dept],TRIM($B17),tbl_Opex[scenario],"Actual"),_xlfn.XLOOKUP(TRIM($B17),Forecast!$B$85:$B$88,Forecast!D$85:D$88))} -> 58991.34 | E17: {=IF(ISCLOSED(E$4),SUMIFS(tbl_Opex[amount],tbl_Opex[month],E$4,tbl_Opex[dept],TRIM($B17),tbl_Opex[scenario],"Actual"),_xlfn.XLOOKUP(TRIM($B17),Forecast!$B$85:$B$88,Forecast!E$85:E$88))} -> 57941.05 | F17: {=IF(ISCLOSED(F$4),SUMIFS(tbl_Opex[amount],tbl_Opex[month],F$4,tbl_Opex[dept],TRIM($B17),tbl_Opex[scenario],"Actual"),_xlfn.XLOOKUP(TRIM($B17),Forecast!$B$85:$B$88,Forecast!F$85:F$88))} -> 58991.34 | G17: {=IF(ISCLOSED(G$4),SUMIFS(tbl_Opex[amount],tbl_Opex[month],G$4,tbl_Opex[dept],TRIM($B17),tbl_Opex[scenario],"Actual"),_xlfn.XLOOKUP(TRIM($B17),Forecast!$B$85:$B$88,Forecast!G$85:G$88))} -> 58116.1 | H17: {=IF(ISCLOSED(H$4),SUMIFS(tbl_Opex[amount],tbl_Opex[month],H$4,tbl_Opex[dept],TRIM($B17),tbl_Opex[scenario],"Actual"),_xlfn.XLOOKUP(TRIM($B17),Forecast!$B$85:$B$88,Forecast!H$85:H$88))} -> 57824.35 | I17: {=IF(ISCLOSED(I$4),SUMIFS(tbl_Opex[amount],tbl_Opex[month],I$4,tbl_Opex[dept],TRIM($B17),tbl_Opex[scenario],"Actual"),_xlfn.XLOOKUP(TRIM($B17),Forecast!$B$85:$B$88,Forecast!I$85:I$88))} -> 58291.15 | J17: {=IF(ISCLOSED(J$4),SUMIFS(tbl_Opex[amount],tbl_Opex[month],J$4,tbl_Opex[dept],TRIM($B17),tbl_Opex[scenario],"Actual"),_xlfn.XLOOKUP(TRIM($B17),Forecast!$B$85:$B$88,Forecast!J$85:J$88))} -> 57474.26 | K17: {=IF(ISCLOSED(K$4),SUMIFS(tbl_Opex[amount],tbl_Opex[month],K$4,tbl_Opex[dept],TRIM($B17),tbl_Opex[scenario],"Actual"),_xlfn.XLOOKUP(TRIM($B17),Forecast!$B$85:$B$88,Forecast!K$85:K$88))} -> 58232.8 | ... O17: {=IF(ISCLOSED(O$4),SUMIFS(tbl_Opex[amount],tbl_Opex[month],O$4,tbl_Opex[dept],TRIM($B17),tbl_Opex[scenario],"Actual"),_xlfn.XLOOKUP(TRIM($B17),Forecast!$B$85:$B$88,Forecast!O$85:O$88))} -> 58232.799 | P17: =SUM(D17:O17) -> 698793.58 | Q17: =P34 -> 699318.72 | R17: {=FAVVAR(P17,Q17,TRUE)} -> 525.135 | S17: {=SAFEDIV(R17,ABS(Q17))} -> 0.0007509237 | T17: =P51 -> 678950.25 | U17: {=SAFEDIV(P17-T17,ABS(T17))} -> 0.029226493 | W17: =SUMIFS(D17:O17,$D$4:$O$4,"<="&AsOfMonth) -> 465862.39 | X17: =SUMIFS(D34:O34,$D$4:$O$4,"<="&AsOfMonth) -> 466212.48 | Y17: {=FAVVAR(W17,X17,TRUE)} -> 350.09 | Z17: {=SAFEDIV(Y17,ABS(X17))} -> 0.0007509237 | AA17: =SUMIFS(D51:O51,$D$4:$O$4,"<="&AsOfMonth) -> 452690.15 | AB17: {=SAFEDIV(W17-AA17,ABS(AA17))} -> 0.029097695
B18: Total operating expenses | D18: =SUM(D14:D17) -> 743027.41 | E18: =SUM(E14:E17) -> 737902.31 | F18: =SUM(F14:F17) -> 741260.8 | G18: =SUM(G14:G17) -> 741016.48 | H18: =SUM(H14:H17) -> 737578.94 | I18: =SUM(I14:I17) -> 735832.5 | J18: =SUM(J14:J17) -> 735863.49 | K18: =SUM(K14:K17) -> 733345.12 | ... O18: =SUM(O14:O17) -> 756138.17 | P18: =SUM(D18:O18) -> 8894560.2 | Q18: =P35 -> 8624579.5 | R18: {=FAVVAR(P18,Q18,TRUE)} -> -269980.68 | S18: {=SAFEDIV(R18,ABS(Q18))} -> -0.031303634 | T18: =P52 -> 8373378.2 | U18: {=SAFEDIV(P18-T18,ABS(T18))} -> 0.062242735 | W18: =SUMIFS(D18:O18,$D$4:$O$4,"<="&AsOfMonth) -> 5905827 | X18: =SUMIFS(D35:O35,$D$4:$O$4,"<="&AsOfMonth) -> 5727640.5 | Y18: {=FAVVAR(W18,X18,TRUE)} -> -178186.57 | Z18: {=SAFEDIV(Y18,ABS(X18))} -> -0.031109943 | AA18: =SUMIFS(D52:O52,$D$4:$O$4,"<="&AsOfMonth) -> 5556638.9 | AB18: {=SAFEDIV(W18-AA18,ABS(AA18))} -> 0.062841622
B19: EBITDA | D19: =D13-D18 -> 98640.12 | E19: =E13-E18 -> 109888.29 | F19: =F13-F18 -> 162123.04 | G19: =G13-G18 -> 195695.62 | H19: =H13-H18 -> 225140.47 | I19: =I13-I18 -> 258604.11 | J19: =J13-J18 -> 250500.77 | K19: =K13-K18 -> 225358.11 | ... O19: =O13-O18 -> 272650.71 | P19: =SUM(D19:O19) -> 2319179.9 | Q19: =P36 -> 2731657 | R19: {=FAVVAR(P19,Q19,FALSE)} -> -412477.17 | S19: {=SAFEDIV(R19,ABS(Q19))} -> -0.15099889 | T19: =P53 -> 1919310.6 | U19: {=SAFEDIV(P19-T19,ABS(T19))} -> 0.20834002 | W19: =SUMIFS(D19:O19,$D$4:$O$4,"<="&AsOfMonth) -> 1525950.5 | X19: =SUMIFS(D36:O36,$D$4:$O$4,"<="&AsOfMonth) -> 1757686.4 | Y19: {=FAVVAR(W19,X19,FALSE)} -> -231735.84 | Z19: {=SAFEDIV(Y19,ABS(X19))} -> -0.1318414 | AA19: =SUMIFS(D53:O53,$D$4:$O$4,"<="&AsOfMonth) -> 1225776.7 | AB19: {=SAFEDIV(W19-AA19,ABS(AA19))} -> 0.24488462
B20: EBITDA margin % | D20: {=SAFEDIV(D19,D8)} -> 0.029078045 | E20: {=SAFEDIV(E19,E8)} -> 0.031541348 | F20: {=SAFEDIV(F19,F8)} -> 0.043550917 | G20: {=SAFEDIV(G19,G8)} -> 0.050204687 | H20: {=SAFEDIV(H19,H8)} -> 0.053748691 | I20: {=SAFEDIV(I19,I8)} -> 0.059533107 | J20: {=SAFEDIV(J19,J8)} -> 0.058071169 | K20: {=SAFEDIV(K19,K8)} -> 0.053777687 | ... P20: {=SAFEDIV(P19,P8)} -> 0.048920272 | Q20: =P37 -> 0.059683822 | R20: =P20-Q20 -> -0.01076355 | T20: =P54 -> 0.044852984 | U20: =P20-T20 -> 0.0040672877 | W20: {=SAFEDIV(W19,W8)} -> 0.048391209 | X20: {=SAFEDIV(X19,X8)} -> 0.057774196 | Y20: =W20-X20 -> -0.0093829868 | AA20: {=SAFEDIV(AA19,AA8)} -> 0.043091614 | AB20: =W20-AA20 -> 0.0052995953
B23: Budget
B24: Cases sold | D24: =SUMIFS(tbl_Budget[units],tbl_Budget[month],D$4) -> 24262 | E24: =SUMIFS(tbl_Budget[units],tbl_Budget[month],E$4) -> 23600 | F24: =SUMIFS(tbl_Budget[units],tbl_Budget[month],F$4) -> 24954 | G24: =SUMIFS(tbl_Budget[units],tbl_Budget[month],G$4) -> 26010 | H24: =SUMIFS(tbl_Budget[units],tbl_Budget[month],H$4) -> 27666 | I24: =SUMIFS(tbl_Budget[units],tbl_Budget[month],I$4) -> 28362 | J24: =SUMIFS(tbl_Budget[units],tbl_Budget[month],J$4) -> 28149 | K24: =SUMIFS(tbl_Budget[units],tbl_Budget[month],K$4) -> 27529 | ... O24: =SUMIFS(tbl_Budget[units],tbl_Budget[month],O$4) -> 28921 | P24: =SUM(D24:O24) -> 317860
B25: Revenue | D25: =SUMIFS(tbl_Budget[revenue],tbl_Budget[month],D$4) -> 3439390.9 | E25: =SUMIFS(tbl_Budget[revenue],tbl_Budget[month],E$4) -> 3351624.8 | F25: =SUMIFS(tbl_Budget[revenue],tbl_Budget[month],F$4) -> 3562620.3 | G25: =SUMIFS(tbl_Budget[revenue],tbl_Budget[month],G$4) -> 3745449.1 | H25: =SUMIFS(tbl_Budget[revenue],tbl_Budget[month],H$4) -> 4031810.3 | I25: =SUMIFS(tbl_Budget[revenue],tbl_Budget[month],I$4) -> 4156915.1 | J25: =SUMIFS(tbl_Budget[revenue],tbl_Budget[month],J$4) -> 4127204 | K25: =SUMIFS(tbl_Budget[revenue],tbl_Budget[month],K$4) -> 4008366.5 | ... O25: =SUMIFS(tbl_Budget[revenue],tbl_Budget[month],O$4) -> 4109293.5 | P25: =SUM(D25:O25) -> 45768802
B26: Cost of goods sold | D26: =SUMIFS(tbl_Budget[cogs],tbl_Budget[month],D$4) -> 2503134.3 | E26: =SUMIFS(tbl_Budget[cogs],tbl_Budget[month],E$4) -> 2443090.8 | F26: =SUMIFS(tbl_Budget[cogs],tbl_Budget[month],F$4) -> 2599302.9 | G26: =SUMIFS(tbl_Budget[cogs],tbl_Budget[month],G$4) -> 2736112.9 | H26: =SUMIFS(tbl_Budget[cogs],tbl_Budget[month],H$4) -> 2954930.4 | I26: =SUMIFS(tbl_Budget[cogs],tbl_Budget[month],I$4) -> 3051338.8 | J26: =SUMIFS(tbl_Budget[cogs],tbl_Budget[month],J$4) -> 3028927.3 | K26: =SUMIFS(tbl_Budget[cogs],tbl_Budget[month],K$4) -> 2936796.6 | ... O26: =SUMIFS(tbl_Budget[cogs],tbl_Budget[month],O$4) -> 2966215.7 | P26: =SUM(D26:O26) -> 33378999
B27: Gross margin | D27: =D25-D26 -> 936256.58 | E27: =E25-E26 -> 908534.03 | F27: =F25-F26 -> 963317.45 | G27: =G25-G26 -> 1009336.2 | H27: =H25-H26 -> 1076879.9 | I27: =I25-I26 -> 1105576.3 | J27: =J25-J26 -> 1098276.7 | K27: =K25-K26 -> 1071569.9 | ... O27: =O25-O26 -> 1143077.9 | P27: =SUM(D27:O27) -> 12389803
B28: Gross margin % | D28: {=SAFEDIV(D27,D25)} -> 0.27221581 | E28: {=SAFEDIV(E27,E25)} -> 0.27107271 | F28: {=SAFEDIV(F27,F25)} -> 0.27039577 | G28: {=SAFEDIV(G27,G25)} -> 0.26948336 | H28: {=SAFEDIV(H27,H25)} -> 0.26709588 | I28: {=SAFEDIV(I27,I25)} -> 0.26596076 | J28: {=SAFEDIV(J27,J25)} -> 0.26610671 | K28: {=SAFEDIV(K27,K25)} -> 0.26733332 | ... P28: {=SAFEDIV(P27,P25)} -> 0.27070412
B29: Freight | D29: =SUMIFS(tbl_Budget[freight],tbl_Budget[month],D$4) -> 78834.06 | E29: =SUMIFS(tbl_Budget[freight],tbl_Budget[month],E$4) -> 76807.77 | F29: =SUMIFS(tbl_Budget[freight],tbl_Budget[month],F$4) -> 81067.93 | G29: =SUMIFS(tbl_Budget[freight],tbl_Budget[month],G$4) -> 84532.07 | H29: =SUMIFS(tbl_Budget[freight],tbl_Budget[month],H$4) -> 89908.89 | I29: =SUMIFS(tbl_Budget[freight],tbl_Budget[month],I$4) -> 92378.86 | J29: =SUMIFS(tbl_Budget[freight],tbl_Budget[month],J$4) -> 91557.37 | K29: =SUMIFS(tbl_Budget[freight],tbl_Budget[month],K$4) -> 89333.3 | ... O29: =SUMIFS(tbl_Budget[freight],tbl_Budget[month],O$4) -> 94053.98 | P29: =SUM(D29:O29) -> 1033566.9
B30: Contribution | D30: =D27-D29 -> 857422.52 | E30: =E27-E29 -> 831726.26 | F30: =F27-F29 -> 882249.52 | G30: =G27-G29 -> 924804.13 | H30: =H27-H29 -> 986971.06 | I30: =I27-I29 -> 1013197.5 | J30: =J27-J29 -> 1006719.3 | K30: =K27-K29 -> 982236.6 | ... O30: =O27-O29 -> 1049023.9 | P30: =SUM(D30:O30) -> 11356237
B31: Sales & Marketing | D31: =SUMIFS(tbl_Opex[amount],tbl_Opex[month],D$4,tbl_Opex[dept],TRIM($B31),tbl_Opex[scenario],"Budget") -> 201621.39 | E31: =SUMIFS(tbl_Opex[amount],tbl_Opex[month],E$4,tbl_Opex[dept],TRIM($B31),tbl_Opex[scenario],"Budget") -> 201621.39 | F31: =SUMIFS(tbl_Opex[amount],tbl_Opex[month],F$4,tbl_Opex[dept],TRIM($B31),tbl_Opex[scenario],"Budget") -> 201621.39 | G31: =SUMIFS(tbl_Opex[amount],tbl_Opex[month],G$4,tbl_Opex[dept],TRIM($B31),tbl_Opex[scenario],"Budget") -> 201621.39 | H31: =SUMIFS(tbl_Opex[amount],tbl_Opex[month],H$4,tbl_Opex[dept],TRIM($B31),tbl_Opex[scenario],"Budget") -> 201621.39 | I31: =SUMIFS(tbl_Opex[amount],tbl_Opex[month],I$4,tbl_Opex[dept],TRIM($B31),tbl_Opex[scenario],"Budget") -> 201621.39 | J31: =SUMIFS(tbl_Opex[amount],tbl_Opex[month],J$4,tbl_Opex[dept],TRIM($B31),tbl_Opex[scenario],"Budget") -> 201621.39 | K31: =SUMIFS(tbl_Opex[amount],tbl_Opex[month],K$4,tbl_Opex[dept],TRIM($B31),tbl_Opex[scenario],"Budget") -> 201621.39 | ... O31: =SUMIFS(tbl_Opex[amount],tbl_Opex[month],O$4,tbl_Opex[dept],TRIM($B31),tbl_Opex[scenario],"Budget") -> 201621.39 | P31: =SUM(D31:O31) -> 2419456.7
B32: Warehouse & Logistics | D32: =SUMIFS(tbl_Opex[amount],tbl_Opex[month],D$4,tbl_Opex[dept],TRIM($B32),tbl_Opex[scenario],"Budget") -> 275989.67 | E32: =SUMIFS(tbl_Opex[amount],tbl_Opex[month],E$4,tbl_Opex[dept],TRIM($B32),tbl_Opex[scenario],"Budget") -> 275989.67 | F32: =SUMIFS(tbl_Opex[amount],tbl_Opex[month],F$4,tbl_Opex[dept],TRIM($B32),tbl_Opex[scenario],"Budget") -> 275989.67 | G32: =SUMIFS(tbl_Opex[amount],tbl_Opex[month],G$4,tbl_Opex[dept],TRIM($B32),tbl_Opex[scenario],"Budget") -> 275989.67 | H32: =SUMIFS(tbl_Opex[amount],tbl_Opex[month],H$4,tbl_Opex[dept],TRIM($B32),tbl_Opex[scenario],"Budget") -> 275989.67 | I32: =SUMIFS(tbl_Opex[amount],tbl_Opex[month],I$4,tbl_Opex[dept],TRIM($B32),tbl_Opex[scenario],"Budget") -> 275989.67 | J32: =SUMIFS(tbl_Opex[amount],tbl_Opex[month],J$4,tbl_Opex[dept],TRIM($B32),tbl_Opex[scenario],"Budget") -> 275989.67 | K32: =SUMIFS(tbl_Opex[amount],tbl_Opex[month],K$4,tbl_Opex[dept],TRIM($B32),tbl_Opex[scenario],"Budget") -> 275989.67 | ... O32: =SUMIFS(tbl_Opex[amount],tbl_Opex[month],O$4,tbl_Opex[dept],TRIM($B32),tbl_Opex[scenario],"Budget") -> 292549.05 | P32: =SUM(D32:O32) -> 3344994.8
B33: General & Admin | D33: =SUMIFS(tbl_Opex[amount],tbl_Opex[month],D$4,tbl_Opex[dept],TRIM($B33),tbl_Opex[scenario],"Budget") -> 180067.44 | E33: =SUMIFS(tbl_Opex[amount],tbl_Opex[month],E$4,tbl_Opex[dept],TRIM($B33),tbl_Opex[scenario],"Budget") -> 180067.44 | F33: =SUMIFS(tbl_Opex[amount],tbl_Opex[month],F$4,tbl_Opex[dept],TRIM($B33),tbl_Opex[scenario],"Budget") -> 180067.44 | G33: =SUMIFS(tbl_Opex[amount],tbl_Opex[month],G$4,tbl_Opex[dept],TRIM($B33),tbl_Opex[scenario],"Budget") -> 180067.44 | H33: =SUMIFS(tbl_Opex[amount],tbl_Opex[month],H$4,tbl_Opex[dept],TRIM($B33),tbl_Opex[scenario],"Budget") -> 180067.44 | I33: =SUMIFS(tbl_Opex[amount],tbl_Opex[month],I$4,tbl_Opex[dept],TRIM($B33),tbl_Opex[scenario],"Budget") -> 180067.44 | J33: =SUMIFS(tbl_Opex[amount],tbl_Opex[month],J$4,tbl_Opex[dept],TRIM($B33),tbl_Opex[scenario],"Budget") -> 180067.44 | K33: =SUMIFS(tbl_Opex[amount],tbl_Opex[month],K$4,tbl_Opex[dept],TRIM($B33),tbl_Opex[scenario],"Budget") -> 180067.44 | ... O33: =SUMIFS(tbl_Opex[amount],tbl_Opex[month],O$4,tbl_Opex[dept],TRIM($B33),tbl_Opex[scenario],"Budget") -> 180067.44 | P33: =SUM(D33:O33) -> 2160809.3
B34: Technology | D34: =SUMIFS(tbl_Opex[amount],tbl_Opex[month],D$4,tbl_Opex[dept],TRIM($B34),tbl_Opex[scenario],"Budget") -> 58276.56 | E34: =SUMIFS(tbl_Opex[amount],tbl_Opex[month],E$4,tbl_Opex[dept],TRIM($B34),tbl_Opex[scenario],"Budget") -> 58276.56 | F34: =SUMIFS(tbl_Opex[amount],tbl_Opex[month],F$4,tbl_Opex[dept],TRIM($B34),tbl_Opex[scenario],"Budget") -> 58276.56 | G34: =SUMIFS(tbl_Opex[amount],tbl_Opex[month],G$4,tbl_Opex[dept],TRIM($B34),tbl_Opex[scenario],"Budget") -> 58276.56 | H34: =SUMIFS(tbl_Opex[amount],tbl_Opex[month],H$4,tbl_Opex[dept],TRIM($B34),tbl_Opex[scenario],"Budget") -> 58276.56 | I34: =SUMIFS(tbl_Opex[amount],tbl_Opex[month],I$4,tbl_Opex[dept],TRIM($B34),tbl_Opex[scenario],"Budget") -> 58276.56 | J34: =SUMIFS(tbl_Opex[amount],tbl_Opex[month],J$4,tbl_Opex[dept],TRIM($B34),tbl_Opex[scenario],"Budget") -> 58276.56 | K34: =SUMIFS(tbl_Opex[amount],tbl_Opex[month],K$4,tbl_Opex[dept],TRIM($B34),tbl_Opex[scenario],"Budget") -> 58276.56 | ... O34: =SUMIFS(tbl_Opex[amount],tbl_Opex[month],O$4,tbl_Opex[dept],TRIM($B34),tbl_Opex[scenario],"Budget") -> 58276.56 | P34: =SUM(D34:O34) -> 699318.72
B35: Total operating expenses | D35: =SUM(D31:D34) -> 715955.06 | E35: =SUM(E31:E34) -> 715955.06 | F35: =SUM(F31:F34) -> 715955.06 | G35: =SUM(G31:G34) -> 715955.06 | H35: =SUM(H31:H34) -> 715955.06 | I35: =SUM(I31:I34) -> 715955.06 | J35: =SUM(J31:J34) -> 715955.06 | K35: =SUM(K31:K34) -> 715955.06 | ... O35: =SUM(O31:O34) -> 732514.44 | P35: =SUM(D35:O35) -> 8624579.5
B36: EBITDA | D36: =D30-D35 -> 141467.46 | E36: =E30-E35 -> 115771.2 | F36: =F30-F35 -> 166294.46 | G36: =G30-G35 -> 208849.07 | H36: =H30-H35 -> 271016 | I36: =I30-I35 -> 297242.4 | J36: =J30-J35 -> 290764.24 | K36: =K30-K35 -> 266281.54 | ... O36: =O30-O35 -> 316509.43 | P36: =SUM(D36:O36) -> 2731657
B37: EBITDA margin % | D37: {=SAFEDIV(D36,D25)} -> 0.041131545 | E37: {=SAFEDIV(E36,E25)} -> 0.034541814 | F37: {=SAFEDIV(F36,F25)} -> 0.04667757 | G37: {=SAFEDIV(G36,G25)} -> 0.055760755 | H37: {=SAFEDIV(H36,H25)} -> 0.067219432 | I37: {=SAFEDIV(I36,I25)} -> 0.071505525 | J37: {=SAFEDIV(J36,J25)} -> 0.070450658 | K37: {=SAFEDIV(K36,K25)} -> 0.066431436 | ... P37: {=SAFEDIV(P36,P25)} -> 0.059683822
B40: Prior year (actuals)
B41: Cases sold | D41: =SUMIFS(tbl_Sales[units],tbl_Sales[month],EDATE(D$4,-12)) -> 23609 | E41: =SUMIFS(tbl_Sales[units],tbl_Sales[month],EDATE(E$4,-12)) -> 22956 | F41: =SUMIFS(tbl_Sales[units],tbl_Sales[month],EDATE(F$4,-12)) -> 24276 | G41: =SUMIFS(tbl_Sales[units],tbl_Sales[month],EDATE(G$4,-12)) -> 25301 | H41: =SUMIFS(tbl_Sales[units],tbl_Sales[month],EDATE(H$4,-12)) -> 26908 | I41: =SUMIFS(tbl_Sales[units],tbl_Sales[month],EDATE(I$4,-12)) -> 27577 | J41: =SUMIFS(tbl_Sales[units],tbl_Sales[month],EDATE(J$4,-12)) -> 27379 | K41: =SUMIFS(tbl_Sales[units],tbl_Sales[month],EDATE(K$4,-12)) -> 26778 | ... O41: =SUMIFS(tbl_Sales[units],tbl_Sales[month],EDATE(O$4,-12)) -> 28110 | P41: =SUM(D41:O41) -> 309144
B42: Revenue | D42: =SUMIFS(tbl_Sales[net_revenue],tbl_Sales[month],EDATE(D$4,-12)) -> 3218241.6 | E42: =SUMIFS(tbl_Sales[net_revenue],tbl_Sales[month],EDATE(E$4,-12)) -> 3130900.3 | F42: =SUMIFS(tbl_Sales[net_revenue],tbl_Sales[month],EDATE(F$4,-12)) -> 3334202.5 | G42: =SUMIFS(tbl_Sales[net_revenue],tbl_Sales[month],EDATE(G$4,-12)) -> 3503499.3 | H42: =SUMIFS(tbl_Sales[net_revenue],tbl_Sales[month],EDATE(H$4,-12)) -> 3770601.9 | I42: =SUMIFS(tbl_Sales[net_revenue],tbl_Sales[month],EDATE(I$4,-12)) -> 3886478.4 | J42: =SUMIFS(tbl_Sales[net_revenue],tbl_Sales[month],EDATE(J$4,-12)) -> 3854332.6 | K42: =SUMIFS(tbl_Sales[net_revenue],tbl_Sales[month],EDATE(K$4,-12)) -> 3747572.4 | ... O42: =SUMIFS(tbl_Sales[net_revenue],tbl_Sales[month],EDATE(O$4,-12)) -> 3837508.8 | P42: =SUM(D42:O42) -> 42791147
B43: Cost of goods sold | D43: =SUMIFS(tbl_Sales[cogs],tbl_Sales[month],EDATE(D$4,-12)) -> 2364516.3 | E43: =SUMIFS(tbl_Sales[cogs],tbl_Sales[month],EDATE(E$4,-12)) -> 2306988 | F43: =SUMIFS(tbl_Sales[cogs],tbl_Sales[month],EDATE(F$4,-12)) -> 2454814.8 | G43: =SUMIFS(tbl_Sales[cogs],tbl_Sales[month],EDATE(G$4,-12)) -> 2583957.8 | H43: =SUMIFS(tbl_Sales[cogs],tbl_Sales[month],EDATE(H$4,-12)) -> 2789435.4 | I43: =SUMIFS(tbl_Sales[cogs],tbl_Sales[month],EDATE(I$4,-12)) -> 2878998.2 | J43: =SUMIFS(tbl_Sales[cogs],tbl_Sales[month],EDATE(J$4,-12)) -> 2859812.6 | K43: =SUMIFS(tbl_Sales[cogs],tbl_Sales[month],EDATE(K$4,-12)) -> 2771600.2 | ... O43: =SUMIFS(tbl_Sales[cogs],tbl_Sales[month],EDATE(O$4,-12)) -> 2797934.9 | P43: =SUM(D43:O43) -> 31512171
B44: Gross margin | D44: =D42-D43 -> 853725.32 | E44: =E42-E43 -> 823912.31 | F44: =F42-F43 -> 879387.74 | G44: =G42-G43 -> 919541.52 | H44: =H42-H43 -> 981166.46 | I44: =I42-I43 -> 1007480.2 | J44: =J42-J43 -> 994520 | K44: =K42-K43 -> 975972.23 | ... O44: =O42-O43 -> 1039574 | P44: =SUM(D44:O44) -> 11278976
B45: Gross margin % | D45: {=SAFEDIV(D44,D42)} -> 0.26527695 | E45: {=SAFEDIV(E44,E42)} -> 0.26315508 | F45: {=SAFEDIV(F44,F42)} -> 0.26374755 | G45: {=SAFEDIV(G44,G42)} -> 0.26246374 | H45: {=SAFEDIV(H44,H42)} -> 0.26021481 | I45: {=SAFEDIV(I44,I42)} -> 0.25922702 | J45: {=SAFEDIV(J44,J42)} -> 0.25802651 | K45: {=SAFEDIV(K44,K42)} -> 0.26042785 | ... P45: {=SAFEDIV(P44,P42)} -> 0.263582
...

Sheet PVM
B1: Price-volume-mix: why margin moved against budget
B2: Gross-margin variance split four ways on 24 category × channel segments. Each segment's change in cases is valued at the budget's average margin per case (volume) and at its own margin's distance from that average (mix); price and cost are per-case changes on actual cases. The four effects add up to every segment's variance exactly: column V is zero.
B4: ="Month: "&TEXT(AsOfMonth,"mmmm yyyy")&" against budget" -> Month: August 2026 against budget
B5: Category | C5: Channel | D5: Budget cases | E5: Budget revenue | F5: Budget COGS | G5: Actual cases | H5: Actual revenue | I5: Actual COGS | J5: Budget price / case | K5: Actual price / case | L5: Budget cost / case | M5: Actual cost / case | N5: Budget margin / case | O5: Share shift | P5: Volume | Q5: Mix | R5: Price | S5: Unit cost | T5: Effects, total | U5: GM variance | V5: Unexplained | W5: Main driver
B6: Beef | C6: Restaurants | D6: =SUMIFS(tbl_Budget[units],tbl_Budget[category],$B6,tbl_Budget[channel],$C6,tbl_Budget[month],">="&AsOfMonth,tbl_Budget[month],"<="&AsOfMonth) -> 2959 | E6: =SUMIFS(tbl_Budget[revenue],tbl_Budget[category],$B6,tbl_Budget[channel],$C6,tbl_Budget[month],">="&AsOfMonth,tbl_Budget[month],"<="&AsOfMonth) -> 583426.31 | F6: =SUMIFS(tbl_Budget[cogs],tbl_Budget[category],$B6,tbl_Budget[channel],$C6,tbl_Budget[month],">="&AsOfMonth,tbl_Budget[month],"<="&AsOfMonth) -> 431578.03 | G6: =SUMIFS(tbl_Sales[units],tbl_Sales[category],$B6,tbl_Sales[channel],$C6,tbl_Sales[month],">="&AsOfMonth,tbl_Sales[month],"<="&AsOfMonth) -> 2931 | H6: =SUMIFS(tbl_Sales[net_revenue],tbl_Sales[category],$B6,tbl_Sales[channel],$C6,tbl_Sales[month],">="&AsOfMonth,tbl_Sales[month],"<="&AsOfMonth) -> 584467.03 | I6: =SUMIFS(tbl_Sales[cogs],tbl_Sales[category],$B6,tbl_Sales[channel],$C6,tbl_Sales[month],">="&AsOfMonth,tbl_Sales[month],"<="&AsOfMonth) -> 456580.44 | J6: {=SAFEDIV(E6,D6)} -> 197.17009 | K6: {=SAFEDIV(H6,G6)} -> 199.40874 | L6: {=SAFEDIV(F6,D6)} -> 145.85266 | M6: {=SAFEDIV(I6,G6)} -> 155.77634 | N6: =J6-L6 -> 51.317432 | O6: {=SAFEDIV(G6,G$30)-SAFEDIV(D6,D$30)} -> -0.0057687952 | P6: =(G6-D6)*N$30 -> -1089.9036 | Q6: =(G6-D6)*(N6-N$30) -> -346.98445 | R6: =G6*(K6-J6) -> 6561.4826 | S6: =-G6*(M6-L6) -> -29086.285 | T6: =SUM(P6:S6) -> -23961.69 | U6: =(H6-I6)-(E6-F6) -> -23961.69 | V6: =T6-U6 -> 0 | W6: {=INDEX({"Volume","Mix","Price","Unit cost"},_xlfn.XMATCH(MAX(ABS(P6:S6)),ABS(P6:S6)))} -> Unit cost
B7: Beef | C7: Grocery Retail | D7: =SUMIFS(tbl_Budget[units],tbl_Budget[category],$B7,tbl_Budget[channel],$C7,tbl_Budget[month],">="&AsOfMonth,tbl_Budget[month],"<="&AsOfMonth) -> 2025 | E7: =SUMIFS(tbl_Budget[revenue],tbl_Budget[category],$B7,tbl_Budget[channel],$C7,tbl_Budget[month],">="&AsOfMonth,tbl_Budget[month],"<="&AsOfMonth) -> 347499.93 | F7: =SUMIFS(tbl_Budget[cogs],tbl_Budget[category],$B7,tbl_Budget[channel],$C7,tbl_Budget[month],">="&AsOfMonth,tbl_Budget[month],"<="&AsOfMonth) -> 296251.17 | G7: =SUMIFS(tbl_Sales[units],tbl_Sales[category],$B7,tbl_Sales[channel],$C7,tbl_Sales[month],">="&AsOfMonth,tbl_Sales[month],"<="&AsOfMonth) -> 2331 | H7: =SUMIFS(tbl_Sales[net_revenue],tbl_Sales[category],$B7,tbl_Sales[channel],$C7,tbl_Sales[month],">="&AsOfMonth,tbl_Sales[month],"<="&AsOfMonth) -> 402742.6 | I7: =SUMIFS(tbl_Sales[cogs],tbl_Sales[category],$B7,tbl_Sales[channel],$C7,tbl_Sales[month],">="&AsOfMonth,tbl_Sales[month],"<="&AsOfMonth) -> 364589.83 | J7: {=SAFEDIV(E7,D7)} -> 171.6049 | K7: {=SAFEDIV(H7,G7)} -> 172.77675 | L7: {=SAFEDIV(F7,D7)} -> 146.29687 | M7: {=SAFEDIV(I7,G7)} -> 156.40919 | N7: =J7-L7 -> 25.30803 | O7: {=SAFEDIV(G7,G$30)-SAFEDIV(D7,D$30)} -> 0.0073365745 | P7: =(G7-D7)*N$30 -> 11911.09 | Q7: =(G7-D7)*(N7-N$30) -> -4166.8327 | R7: =G7*(K7-J7) -> 2731.5695 | S7: =-G7*(M7-L7) -> -23571.817 | T7: =SUM(P7:S7) -> -13095.99 | U7: =(H7-I7)-(E7-F7) -> -13095.99 | V7: =T7-U7 -> -6.184564e-11 | W7: {=INDEX({"Volume","Mix","Price","Unit cost"},_xlfn.XMATCH(MAX(ABS(P7:S7)),ABS(P7:S7)))} -> Unit cost
B8: Beef | C8: Hotels & Institutions | D8: =SUMIFS(tbl_Budget[units],tbl_Budget[category],$B8,tbl_Budget[channel],$C8,tbl_Budget[month],">="&AsOfMonth,tbl_Budget[month],"<="&AsOfMonth) -> 1240 | E8: =SUMIFS(tbl_Budget[revenue],tbl_Budget[category],$B8,tbl_Budget[channel],$C8,tbl_Budget[month],">="&AsOfMonth,tbl_Budget[month],"<="&AsOfMonth) -> 231979.01 | F8: =SUMIFS(tbl_Budget[cogs],tbl_Budget[category],$B8,tbl_Budget[channel],$C8,tbl_Budget[month],">="&AsOfMonth,tbl_Budget[month],"<="&AsOfMonth) -> 180751.94 | G8: =SUMIFS(tbl_Sales[units],tbl_Sales[category],$B8,tbl_Sales[channel],$C8,tbl_Sales[month],">="&AsOfMonth,tbl_Sales[month],"<="&AsOfMonth) -> 1183 | H8: =SUMIFS(tbl_Sales[net_revenue],tbl_Sales[category],$B8,tbl_Sales[channel],$C8,tbl_Sales[month],">="&AsOfMonth,tbl_Sales[month],"<="&AsOfMonth) -> 223595.78 | I8: =SUMIFS(tbl_Sales[cogs],tbl_Sales[category],$B8,tbl_Sales[channel],$C8,tbl_Sales[month],">="&AsOfMonth,tbl_Sales[month],"<="&AsOfMonth) -> 184475.94 | J8: {=SAFEDIV(E8,D8)} -> 187.07985 | K8: {=SAFEDIV(H8,G8)} -> 189.00742 | L8: {=SAFEDIV(F8,D8)} -> 145.76769 | M8: {=SAFEDIV(I8,G8)} -> 155.93909 | N8: =J8-L8 -> 41.312153 | O8: {=SAFEDIV(G8,G$30)-SAFEDIV(D8,D$30)} -> -0.0039884027 | P8: =(G8-D8)*N$30 -> -2218.7324 | Q8: =(G8-D8)*(N8-N$30) -> -136.06033 | R8: =G8*(K8-J8) -> 2280.3213 | S8: =-G8*(M8-L8) -> -12032.759 | T8: =SUM(P8:S8) -> -12107.23 | U8: =(H8-I8)-(E8-F8) -> -12107.23 | V8: =T8-U8 -> -2.3646862e-11 | W8: {=INDEX({"Volume","Mix","Price","Unit cost"},_xlfn.XMATCH(MAX(ABS(P8:S8)),ABS(P8:S8)))} -> Unit cost
B9: Beef | C9: Online Direct | D9: =SUMIFS(tbl_Budget[units],tbl_Budget[category],$B9,tbl_Budget[channel],$C9,tbl_Budget[month],">="&AsOfMonth,tbl_Budget[month],"<="&AsOfMonth) -> 541 | E9: =SUMIFS(tbl_Budget[revenue],tbl_Budget[category],$B9,tbl_Budget[channel],$C9,tbl_Budget[month],">="&AsOfMonth,tbl_Budget[month],"<="&AsOfMonth) -> 118826.82 | F9: =SUMIFS(tbl_Budget[cogs],tbl_Budget[category],$B9,tbl_Budget[channel],$C9,tbl_Budget[month],">="&AsOfMonth,tbl_Budget[month],"<="&AsOfMonth) -> 78401.95 | G9: =SUMIFS(tbl_Sales[units],tbl_Sales[category],$B9,tbl_Sales[channel],$C9,tbl_Sales[month],">="&AsOfMonth,tbl_Sales[month],"<="&AsOfMonth) -> 531 | H9: =SUMIFS(tbl_Sales[net_revenue],tbl_Sales[category],$B9,tbl_Sales[channel],$C9,tbl_Sales[month],">="&AsOfMonth,tbl_Sales[month],"<="&AsOfMonth) -> 118874.18 | I9: =SUMIFS(tbl_Sales[cogs],tbl_Sales[category],$B9,tbl_Sales[channel],$C9,tbl_Sales[month],">="&AsOfMonth,tbl_Sales[month],"<="&AsOfMonth) -> 83168.69 | J9: {=SAFEDIV(E9,D9)} -> 219.64292 | K9: {=SAFEDIV(H9,G9)} -> 223.86851 | L9: {=SAFEDIV(F9,D9)} -> 144.92043 | M9: {=SAFEDIV(I9,G9)} -> 156.62653 | N9: =J9-L9 -> 74.722495 | O9: {=SAFEDIV(G9,G$30)-SAFEDIV(D9,D$30)} -> -0.0012241012 | P9: =(G9-D9)*N$30 -> -389.2513 | Q9: =(G9-D9)*(N9-N$30) -> -357.97366 | R9: =G9*(K9-J9) -> 2243.7892 | S9: =-G9*(M9-L9) -> -6215.9443 | T9: =SUM(P9:S9) -> -4719.38 | U9: =(H9-I9)-(E9-F9) -> -4719.38 | V9: =T9-U9 -> -1.2732926e-11 | W9: {=INDEX({"Volume","Mix","Price","Unit cost"},_xlfn.XMATCH(MAX(ABS(P9:S9)),ABS(P9:S9)))} -> Unit cost
B10: Pork | C10: Restaurants | D10: =SUMIFS(tbl_Budget[units],tbl_Budget[category],$B10,tbl_Budget[channel],$C10,tbl_Budget[month],">="&AsOfMonth,tbl_Budget[month],"<="&AsOfMonth) -> 2377 | E10: =SUMIFS(tbl_Budget[revenue],tbl_Budget[category],$B10,tbl_Budget[channel],$C10,tbl_Budget[month],">="&AsOfMonth,tbl_Budget[month],"<="&AsOfMonth) -> 296153.46 | F10: =SUMIFS(tbl_Budget[cogs],tbl_Budget[category],$B10,tbl_Budget[channel],$C10,tbl_Budget[month],">="&AsOfMonth,tbl_Budget[month],"<="&AsOfMonth) -> 206363.81 | G10: =SUMIFS(tbl_Sales[units],tbl_Sales[category],$B10,tbl_Sales[channel],$C10,tbl_Sales[month],">="&AsOfMonth,tbl_Sales[month],"<="&AsOfMonth) -> 2383 | H10: =SUMIFS(tbl_Sales[net_revenue],tbl_Sales[category],$B10,tbl_Sales[channel],$C10,tbl_Sales[month],">="&AsOfMonth,tbl_Sales[month],"<="&AsOfMonth) -> 297549.75 | I10: =SUMIFS(tbl_Sales[cogs],tbl_Sales[category],$B10,tbl_Sales[channel],$C10,tbl_Sales[month],">="&AsOfMonth,tbl_Sales[month],"<="&AsOfMonth) -> 207729.97 | J10: {=SAFEDIV(E10,D10)} -> 124.59127 | K10: {=SAFEDIV(H10,G10)} -> 124.86351 | L10: {=SAFEDIV(F10,D10)} -> 86.816916 | M10: {=SAFEDIV(I10,G10)} -> 87.17162 | N10: =J10-L10 -> 37.774358 | O10: {=SAFEDIV(G10,G$30)-SAFEDIV(D10,D$30)} -> -0.0036453259 | P10: =(G10-D10)*N$30 -> 233.55078 | Q10: =(G10-D10)*(N10-N$30) -> -6.9046286 | R10: =G10*(K10-J10) -> 648.74235 | S10: =-G10*(M10-L10) -> -845.2585 | T10: =SUM(P10:S10) -> 30.13 | U10: =(H10-I10)-(E10-F10) -> 30.13 | V10: =T10-U10 -> 2.5011104e-12 | W10: {=INDEX({"Volume","Mix","Price","Unit cost"},_xlfn.XMATCH(MAX(ABS(P10:S10)),ABS(P10:S10)))} -> Unit cost
