Workbook
Name actual_cdd: Weather!$C$15:$N$15
Name actual_hdd: Weather!$C$14:$N$14
Name AsOfMonth: Assumptions!$C$6
Name backtest: Plan!$B$113:$H$116
Name BaseYear: Assumptions!$C$13
Name bridge_long: PVM!$C$34:$C$38
Name CddOverlay: Scenarios!$C$9
Name CddScale: INDEX(ScenarioCdd,ScenarioNo)*CddOverlay
Name checks_status: Checks!$H$6:$H$36
Name checks_summary: Checks!$B$2
Name coef_commercial: Weather!$C$7:$G$7
Name coef_residential: Weather!$C$6:$G$6
Name CompanyId: Assumptions!$C$12
Name cover_answers: Cover!$C$13:$C$17
Name CPK: _xlfn.LAMBDA(_xlpm.revenue,_xlpm.mwh,SAFEDIV(_xlpm.revenue,_xlpm.mwh)/10)
Name ctrl_eia_mwh: Checks!$D$42
Name ctrl_eia_revenue_k: Checks!$D$43
Name ctrl_eia_rows: Checks!$D$41
Name ctrl_ferc_rows: Checks!$D$44
Name ctrl_noaa_lines: Checks!$D$45
Name CustOverlay: Scenarios!$C$7
Name dash_commentary: Dashboard!$B$11:$B$15
Name dash_outlook_table: Dashboard!$K$57:$S$61
Name dash_plan_table: Dashboard!$B$57:$J$61
Name explore_cube: Explore!$C$28:$F$32
Name explore_yoy: Explore!$G$28:$I$32
Name ExtraMW: Scenarios!$C$6
Name fc_degree_days: Forecast!$C$13:$N$14
Name fc_drivers: Forecast!$D$6:$L$9
Name fc_long: Forecast!$B$19:$K$66
Name fc_months: Forecast!$B$80:$H$91
Name fc_months_total: Forecast!$C$92:$H$92
Name fc_outlook: Forecast!$D$71:$L$74
Name fc_outlook_total: Forecast!$D$75:$L$75
Name FercYear: Assumptions!$C$14
Name FiscalYear: Assumptions!$C$7
Name fit_months: Weather!$H$6:$H$7
Name FitStart: Assumptions!$C$10
Name fy_mwh: Forecast!$K$75
Name fy_revenue: Forecast!$F$75
Name FYStart: Assumptions!$C$8
Name h2_revenue: Forecast!$E$75
Name HddOverlay: Scenarios!$C$8
Name HddScale: INDEX(ScenarioHdd,ScenarioNo)*HddOverlay
Name ISCLOSED: _xlfn.LAMBDA(_xlpm.month,_xlpm.month<=AsOfMonth)
Name kpi_fy_revenue: Dashboard!$B$5
Name kpi_industrial_growth: Dashboard!$K$5
Name kpi_op_margin: Dashboard!$Q$5
Name kpi_price: Dashboard!$N$5
Name kpi_weather_gwh: Dashboard!$H$5
Name kpi_ytd_vs_plan: Dashboard!$E$5
Name MONEY: _xlfn.LAMBDA(_xlpm.x,IF(ABS(_xlpm.x)>=999500000,TEXT(_xlpm.x/1000000000,"$#,##0.00")&"B",IF(ABS(_xlpm.x)>=999500,TEXT(_xlpm.x/1000000,"$#,##0.0")&"M",TEXT(_xlpm.x/1000,"$#,##0")&"K")))
Name monthly_ytd: Monthly!$D$6:$Q$9
Name monthly_ytd_total: Monthly!$D$10:$Q$10
Name MonthsClosed: Assumptions!$C$9
Name normal_cdd: Weather!$C$13:$N$13
Name normal_hdd: Weather!$C$12:$N$12
Name NormalYears: Assumptions!$C$11
Name offset_loss: Scenarios!$C$46
Name offset_rate: Scenarios!$C$47

Sheet Cover
B2: Portland General Electric
B3: Utility FP&A model on public filings: FERC, EIA and NOAA
B4: Plan against actual · weather normalization · price-volume-mix · rolling forecast · scenarios · peers
B6: Every figure is a live formula, Power Query step or DAX measure over public regulatory data: PGE's monthly returns to the U.S. Energy Information Administration, its audited annual FERC Form 1 (processed by Catalyst Cooperative's PUDL project), and NOAA's degree days for the Willamette Valley.
B7: Independent analysis. Not affiliated with or endorsed by Portland General Electric.
B8: Built by Kush Patel · github.com/KushPatel29/excel-fpa-model
B10: Model status | C10: =checks_summary -> All 31 checks pass | D10: Open the checks →
B12: Five questions it answers, live from the model
B13: Is the year on plan, and if not, why? | C13: {="Year to date "&MONEY(ABS(INDEX(plan_bridge_total,7)))&IF(INDEX(plan_bridge_total,7)<0," under"," over")&" plan ("&TEXT(INDEX(plan_bridge_total,8),"+0.0%;-0.0%")&"): weather "&SIGNMONEY(INDEX(plan_bridge_total,3))&", price "&SIGNMONEY(INDEX(plan_bridge_total,5))&", usage "&SIGNMONEY(INDEX(plan_bridge_total,4))&"."} -> Year to date $100.9M under plan (-6.4%): weather −$40.4M, price −$42.3M, usage −$18.3M. | D13: Plan →
B14: How much of that is the weather? | C14: {="Weather against normal: "&TEXT(INDEX(weather_impact_total,11)/1000,"+#,##0;-#,##0")&" GWh and "&SIGNMONEY(INDEX(weather_impact_total,12))&" of revenue this year."} -> Weather against normal: -212 GWh and −$38.7M of revenue this year. | D14: Weather →
B15: Where did revenue growth come from? | C15: {="Since "&BaseYear&": price "&SIGNMONEY(PVM!L11)&", volume "&SIGNMONEY(PVM!J11)&", mix "&SIGNMONEY(PVM!K11)&"."} -> Since 2019: price +$993.6M, volume +$275.4M, mix −$89.0M. | D15: PVM →
B16: Where will the year land? | C16: {="Retail revenue "&MONEY(fy_revenue)&", "&TEXT(Forecast!H75,"+0.0%;-0.0%")&" on "&(FiscalYear-1)&"; a point of rate on the open months is worth "&MONEY(INDEX(tornado,1))&"."} -> Retail revenue $3.01B, +2.7% on 2025; a point of rate on the open months is worth $15.4M. | D16: Forecast →
B17: How does PGE compare with its neighbours? | C17: ="Industrial load growing "&TEXT(INDEX(peers_table,8,1),"0.0%")&" a year, rank "&INDEX(peers_rank,8)&" of 5; retail price "&TEXT(INDEX(peers_table,4,1),"0.0")&"¢/kWh, rank "&INDEX(peers_rank,4)&" of 5." -> Industrial load growing 10.9% a year, rank 1 of 5; retail price 14.9¢/kWh, rank 2 of 5. | D17: Peers →
B19: Sheets
B20: Sheet | C20: What it shows | D20: Excel on show
B21: Dashboard | C21: One page: plan against actual, weather, price mix, the outlook, and a summary written by formulas. | D21: Formula-driven commentary, waterfalls, combo chart, sparklines, LET
B22: PnL | C22: Twelve years of PGE's electric P&L from FERC Form 1, with unit economics. | D22: SUMIFS over a long table with array criteria, named LAMBDAs, CAGR
B23: PVM | C23: Where retail revenue growth came from: volume, mix and price by customer class. | D23: Exact three-effect decomposition, waterfall
B24: Monthly | C24: EIA's monthly survey by class, a revenue heat map, and the EIA-to-FERC tie-out. | D24: SUMIFS, colour scales, cross-source reconciliation
B25: Weather | C25: How much load follows the thermostat; this year's weather impact. | D25: LINEST on FILTER + HSTACK, normals with FILTER/AVERAGE
B26: Plan | C26: A plan built only from data before the year, against actuals, split four ways; backtested. | D26: Month-by-class model, what-if data table on the plan year
B27: Forecast | C27: The rest of the year from drivers and observed weather; a FORECAST.ETS cross-check. | D27: XLOOKUP with fallbacks, FORECAST.ETS
B28: Scenarios | C28: Weather, rates, data-center load: tables that re-run the model, and a tornado. | D28: One- and two-variable data tables, SORTBY + HSTACK
B29: Peers | C29: PGE against four Pacific Northwest utilities on price, growth and cost. | D29: SUMIFS by respondent, RANK.EQ
B30: Explore | C30: The same data as a Power Pivot model: PivotTable, slicers, CUBEVALUE. | D30: Power Pivot, DAX (TREATAS time intelligence), CUBEVALUE
B31: Checks | C31: 31 controls that prove the numbers, each with its own tolerance. | D31: Reconciliations
... B35: Data_EIA | C35: The public extracts, exactly as published. | D35: Excel tables, structured references
B37: How to use it
B38: 1 Move a lever | C38: Scenarios!C4:C9: weather, a rate change, new data-center load. Every sheet follows.
B39: 2 Re-run the plan as of another year | C39: Plan!C4. The backtest on the same sheet does it for four years.
B40: 3 Explore the data model | C40: The slicers on Explore filter a PivotTable built on DAX measures.
B41: 4 Refresh the data | C41: python pipeline/fetch_sources.py downloads the latest public releases; rebuild.
B43: Sources and conventions
B44: EIA-861M | C44: U.S. Energy Information Administration, monthly electric utility sales and revenue. Public domain.
B45: FERC Form 1 | C45: Federal Energy Regulatory Commission annual report, via Catalyst Cooperative's PUDL (CC BY 4.0).
B46: NOAA nClimDiv | C46: NOAA National Centers for Environmental Information, divisional degree days. Public domain.
B47: 0.01 | C47: Input: blue on yellow. Change these; everything else is calculated.
B48: +1,234 (1,234) | C48: Variances are signed so favourable is positive (green) and unfavourable is in brackets (red).

Sheet Dashboard
B1: ="Portland General Electric: "&FiscalYear&" retail revenue, plan and outlook" -> Portland General Electric: 2026 retail revenue, plan and outlook
B2: ="Actuals from EIA through "&TEXT(AsOfMonth,"mmmm yyyy")&" · FERC Form 1 through "&FercYear&" · weather: NOAA, Willamette Valley · scenario: "&WeatherScenario&" · "&checks_summary -> Actuals from EIA through June 2026 · FERC Form 1 through 2025 · weather: NOAA, Willamette Valley · scenario: Normal · All 31 checks pass
B4: =UPPER("Retail revenue, "&FiscalYear&" outlook") -> RETAIL REVENUE, 2026 OUTLOOK | E4: YEAR TO DATE AGAINST PLAN | H4: WEATHER AGAINST NORMAL, YTD | K4: INDUSTRIAL LOAD, YTD | N4: AVERAGE RETAIL PRICE, YTD | Q4: =UPPER("Operating margin, FERC "&FercYear) -> OPERATING MARGIN, FERC 2025
B5: =fy_revenue -> 3.0076648e+09 | E5: =INDEX(plan_bridge_total,7) -> -1.0094098e+08 | H5: =INDEX(weather_impact_total,11)/1000 -> -211.51445 | K5: =Monthly!I8 -> 0.12163369 | N5: =Monthly!J10 -> 14.75726 | Q5: =INDEX(pnl_op_margin,1,MATCH(FercYear,pnl_years,0)) -> 0.15287796
B6: =Forecast!H75 -> 0.027144809 | E6: =INDEX(plan_bridge_total,8) -> -0.064256653 | H6: =INDEX(weather_impact_total,12) -> -38674235 | K6: megawatt-hours, on last year | N6: =Monthly!L10 -> 0.0015430234 | Q6: =PnL!P33 -> -0.019790371
E7: {="weather "&SIGNMONEY(INDEX(plan_bridge_total,3))&" · price "&SIGNMONEY(INDEX(plan_bridge_total,5))} -> weather −$40.4M · price −$42.3M
B8: {="plan "&MONEY(Forecast!I75)&" · "&SIGNMONEY(Forecast!J75)} -> plan $3.19B · −$184.2M | E8: ="plan from data to Dec "&(PlanYear-1) -> plan from data to Dec 2025 | H8: {="heating degree days "&TEXT(SAFEDIV(INDEX(weather_impact_total,1),SUM(INDEX(normal_hdd,1,1):INDEX(normal_hdd,1,MonthsClosed))),"+0%;-0%")&" vs normal"} -> heating degree days -13% vs normal | K8: ="plan assumed "&TEXT(Plan!I11-1,"+0%;-0%") -> plan assumed +17% | N8: ="classes "&TEXT(MIN(Monthly!L6:L8),"+0.0%")&" to "&TEXT(MAX(Monthly!L6:L8),"+0.0%") -> classes +0.8% to +2.9% | Q8: ="before income tax, since "&BaseYear -> before income tax, since 2019
B10: What the numbers say
B11: {="Retail revenue for "&TEXT(FYStart,"mmm")&"–"&TEXT(AsOfMonth,"mmm")&" came in "&MONEY(ABS(INDEX(plan_bridge_total,7)))&" ("&TEXT(ABS(INDEX(plan_bridge_total,8)),"0.0%")&")"&IF(INDEX(plan_bridge_total,7)<0," under"," over")&" plan: weather "&SIGNMONEY(INDEX(plan_bridge_total,3))&", price "&SIGNMONEY(INDEX(plan_bridge_total,5))&", usage "&SIGNMONEY(INDEX(plan_bridge_total,4))&", customers "&SIGNMONEY(INDEX(plan_bridge_total,2))&"."} -> Retail revenue for Jan–Jun came in $100.9M (6.4%) under plan: weather −$40.4M, price −$42.3M, usage −$18.3M, customers +$79K.
B12: {=_xlfn.LET(_xlpm.dev,SAFEDIV(INDEX(weather_impact_total,1),SUM(INDEX(normal_hdd,1,1):INDEX(normal_hdd,1,MonthsClosed))),"Heating degree days ran "&TEXT(ABS(_xlpm.dev),"0%")&IF(_xlpm.dev<0," below"," above")&" normal: "&TEXT(ABS(INDEX(weather_impact_total,11))/1000,"#,##0")&" GWh of load and "&MONEY(ABS(INDEX(weather_impact_total,12)))&" of revenue"&IF(INDEX(weather_impact_total,12)<0," lost"," gained")&" to the thermostat, at actual prices.")} -> Heating degree days ran 13% below normal: 212 GWh of load and $38.7M of revenue lost to the thermostat, at actual prices.
B13: =_xlfn.LET(_xlpm.p,Monthly!L6:L8,"Every class paid more per kWh ("&TEXT(MIN(_xlpm.p),"+0.0%")&" to "&TEXT(MAX(_xlpm.p),"+0.0%")&"), yet the average rose "&TEXT(Monthly!L10,"+0.0%;-0.0%")&": the growth is industrial load ("&TEXT(Monthly!I8,"+0.0%")&" MWh), billed at "&TEXT(Monthly!J8,"0.0")&"¢ against "&TEXT(Monthly!J6,"0.0")&"¢ residential.") -> Every class paid more per kWh (+0.8% to +2.9%), yet the average rose +0.2%: the growth is industrial load (+12.2% MWh), billed at 9.4¢ against 18.9¢ residential.
B14: {="Since "&BaseYear&", retail revenue is up "&MONEY(PVM!N11)&": price "&SIGNMONEY(PVM!L11)&", volume "&SIGNMONEY(PVM!J11)&", mix "&SIGNMONEY(PVM!K11)&". Power cost rose faster than revenue, and operating margin fell "&TEXT(ABS(PnL!P33),"0.0%")&" points."} -> Since 2019, retail revenue is up $1.18B: price +$993.6M, volume +$275.4M, mix −$89.0M. Power cost rose faster than revenue, and operating margin fell 2.0% points.
B15: {="Full year "&FiscalYear&": "&MONEY(fy_revenue)&", "&TEXT(Forecast!H75,"+0.0%;-0.0%")&" on "&(FiscalYear-1)&IF(ISNUMBER(Forecast!J75),", "&MONEY(ABS(Forecast!J75))&IF(Forecast!J75<0," under"," over")&" plan","")&". A point of rate on the open months is worth "&MONEY(INDEX(tornado,1))&"; 50 MW of new data-center load, "&MONEY(INDEX(tornado,2))&"."} -> Full year 2026: $3.01B, +2.7% on 2025, $184.2M under plan. A point of rate on the open months is worth $15.4M; 50 MW of new data-center load, $21.1M.
B55: ="Plan against actual by class, "&TEXT(FYStart,"mmm")&"–"&TEXT(AsOfMonth,"mmm") -> Plan against actual by class, Jan–Jun | K55: ="Full-year outlook by class, "&FiscalYear -> Full-year outlook by class, 2026
B56: Class | E56: Plan | G56: Actual | I56: Variance | J56: % | K56: Class | M56: Actual YTD | O56: Forecast | Q56: Full year | S56: Growth
B57: =Plan!B80 -> Residential | E57: =Plan!D80 -> 7.6124929e+08 | G57: =Plan!I80 -> 695144762 | I57: =Plan!J80 -> -66104525 | J57: =Plan!K80 -> -0.086836896 | K57: =Forecast!B71 -> Residential | M57: =Forecast!D71 -> 695144762 | O57: =Forecast!E71 -> 7.1944283e+08 | Q57: =Forecast!F71 -> 1.4145876e+09 | S57: =Forecast!H71 -> -0.0091738536
B58: =Plan!B81 -> Commercial | E58: =Plan!D81 -> 4.8858664e+08 | G58: =Plan!I81 -> 474305106 | I58: =Plan!J81 -> -14281537 | J58: =Plan!K81 -> -0.029230306 | K58: =Forecast!B72 -> Commercial | M58: =Forecast!D72 -> 474305106 | O58: =Forecast!E72 -> 4.8063087e+08 | Q58: =Forecast!F72 -> 9.5493598e+08 | S58: =Forecast!H72 -> 0.010327589
B59: =Plan!B82 -> Industrial | E59: =Plan!D82 -> 3.2023868e+08 | G59: =Plan!I82 -> 299820792 | I59: =Plan!J82 -> -20417887 | J59: =Plan!K82 -> -0.063758342 | K59: =Forecast!B73 -> Industrial | M59: =Forecast!D73 -> 299820792 | O59: =Forecast!E73 -> 3.3699007e+08 | Q59: =Forecast!F73 -> 6.3681086e+08 | S59: =Forecast!H73 -> 0.14964437
B60: =Plan!B83 -> Transportation | E60: =Plan!D83 -> 828523.27 | G60: =Plan!I83 -> 691495 | I60: =Plan!J83 -> -137028.27 | J60: =Plan!K83 -> -0.16538856 | K60: =Forecast!B74 -> Transportation | M60: =Forecast!D74 -> 691495 | O60: =Forecast!E74 -> 638908.92 | Q60: =Forecast!F74 -> 1330403.9 | S60: =Forecast!H74 -> -0.0500555
B61: =Plan!B84 -> All classes | E61: =Plan!D84 -> 1.5709031e+09 | G61: =Plan!I84 -> 1469962155 | I61: =Plan!J84 -> -1.0094098e+08 | J61: =Plan!K84 -> -0.064256653 | K61: =Forecast!B75 -> All classes | M61: =Forecast!D75 -> 1469962155 | O61: =Forecast!E75 -> 1.5377027e+09 | Q61: =Forecast!F75 -> 3.0076648e+09 | S61: =Forecast!H75 -> 0.027144809
B62: Independent analysis of public regulatory filings (EIA-861M, FERC Form 1 via Catalyst Cooperative's PUDL, NOAA nClimDiv). Not affiliated with or endorsed by Portland General Electric. Built in Excel by Kush Patel: github.com/KushPatel29/excel-fpa-model
B68: Chart data: the charts above read these cells, which read the model.
B71: Month | C71: Actual | D71: Forecast | E71: Plan | F71: Prior year
B72: =TEXT(Forecast!B80,"mmm") -> Jan | C72: =Forecast!C80 -> 271495430 | D72: =Forecast!D80 | E72: =Forecast!E80 -> 2.8301338e+08 | F72: =Forecast!F80 -> 280461721
B73: =TEXT(Forecast!B81,"mmm") -> Feb | C73: =Forecast!C81 -> 236446919 | D73: =Forecast!D81 | E73: =Forecast!E81 -> 2.78332e+08 | F73: =Forecast!F81 -> 252288295
B74: =TEXT(Forecast!B82,"mmm") -> Mar | C74: =Forecast!C82 -> 241516825 | D74: =Forecast!D82 | E74: =Forecast!E82 -> 2.7853482e+08 | F74: =Forecast!F82 -> 247602397
B75: =TEXT(Forecast!B83,"mmm") -> Apr | C75: =Forecast!C83 -> 233585146 | D75: =Forecast!D83 | E75: =Forecast!E83 -> 2.5837732e+08 | F75: =Forecast!F83 -> 217637842
B76: =TEXT(Forecast!B84,"mmm") -> May | C76: =Forecast!C84 -> 239271154 | D76: =Forecast!D84 | E76: =Forecast!E84 -> 2.4114012e+08 | F76: =Forecast!F84 -> 216290531
B77: =TEXT(Forecast!B85,"mmm") -> Jun | C77: =Forecast!C85 -> 247646681 | D77: =Forecast!D85 | E77: =Forecast!E85 -> 2.3150549e+08 | F77: =Forecast!F85 -> 228083828
B78: =TEXT(Forecast!B86,"mmm") -> Jul | C78: =Forecast!C86 | D78: =Forecast!D86 -> 2.4976576e+08 | E78: =Forecast!E86 -> 2.7190595e+08 | F78: =Forecast!F86 -> 260233530
B79: =TEXT(Forecast!B87,"mmm") -> Aug | C79: =Forecast!C87 | D79: =Forecast!D87 -> 2.618713e+08 | E79: =Forecast!E87 -> 2.8285095e+08 | F79: =Forecast!F87 -> 268274378
B80: =TEXT(Forecast!B88,"mmm") -> Sep | C80: =Forecast!C88 | D80: =Forecast!D88 -> 2.3329519e+08 | E80: =Forecast!E88 -> 2.4272094e+08 | F80: =Forecast!F88 -> 230382555
B81: =TEXT(Forecast!B89,"mmm") -> Oct | C81: =Forecast!C89 | D81: =Forecast!D89 -> 2.4243137e+08 | E81: =Forecast!E89 -> 2.5203e+08 | F81: =Forecast!F89 -> 226390278
B82: =TEXT(Forecast!B90,"mmm") -> Nov | C82: =Forecast!C90 | D82: =Forecast!D90 -> 2.662898e+08 | E82: =Forecast!E90 -> 2.7651424e+08 | F82: =Forecast!F90 -> 236444019
B83: =TEXT(Forecast!B91,"mmm") -> Dec | C83: =Forecast!C91 | D83: =Forecast!D91 -> 2.8404926e+08 | E83: =Forecast!E91 -> 2.9498314e+08 | F83: =Forecast!F91 -> 264090576
B86: =Plan!N79 -> Plan 2026 | C86: =Plan!O79 -> 1.5709031e+09
B87: =Plan!N80 -> Customers | C87: =Plan!O80 -> 79021.507
B88: =Plan!N81 -> Weather | C88: =Plan!O81 -> -40425964
B89: =Plan!N82 -> Usage | C89: =Plan!O82 -> -18307381
B90: =Plan!N83 -> Price | C90: =Plan!O83 -> -42286654
...

Sheet PnL
B1: Profit and loss: Portland General Electric, electric utility (FERC Form 1)
B2: Audited annual figures as filed with FERC, via Catalyst Cooperative's PUDL, in $ millions. Column C names the FERC line each revenue row reads. Operating income is before income taxes and interest.
B4: Year | C4: FERC line | D4: =FercYear-11 -> 2014 | E4: =D4+1 -> 2015 | F4: =E4+1 -> 2016 | G4: =F4+1 -> 2017 | H4: =G4+1 -> 2018 | I4: =H4+1 -> 2019 | J4: =I4+1 -> 2020 | K4: =J4+1 -> 2021 | L4: =K4+1 -> 2022 | ... O4: =N4+1 -> 2025 | P4: ="CAGR "&BaseYear&"–"&RIGHT(FercYear,2) -> CAGR 2019–25 | Q4: ="Δ vs "&(FercYear-1) -> Δ vs 2024 | R4: % change
B5: Revenue
B6: Residential | C6: residential_sales | D6: =SUMIFS(tbl_FERC_Revenue[dollar_value],tbl_FERC_Revenue[utility_id_ferc1],CompanyId,tbl_FERC_Revenue[report_year],D$4,tbl_FERC_Revenue[revenue_type],"residential_sales") -> 848594155 | E6: =SUMIFS(tbl_FERC_Revenue[dollar_value],tbl_FERC_Revenue[utility_id_ferc1],CompanyId,tbl_FERC_Revenue[report_year],E$4,tbl_FERC_Revenue[revenue_type],"residential_sales") -> 845906182 | F6: =SUMIFS(tbl_FERC_Revenue[dollar_value],tbl_FERC_Revenue[utility_id_ferc1],CompanyId,tbl_FERC_Revenue[report_year],F$4,tbl_FERC_Revenue[revenue_type],"residential_sales") -> 837938465 | G6: =SUMIFS(tbl_FERC_Revenue[dollar_value],tbl_FERC_Revenue[utility_id_ferc1],CompanyId,tbl_FERC_Revenue[report_year],G$4,tbl_FERC_Revenue[revenue_type],"residential_sales") -> 900171801 | H6: =SUMIFS(tbl_FERC_Revenue[dollar_value],tbl_FERC_Revenue[utility_id_ferc1],CompanyId,tbl_FERC_Revenue[report_year],H$4,tbl_FERC_Revenue[revenue_type],"residential_sales") -> 890376597 | I6: =SUMIFS(tbl_FERC_Revenue[dollar_value],tbl_FERC_Revenue[utility_id_ferc1],CompanyId,tbl_FERC_Revenue[report_year],I$4,tbl_FERC_Revenue[revenue_type],"residential_sales") -> 917792335 | J6: =SUMIFS(tbl_FERC_Revenue[dollar_value],tbl_FERC_Revenue[utility_id_ferc1],CompanyId,tbl_FERC_Revenue[report_year],J$4,tbl_FERC_Revenue[revenue_type],"residential_sales") -> 969909454 | K6: =SUMIFS(tbl_FERC_Revenue[dollar_value],tbl_FERC_Revenue[utility_id_ferc1],CompanyId,tbl_FERC_Revenue[report_year],K$4,tbl_FERC_Revenue[revenue_type],"residential_sales") -> 1056368675 | ... O6: =SUMIFS(tbl_FERC_Revenue[dollar_value],tbl_FERC_Revenue[utility_id_ferc1],CompanyId,tbl_FERC_Revenue[report_year],O$4,tbl_FERC_Revenue[revenue_type],"residential_sales") -> 1427684968 | P6: =IFERROR((INDEX($D6:$O6,MATCH(FercYear,$D$4:$O$4,0))/INDEX($D6:$O6,MATCH(BaseYear,$D$4:$O$4,0)))^(1/(FercYear-BaseYear))-1,0) -> 0.07641893 | Q6: =INDEX($D6:$O6,MATCH(FercYear,$D$4:$O$4,0))-INDEX($D6:$O6,MATCH(FercYear-1,$D$4:$O$4,0)) -> 21314333 | R6: {=SAFEDIV(Q6,ABS(INDEX($D6:$O6,MATCH(FercYear-1,$D$4:$O$4,0))))} -> 0.015155559
B7: Commercial | C7: small_or_commercial | D7: =SUMIFS(tbl_FERC_Revenue[dollar_value],tbl_FERC_Revenue[utility_id_ferc1],CompanyId,tbl_FERC_Revenue[report_year],D$4,tbl_FERC_Revenue[revenue_type],"small_or_commercial") -> 633949689 | E7: =SUMIFS(tbl_FERC_Revenue[dollar_value],tbl_FERC_Revenue[utility_id_ferc1],CompanyId,tbl_FERC_Revenue[report_year],E$4,tbl_FERC_Revenue[revenue_type],"small_or_commercial") -> 646306478 | F7: =SUMIFS(tbl_FERC_Revenue[dollar_value],tbl_FERC_Revenue[utility_id_ferc1],CompanyId,tbl_FERC_Revenue[report_year],F$4,tbl_FERC_Revenue[revenue_type],"small_or_commercial") -> 645487072 | G7: =SUMIFS(tbl_FERC_Revenue[dollar_value],tbl_FERC_Revenue[utility_id_ferc1],CompanyId,tbl_FERC_Revenue[report_year],G$4,tbl_FERC_Revenue[revenue_type],"small_or_commercial") -> 650481084 | H7: =SUMIFS(tbl_FERC_Revenue[dollar_value],tbl_FERC_Revenue[utility_id_ferc1],CompanyId,tbl_FERC_Revenue[report_year],H$4,tbl_FERC_Revenue[revenue_type],"small_or_commercial") -> 648540186 | I7: =SUMIFS(tbl_FERC_Revenue[dollar_value],tbl_FERC_Revenue[utility_id_ferc1],CompanyId,tbl_FERC_Revenue[report_year],I$4,tbl_FERC_Revenue[revenue_type],"small_or_commercial") -> 638317031 | J7: =SUMIFS(tbl_FERC_Revenue[dollar_value],tbl_FERC_Revenue[utility_id_ferc1],CompanyId,tbl_FERC_Revenue[report_year],J$4,tbl_FERC_Revenue[revenue_type],"small_or_commercial") -> 619175770 | K7: =SUMIFS(tbl_FERC_Revenue[dollar_value],tbl_FERC_Revenue[utility_id_ferc1],CompanyId,tbl_FERC_Revenue[report_year],K$4,tbl_FERC_Revenue[revenue_type],"small_or_commercial") -> 691317312 | ... O7: =SUMIFS(tbl_FERC_Revenue[dollar_value],tbl_FERC_Revenue[utility_id_ferc1],CompanyId,tbl_FERC_Revenue[report_year],O$4,tbl_FERC_Revenue[revenue_type],"small_or_commercial") -> 966187754 | P7: =IFERROR((INDEX($D7:$O7,MATCH(FercYear,$D$4:$O$4,0))/INDEX($D7:$O7,MATCH(BaseYear,$D$4:$O$4,0)))^(1/(FercYear-BaseYear))-1,0) -> 0.071529625 | Q7: =INDEX($D7:$O7,MATCH(FercYear,$D$4:$O$4,0))-INDEX($D7:$O7,MATCH(FercYear-1,$D$4:$O$4,0)) -> 61289117 | R7: {=SAFEDIV(Q7,ABS(INDEX($D7:$O7,MATCH(FercYear-1,$D$4:$O$4,0))))} -> 0.067730367
B8: Industrial | C8: large_or_industrial | D8: =SUMIFS(tbl_FERC_Revenue[dollar_value],tbl_FERC_Revenue[utility_id_ferc1],CompanyId,tbl_FERC_Revenue[report_year],D$4,tbl_FERC_Revenue[revenue_type],"large_or_industrial") -> 221298764 | E8: =SUMIFS(tbl_FERC_Revenue[dollar_value],tbl_FERC_Revenue[utility_id_ferc1],CompanyId,tbl_FERC_Revenue[report_year],E$4,tbl_FERC_Revenue[revenue_type],"large_or_industrial") -> 227985121 | F8: =SUMIFS(tbl_FERC_Revenue[dollar_value],tbl_FERC_Revenue[utility_id_ferc1],CompanyId,tbl_FERC_Revenue[report_year],F$4,tbl_FERC_Revenue[revenue_type],"large_or_industrial") -> 207677973 | G8: =SUMIFS(tbl_FERC_Revenue[dollar_value],tbl_FERC_Revenue[utility_id_ferc1],CompanyId,tbl_FERC_Revenue[report_year],G$4,tbl_FERC_Revenue[revenue_type],"large_or_industrial") -> 211588342 | H8: =SUMIFS(tbl_FERC_Revenue[dollar_value],tbl_FERC_Revenue[utility_id_ferc1],CompanyId,tbl_FERC_Revenue[report_year],H$4,tbl_FERC_Revenue[revenue_type],"large_or_industrial") -> 209586172 | I8: =SUMIFS(tbl_FERC_Revenue[dollar_value],tbl_FERC_Revenue[utility_id_ferc1],CompanyId,tbl_FERC_Revenue[report_year],I$4,tbl_FERC_Revenue[revenue_type],"large_or_industrial") -> 221934941 | J8: =SUMIFS(tbl_FERC_Revenue[dollar_value],tbl_FERC_Revenue[utility_id_ferc1],CompanyId,tbl_FERC_Revenue[report_year],J$4,tbl_FERC_Revenue[revenue_type],"large_or_industrial") -> 246051284 | K8: =SUMIFS(tbl_FERC_Revenue[dollar_value],tbl_FERC_Revenue[utility_id_ferc1],CompanyId,tbl_FERC_Revenue[report_year],K$4,tbl_FERC_Revenue[revenue_type],"large_or_industrial") -> 279876046 | ... O8: =SUMIFS(tbl_FERC_Revenue[dollar_value],tbl_FERC_Revenue[utility_id_ferc1],CompanyId,tbl_FERC_Revenue[report_year],O$4,tbl_FERC_Revenue[revenue_type],"large_or_industrial") -> 560496980 | P8: =IFERROR((INDEX($D8:$O8,MATCH(FercYear,$D$4:$O$4,0))/INDEX($D8:$O8,MATCH(BaseYear,$D$4:$O$4,0)))^(1/(FercYear-BaseYear))-1,0) -> 0.16696527 | Q8: =INDEX($D8:$O8,MATCH(FercYear,$D$4:$O$4,0))-INDEX($D8:$O8,MATCH(FercYear-1,$D$4:$O$4,0)) -> 103041230 | R8: {=SAFEDIV(Q8,ABS(INDEX($D8:$O8,MATCH(FercYear-1,$D$4:$O$4,0))))} -> 0.22524852
B9: Street lighting | C9: public_street_and_highway_lighting | D9: =SUMIFS(tbl_FERC_Revenue[dollar_value],tbl_FERC_Revenue[utility_id_ferc1],CompanyId,tbl_FERC_Revenue[report_year],D$4,tbl_FERC_Revenue[revenue_type],"public_street_and_highway_lighting") -> 17151203 | E9: =SUMIFS(tbl_FERC_Revenue[dollar_value],tbl_FERC_Revenue[utility_id_ferc1],CompanyId,tbl_FERC_Revenue[report_year],E$4,tbl_FERC_Revenue[revenue_type],"public_street_and_highway_lighting") -> 15385088 | F9: =SUMIFS(tbl_FERC_Revenue[dollar_value],tbl_FERC_Revenue[utility_id_ferc1],CompanyId,tbl_FERC_Revenue[report_year],F$4,tbl_FERC_Revenue[revenue_type],"public_street_and_highway_lighting") -> 12824132 | G9: =SUMIFS(tbl_FERC_Revenue[dollar_value],tbl_FERC_Revenue[utility_id_ferc1],CompanyId,tbl_FERC_Revenue[report_year],G$4,tbl_FERC_Revenue[revenue_type],"public_street_and_highway_lighting") -> 11954183 | H9: =SUMIFS(tbl_FERC_Revenue[dollar_value],tbl_FERC_Revenue[utility_id_ferc1],CompanyId,tbl_FERC_Revenue[report_year],H$4,tbl_FERC_Revenue[revenue_type],"public_street_and_highway_lighting") -> 11648005 | I9: =SUMIFS(tbl_FERC_Revenue[dollar_value],tbl_FERC_Revenue[utility_id_ferc1],CompanyId,tbl_FERC_Revenue[report_year],I$4,tbl_FERC_Revenue[revenue_type],"public_street_and_highway_lighting") -> 11259467 | J9: =SUMIFS(tbl_FERC_Revenue[dollar_value],tbl_FERC_Revenue[utility_id_ferc1],CompanyId,tbl_FERC_Revenue[report_year],J$4,tbl_FERC_Revenue[revenue_type],"public_street_and_highway_lighting") -> 10945945 | K9: =SUMIFS(tbl_FERC_Revenue[dollar_value],tbl_FERC_Revenue[utility_id_ferc1],CompanyId,tbl_FERC_Revenue[report_year],K$4,tbl_FERC_Revenue[revenue_type],"public_street_and_highway_lighting") -> 11922891 | ... O9: =SUMIFS(tbl_FERC_Revenue[dollar_value],tbl_FERC_Revenue[utility_id_ferc1],CompanyId,tbl_FERC_Revenue[report_year],O$4,tbl_FERC_Revenue[revenue_type],"public_street_and_highway_lighting") -> 14976918 | P9: =IFERROR((INDEX($D9:$O9,MATCH(FercYear,$D$4:$O$4,0))/INDEX($D9:$O9,MATCH(BaseYear,$D$4:$O$4,0)))^(1/(FercYear-BaseYear))-1,0) -> 0.048698797 | Q9: =INDEX($D9:$O9,MATCH(FercYear,$D$4:$O$4,0))-INDEX($D9:$O9,MATCH(FercYear-1,$D$4:$O$4,0)) -> 672712 | R9: {=SAFEDIV(Q9,ABS(INDEX($D9:$O9,MATCH(FercYear-1,$D$4:$O$4,0))))} -> 0.047028965
B10: Public authorities | C10: other_sales_to_public_authorities | D10: =SUMIFS(tbl_FERC_Revenue[dollar_value],tbl_FERC_Revenue[utility_id_ferc1],CompanyId,tbl_FERC_Revenue[report_year],D$4,tbl_FERC_Revenue[revenue_type],"other_sales_to_public_authorities") -> 0 | E10: =SUMIFS(tbl_FERC_Revenue[dollar_value],tbl_FERC_Revenue[utility_id_ferc1],CompanyId,tbl_FERC_Revenue[report_year],E$4,tbl_FERC_Revenue[revenue_type],"other_sales_to_public_authorities") -> 0 | F10: =SUMIFS(tbl_FERC_Revenue[dollar_value],tbl_FERC_Revenue[utility_id_ferc1],CompanyId,tbl_FERC_Revenue[report_year],F$4,tbl_FERC_Revenue[revenue_type],"other_sales_to_public_authorities") -> 0 | G10: =SUMIFS(tbl_FERC_Revenue[dollar_value],tbl_FERC_Revenue[utility_id_ferc1],CompanyId,tbl_FERC_Revenue[report_year],G$4,tbl_FERC_Revenue[revenue_type],"other_sales_to_public_authorities") -> 0 | H10: =SUMIFS(tbl_FERC_Revenue[dollar_value],tbl_FERC_Revenue[utility_id_ferc1],CompanyId,tbl_FERC_Revenue[report_year],H$4,tbl_FERC_Revenue[revenue_type],"other_sales_to_public_authorities") -> 0 | I10: =SUMIFS(tbl_FERC_Revenue[dollar_value],tbl_FERC_Revenue[utility_id_ferc1],CompanyId,tbl_FERC_Revenue[report_year],I$4,tbl_FERC_Revenue[revenue_type],"other_sales_to_public_authorities") -> 0 | J10: =SUMIFS(tbl_FERC_Revenue[dollar_value],tbl_FERC_Revenue[utility_id_ferc1],CompanyId,tbl_FERC_Revenue[report_year],J$4,tbl_FERC_Revenue[revenue_type],"other_sales_to_public_authorities") -> 0 | K10: =SUMIFS(tbl_FERC_Revenue[dollar_value],tbl_FERC_Revenue[utility_id_ferc1],CompanyId,tbl_FERC_Revenue[report_year],K$4,tbl_FERC_Revenue[revenue_type],"other_sales_to_public_authorities") -> 0 | ... O10: =SUMIFS(tbl_FERC_Revenue[dollar_value],tbl_FERC_Revenue[utility_id_ferc1],CompanyId,tbl_FERC_Revenue[report_year],O$4,tbl_FERC_Revenue[revenue_type],"other_sales_to_public_authorities") -> 0 | P10: =IFERROR((INDEX($D10:$O10,MATCH(FercYear,$D$4:$O$4,0))/INDEX($D10:$O10,MATCH(BaseYear,$D$4:$O$4,0)))^(1/(FercYear-BaseYear))-1,0) -> 0 | Q10: =INDEX($D10:$O10,MATCH(FercYear,$D$4:$O$4,0))-INDEX($D10:$O10,MATCH(FercYear-1,$D$4:$O$4,0)) -> 0 | R10: {=SAFEDIV(Q10,ABS(INDEX($D10:$O10,MATCH(FercYear-1,$D$4:$O$4,0))))} -> 0
B11: Retail revenue | D11: =SUM(D6:D10) -> 1720993811 | E11: =SUM(E6:E10) -> 1735582869 | F11: =SUM(F6:F10) -> 1703927642 | G11: =SUM(G6:G10) -> 1774195410 | H11: =SUM(H6:H10) -> 1760150960 | I11: =SUM(I6:I10) -> 1789303774 | J11: =SUM(J6:J10) -> 1846082453 | K11: =SUM(K6:K10) -> 2039484924 | ... O11: =SUM(O6:O10) -> 2969346620 | P11: =IFERROR((INDEX($D11:$O11,MATCH(FercYear,$D$4:$O$4,0))/INDEX($D11:$O11,MATCH(BaseYear,$D$4:$O$4,0)))^(1/(FercYear-BaseYear))-1,0) -> 0.08808495 | Q11: =INDEX($D11:$O11,MATCH(FercYear,$D$4:$O$4,0))-INDEX($D11:$O11,MATCH(FercYear-1,$D$4:$O$4,0)) -> 186317392 | R11: {=SAFEDIV(Q11,ABS(INDEX($D11:$O11,MATCH(FercYear-1,$D$4:$O$4,0))))} -> 0.066947695
B12: Wholesale (sales for resale) | D12: =SUMIFS(tbl_FERC_Revenue[dollar_value],tbl_FERC_Revenue[utility_id_ferc1],CompanyId,tbl_FERC_Revenue[report_year],D$4,tbl_FERC_Revenue[revenue_type],"sales_for_resale") -> 130021814 | E12: =SUMIFS(tbl_FERC_Revenue[dollar_value],tbl_FERC_Revenue[utility_id_ferc1],CompanyId,tbl_FERC_Revenue[report_year],E$4,tbl_FERC_Revenue[revenue_type],"sales_for_resale") -> 109756221 | F12: =SUMIFS(tbl_FERC_Revenue[dollar_value],tbl_FERC_Revenue[utility_id_ferc1],CompanyId,tbl_FERC_Revenue[report_year],F$4,tbl_FERC_Revenue[revenue_type],"sales_for_resale") -> 123165759 | G12: =SUMIFS(tbl_FERC_Revenue[dollar_value],tbl_FERC_Revenue[utility_id_ferc1],CompanyId,tbl_FERC_Revenue[report_year],G$4,tbl_FERC_Revenue[revenue_type],"sales_for_resale") -> 122591295 | H12: =SUMIFS(tbl_FERC_Revenue[dollar_value],tbl_FERC_Revenue[utility_id_ferc1],CompanyId,tbl_FERC_Revenue[report_year],H$4,tbl_FERC_Revenue[revenue_type],"sales_for_resale") -> 177074310 | I12: =SUMIFS(tbl_FERC_Revenue[dollar_value],tbl_FERC_Revenue[utility_id_ferc1],CompanyId,tbl_FERC_Revenue[report_year],I$4,tbl_FERC_Revenue[revenue_type],"sales_for_resale") -> 203335776 | J12: =SUMIFS(tbl_FERC_Revenue[dollar_value],tbl_FERC_Revenue[utility_id_ferc1],CompanyId,tbl_FERC_Revenue[report_year],J$4,tbl_FERC_Revenue[revenue_type],"sales_for_resale") -> 184596850 | K12: =SUMIFS(tbl_FERC_Revenue[dollar_value],tbl_FERC_Revenue[utility_id_ferc1],CompanyId,tbl_FERC_Revenue[report_year],K$4,tbl_FERC_Revenue[revenue_type],"sales_for_resale") -> 287282619 | ... O12: =SUMIFS(tbl_FERC_Revenue[dollar_value],tbl_FERC_Revenue[utility_id_ferc1],CompanyId,tbl_FERC_Revenue[report_year],O$4,tbl_FERC_Revenue[revenue_type],"sales_for_resale") -> 406261710 | P12: =IFERROR((INDEX($D12:$O12,MATCH(FercYear,$D$4:$O$4,0))/INDEX($D12:$O12,MATCH(BaseYear,$D$4:$O$4,0)))^(1/(FercYear-BaseYear))-1,0) -> 0.12227343 | Q12: =INDEX($D12:$O12,MATCH(FercYear,$D$4:$O$4,0))-INDEX($D12:$O12,MATCH(FercYear-1,$D$4:$O$4,0)) -> -181832439 | R12: {=SAFEDIV(Q12,ABS(INDEX($D12:$O12,MATCH(FercYear-1,$D$4:$O$4,0))))} -> -0.30918934
B13: Refund provision | D13: =-SUMIFS(tbl_FERC_Revenue[dollar_value],tbl_FERC_Revenue[utility_id_ferc1],CompanyId,tbl_FERC_Revenue[report_year],D$4,tbl_FERC_Revenue[revenue_type],"provision_for_rate_refunds") -> -3398715 | E13: =-SUMIFS(tbl_FERC_Revenue[dollar_value],tbl_FERC_Revenue[utility_id_ferc1],CompanyId,tbl_FERC_Revenue[report_year],E$4,tbl_FERC_Revenue[revenue_type],"provision_for_rate_refunds") -> 1197209 | F13: =-SUMIFS(tbl_FERC_Revenue[dollar_value],tbl_FERC_Revenue[utility_id_ferc1],CompanyId,tbl_FERC_Revenue[report_year],F$4,tbl_FERC_Revenue[revenue_type],"provision_for_rate_refunds") -> 7913648 | G13: =-SUMIFS(tbl_FERC_Revenue[dollar_value],tbl_FERC_Revenue[utility_id_ferc1],CompanyId,tbl_FERC_Revenue[report_year],G$4,tbl_FERC_Revenue[revenue_type],"provision_for_rate_refunds") -> 10337496 | H13: =-SUMIFS(tbl_FERC_Revenue[dollar_value],tbl_FERC_Revenue[utility_id_ferc1],CompanyId,tbl_FERC_Revenue[report_year],H$4,tbl_FERC_Revenue[revenue_type],"provision_for_rate_refunds") -> -40343222 | I13: =-SUMIFS(tbl_FERC_Revenue[dollar_value],tbl_FERC_Revenue[utility_id_ferc1],CompanyId,tbl_FERC_Revenue[report_year],I$4,tbl_FERC_Revenue[revenue_type],"provision_for_rate_refunds") -> 24671723 | J13: =-SUMIFS(tbl_FERC_Revenue[dollar_value],tbl_FERC_Revenue[utility_id_ferc1],CompanyId,tbl_FERC_Revenue[report_year],J$4,tbl_FERC_Revenue[revenue_type],"provision_for_rate_refunds") -> 5767072 | K13: =-SUMIFS(tbl_FERC_Revenue[dollar_value],tbl_FERC_Revenue[utility_id_ferc1],CompanyId,tbl_FERC_Revenue[report_year],K$4,tbl_FERC_Revenue[revenue_type],"provision_for_rate_refunds") -> -17402956 | ... O13: =-SUMIFS(tbl_FERC_Revenue[dollar_value],tbl_FERC_Revenue[utility_id_ferc1],CompanyId,tbl_FERC_Revenue[report_year],O$4,tbl_FERC_Revenue[revenue_type],"provision_for_rate_refunds") -> 20225849 | P13: =IFERROR((INDEX($D13:$O13,MATCH(FercYear,$D$4:$O$4,0))/INDEX($D13:$O13,MATCH(BaseYear,$D$4:$O$4,0)))^(1/(FercYear-BaseYear))-1,0) -> -0.032573722 | Q13: =INDEX($D13:$O13,MATCH(FercYear,$D$4:$O$4,0))-INDEX($D13:$O13,MATCH(FercYear-1,$D$4:$O$4,0)) -> 57155467 | R13: {=SAFEDIV(Q13,ABS(INDEX($D13:$O13,MATCH(FercYear-1,$D$4:$O$4,0))))} -> 1.5476864
B14: Other operating revenue | D14: =SUMIFS(tbl_FERC_Revenue[dollar_value],tbl_FERC_Revenue[utility_id_ferc1],CompanyId,tbl_FERC_Revenue[report_year],D$4,tbl_FERC_Revenue[revenue_type],"other_operating_revenues") -> 78961758 | E14: =SUMIFS(tbl_FERC_Revenue[dollar_value],tbl_FERC_Revenue[utility_id_ferc1],CompanyId,tbl_FERC_Revenue[report_year],E$4,tbl_FERC_Revenue[revenue_type],"other_operating_revenues") -> 68384771 | F14: =SUMIFS(tbl_FERC_Revenue[dollar_value],tbl_FERC_Revenue[utility_id_ferc1],CompanyId,tbl_FERC_Revenue[report_year],F$4,tbl_FERC_Revenue[revenue_type],"other_operating_revenues") -> 104159765 | G14: =SUMIFS(tbl_FERC_Revenue[dollar_value],tbl_FERC_Revenue[utility_id_ferc1],CompanyId,tbl_FERC_Revenue[report_year],G$4,tbl_FERC_Revenue[revenue_type],"other_operating_revenues") -> 115569351 | H14: =SUMIFS(tbl_FERC_Revenue[dollar_value],tbl_FERC_Revenue[utility_id_ferc1],CompanyId,tbl_FERC_Revenue[report_year],H$4,tbl_FERC_Revenue[revenue_type],"other_operating_revenues") -> 108227995 | I14: =SUMIFS(tbl_FERC_Revenue[dollar_value],tbl_FERC_Revenue[utility_id_ferc1],CompanyId,tbl_FERC_Revenue[report_year],I$4,tbl_FERC_Revenue[revenue_type],"other_operating_revenues") -> 130671136 | J14: =SUMIFS(tbl_FERC_Revenue[dollar_value],tbl_FERC_Revenue[utility_id_ferc1],CompanyId,tbl_FERC_Revenue[report_year],J$4,tbl_FERC_Revenue[revenue_type],"other_operating_revenues") -> 120765993 | K14: =SUMIFS(tbl_FERC_Revenue[dollar_value],tbl_FERC_Revenue[utility_id_ferc1],CompanyId,tbl_FERC_Revenue[report_year],K$4,tbl_FERC_Revenue[revenue_type],"other_operating_revenues") -> 105789779 | ... O14: =SUMIFS(tbl_FERC_Revenue[dollar_value],tbl_FERC_Revenue[utility_id_ferc1],CompanyId,tbl_FERC_Revenue[report_year],O$4,tbl_FERC_Revenue[revenue_type],"other_operating_revenues") -> 152350066 | P14: =IFERROR((INDEX($D14:$O14,MATCH(FercYear,$D$4:$O$4,0))/INDEX($D14:$O14,MATCH(BaseYear,$D$4:$O$4,0)))^(1/(FercYear-BaseYear))-1,0) -> 0.025912914 | Q14: =INDEX($D14:$O14,MATCH(FercYear,$D$4:$O$4,0))-INDEX($D14:$O14,MATCH(FercYear-1,$D$4:$O$4,0)) -> 25829084 | R14: {=SAFEDIV(Q14,ABS(INDEX($D14:$O14,MATCH(FercYear-1,$D$4:$O$4,0))))} -> 0.20414862
B15: Total operating revenue | D15: =SUM(D11:D14) -> 1926578668 | E15: =SUM(E11:E14) -> 1914921070 | F15: =SUM(F11:F14) -> 1939166814 | G15: =SUM(G11:G14) -> 2022693552 | H15: =SUM(H11:H14) -> 2005110043 | I15: =SUM(I11:I14) -> 2147982409 | J15: =SUM(J11:J14) -> 2157212368 | K15: =SUM(K11:K14) -> 2415154366 | ... O15: =SUM(O11:O14) -> 3548184245 | P15: =IFERROR((INDEX($D15:$O15,MATCH(FercYear,$D$4:$O$4,0))/INDEX($D15:$O15,MATCH(BaseYear,$D$4:$O$4,0)))^(1/(FercYear-BaseYear))-1,0) -> 0.08724956 | Q15: =INDEX($D15:$O15,MATCH(FercYear,$D$4:$O$4,0))-INDEX($D15:$O15,MATCH(FercYear-1,$D$4:$O$4,0)) -> 87469504 | R15: {=SAFEDIV(Q15,ABS(INDEX($D15:$O15,MATCH(FercYear-1,$D$4:$O$4,0))))} -> 0.025274982
B16: Power supply
B17: Fuel | D17: {=SUM(SUMIFS(tbl_FERC_Expense[dollar_value],tbl_FERC_Expense[utility_id_ferc1],CompanyId,tbl_FERC_Expense[report_year],D$4,tbl_FERC_Expense[expense_type],{"fuel_steam_power_generation","nuclear_fuel_expense","fuel","fuel_other_renewable_generation"}))} -> 251136059 | E17: {=SUM(SUMIFS(tbl_FERC_Expense[dollar_value],tbl_FERC_Expense[utility_id_ferc1],CompanyId,tbl_FERC_Expense[report_year],E$4,tbl_FERC_Expense[expense_type],{"fuel_steam_power_generation","nuclear_fuel_expense","fuel","fuel_other_renewable_generation"}))} -> 275229785 | F17: {=SUM(SUMIFS(tbl_FERC_Expense[dollar_value],tbl_FERC_Expense[utility_id_ferc1],CompanyId,tbl_FERC_Expense[report_year],F$4,tbl_FERC_Expense[expense_type],{"fuel_steam_power_generation","nuclear_fuel_expense","fuel","fuel_other_renewable_generation"}))} -> 294823521 | G17: {=SUM(SUMIFS(tbl_FERC_Expense[dollar_value],tbl_FERC_Expense[utility_id_ferc1],CompanyId,tbl_FERC_Expense[report_year],G$4,tbl_FERC_Expense[expense_type],{"fuel_steam_power_generation","nuclear_fuel_expense","fuel","fuel_other_renewable_generation"}))} -> 280282013 | H17: {=SUM(SUMIFS(tbl_FERC_Expense[dollar_value],tbl_FERC_Expense[utility_id_ferc1],CompanyId,tbl_FERC_Expense[report_year],H$4,tbl_FERC_Expense[expense_type],{"fuel_steam_power_generation","nuclear_fuel_expense","fuel","fuel_other_renewable_generation"}))} -> 250256859 | I17: {=SUM(SUMIFS(tbl_FERC_Expense[dollar_value],tbl_FERC_Expense[utility_id_ferc1],CompanyId,tbl_FERC_Expense[report_year],I$4,tbl_FERC_Expense[expense_type],{"fuel_steam_power_generation","nuclear_fuel_expense","fuel","fuel_other_renewable_generation"}))} -> 287914148 | J17: {=SUM(SUMIFS(tbl_FERC_Expense[dollar_value],tbl_FERC_Expense[utility_id_ferc1],CompanyId,tbl_FERC_Expense[report_year],J$4,tbl_FERC_Expense[expense_type],{"fuel_steam_power_generation","nuclear_fuel_expense","fuel","fuel_other_renewable_generation"}))} -> 241441550 | K17: {=SUM(SUMIFS(tbl_FERC_Expense[dollar_value],tbl_FERC_Expense[utility_id_ferc1],CompanyId,tbl_FERC_Expense[report_year],K$4,tbl_FERC_Expense[expense_type],{"fuel_steam_power_generation","nuclear_fuel_expense","fuel","fuel_other_renewable_generation"}))} -> 236524037 | ... O17: {=SUM(SUMIFS(tbl_FERC_Expense[dollar_value],tbl_FERC_Expense[utility_id_ferc1],CompanyId,tbl_FERC_Expense[report_year],O$4,tbl_FERC_Expense[expense_type],{"fuel_steam_power_generation","nuclear_fuel_expense","fuel","fuel_other_renewable_generation"}))} -> 475759791 | P17: =IFERROR((INDEX($D17:$O17,MATCH(FercYear,$D$4:$O$4,0))/INDEX($D17:$O17,MATCH(BaseYear,$D$4:$O$4,0)))^(1/(FercYear-BaseYear))-1,0) -> 0.08731185 | Q17: =INDEX($D17:$O17,MATCH(FercYear,$D$4:$O$4,0))-INDEX($D17:$O17,MATCH(FercYear-1,$D$4:$O$4,0)) -> 17994661 | R17: {=SAFEDIV(Q17,ABS(INDEX($D17:$O17,MATCH(FercYear-1,$D$4:$O$4,0))))} -> 0.039309812
B18: Purchased power | D18: {=SUM(SUMIFS(tbl_FERC_Expense[dollar_value],tbl_FERC_Expense[utility_id_ferc1],CompanyId,tbl_FERC_Expense[report_year],D$4,tbl_FERC_Expense[expense_type],{"purchased_power","power_purchased_for_storage_operations","storage_fuel_energy_storage_expense"}))} -> 414524300 | E18: {=SUM(SUMIFS(tbl_FERC_Expense[dollar_value],tbl_FERC_Expense[utility_id_ferc1],CompanyId,tbl_FERC_Expense[report_year],E$4,tbl_FERC_Expense[expense_type],{"purchased_power","power_purchased_for_storage_operations","storage_fuel_energy_storage_expense"}))} -> 325139822 | F18: {=SUM(SUMIFS(tbl_FERC_Expense[dollar_value],tbl_FERC_Expense[utility_id_ferc1],CompanyId,tbl_FERC_Expense[report_year],F$4,tbl_FERC_Expense[expense_type],{"purchased_power","power_purchased_for_storage_operations","storage_fuel_energy_storage_expense"}))} -> 264106264 | G18: {=SUM(SUMIFS(tbl_FERC_Expense[dollar_value],tbl_FERC_Expense[utility_id_ferc1],CompanyId,tbl_FERC_Expense[report_year],G$4,tbl_FERC_Expense[expense_type],{"purchased_power","power_purchased_for_storage_operations","storage_fuel_energy_storage_expense"}))} -> 244313723 | H18: {=SUM(SUMIFS(tbl_FERC_Expense[dollar_value],tbl_FERC_Expense[utility_id_ferc1],CompanyId,tbl_FERC_Expense[report_year],H$4,tbl_FERC_Expense[expense_type],{"purchased_power","power_purchased_for_storage_operations","storage_fuel_energy_storage_expense"}))} -> 257926636 | I18: {=SUM(SUMIFS(tbl_FERC_Expense[dollar_value],tbl_FERC_Expense[utility_id_ferc1],CompanyId,tbl_FERC_Expense[report_year],I$4,tbl_FERC_Expense[expense_type],{"purchased_power","power_purchased_for_storage_operations","storage_fuel_energy_storage_expense"}))} -> 281457582 | J18: {=SUM(SUMIFS(tbl_FERC_Expense[dollar_value],tbl_FERC_Expense[utility_id_ferc1],CompanyId,tbl_FERC_Expense[report_year],J$4,tbl_FERC_Expense[expense_type],{"purchased_power","power_purchased_for_storage_operations","storage_fuel_energy_storage_expense"}))} -> 418799466 | K18: {=SUM(SUMIFS(tbl_FERC_Expense[dollar_value],tbl_FERC_Expense[utility_id_ferc1],CompanyId,tbl_FERC_Expense[report_year],K$4,tbl_FERC_Expense[expense_type],{"purchased_power","power_purchased_for_storage_operations","storage_fuel_energy_storage_expense"}))} -> 530010343 | ... O18: {=SUM(SUMIFS(tbl_FERC_Expense[dollar_value],tbl_FERC_Expense[utility_id_ferc1],CompanyId,tbl_FERC_Expense[report_year],O$4,tbl_FERC_Expense[expense_type],{"purchased_power","power_purchased_for_storage_operations","storage_fuel_energy_storage_expense"}))} -> 845996268 | P18: =IFERROR((INDEX($D18:$O18,MATCH(FercYear,$D$4:$O$4,0))/INDEX($D18:$O18,MATCH(BaseYear,$D$4:$O$4,0)))^(1/(FercYear-BaseYear))-1,0) -> 0.2013215 | Q18: =INDEX($D18:$O18,MATCH(FercYear,$D$4:$O$4,0))-INDEX($D18:$O18,MATCH(FercYear-1,$D$4:$O$4,0)) -> -33863493 | R18: {=SAFEDIV(Q18,ABS(INDEX($D18:$O18,MATCH(FercYear-1,$D$4:$O$4,0))))} -> -0.038487375
B19: Power cost | D19: =D17+D18 -> 665660359 | E19: =E17+E18 -> 600369607 | F19: =F17+F18 -> 558929785 | G19: =G17+G18 -> 524595736 | H19: =H17+H18 -> 508183495 | I19: =I17+I18 -> 569371730 | J19: =J17+J18 -> 660241016 | K19: =K17+K18 -> 766534380 | ... O19: =O17+O18 -> 1321756059 | P19: =IFERROR((INDEX($D19:$O19,MATCH(FercYear,$D$4:$O$4,0))/INDEX($D19:$O19,MATCH(BaseYear,$D$4:$O$4,0)))^(1/(FercYear-BaseYear))-1,0) -> 0.15069237 | Q19: =INDEX($D19:$O19,MATCH(FercYear,$D$4:$O$4,0))-INDEX($D19:$O19,MATCH(FercYear-1,$D$4:$O$4,0)) -> -15868832 | R19: {=SAFEDIV(Q19,ABS(INDEX($D19:$O19,MATCH(FercYear-1,$D$4:$O$4,0))))} -> -0.01186344
B20: Gross margin | D20: =D15-D19 -> 1260918309 | E20: =E15-E19 -> 1314551463 | F20: =F15-F19 -> 1380237029 | G20: =G15-G19 -> 1498097816 | H20: =H15-H19 -> 1496926548 | I20: =I15-I19 -> 1578610679 | J20: =J15-J19 -> 1496971352 | K20: =K15-K19 -> 1648619986 | ... O20: =O15-O19 -> 2226428186 | P20: =IFERROR((INDEX($D20:$O20,MATCH(FercYear,$D$4:$O$4,0))/INDEX($D20:$O20,MATCH(BaseYear,$D$4:$O$4,0)))^(1/(FercYear-BaseYear))-1,0) -> 0.058982888 | Q20: =INDEX($D20:$O20,MATCH(FercYear,$D$4:$O$4,0))-INDEX($D20:$O20,MATCH(FercYear-1,$D$4:$O$4,0)) -> 103338336 | R20: {=SAFEDIV(Q20,ABS(INDEX($D20:$O20,MATCH(FercYear-1,$D$4:$O$4,0))))} -> 0.048673558
B21: Gross margin % | D21: {=SAFEDIV(D20,D15)} -> 0.65448576 | E21: {=SAFEDIV(E20,E15)} -> 0.68647814 | F21: {=SAFEDIV(F20,F15)} -> 0.71176807 | G21: {=SAFEDIV(G20,G15)} -> 0.74064498 | H21: {=SAFEDIV(H20,H15)} -> 0.74655581 | I21: {=SAFEDIV(I20,I15)} -> 0.73492719 | J21: {=SAFEDIV(J20,J15)} -> 0.69393787 | K21: {=SAFEDIV(K20,K15)} -> 0.68261475 | ... O21: {=SAFEDIV(O20,O15)} -> 0.62748381 | P21: =INDEX($D21:$O21,MATCH(FercYear,$D$4:$O$4,0))-INDEX($D21:$O21,MATCH(BaseYear,$D$4:$O$4,0)) -> -0.10744338 | Q21: =INDEX($D21:$O21,MATCH(FercYear,$D$4:$O$4,0))-INDEX($D21:$O21,MATCH(FercYear-1,$D$4:$O$4,0)) -> 0.01400076
B22: Operating expenses, excluding power
B23: Production, excluding fuel and purchased power | D23: =SUMIFS(tbl_FERC_Expense[dollar_value],tbl_FERC_Expense[utility_id_ferc1],CompanyId,tbl_FERC_Expense[report_year],D$4,tbl_FERC_Expense[expense_type],"power_production_expenses")-D19 -> 132400112 | E23: =SUMIFS(tbl_FERC_Expense[dollar_value],tbl_FERC_Expense[utility_id_ferc1],CompanyId,tbl_FERC_Expense[report_year],E$4,tbl_FERC_Expense[expense_type],"power_production_expenses")-E19 -> 140808746 | F23: =SUMIFS(tbl_FERC_Expense[dollar_value],tbl_FERC_Expense[utility_id_ferc1],CompanyId,tbl_FERC_Expense[report_year],F$4,tbl_FERC_Expense[expense_type],"power_production_expenses")-F19 -> 146447063 | G23: =SUMIFS(tbl_FERC_Expense[dollar_value],tbl_FERC_Expense[utility_id_ferc1],CompanyId,tbl_FERC_Expense[report_year],G$4,tbl_FERC_Expense[expense_type],"power_production_expenses")-G19 -> 154358468 | H23: =SUMIFS(tbl_FERC_Expense[dollar_value],tbl_FERC_Expense[utility_id_ferc1],CompanyId,tbl_FERC_Expense[report_year],H$4,tbl_FERC_Expense[expense_type],"power_production_expenses")-H19 -> 151929566 | I23: =SUMIFS(tbl_FERC_Expense[dollar_value],tbl_FERC_Expense[utility_id_ferc1],CompanyId,tbl_FERC_Expense[report_year],I$4,tbl_FERC_Expense[expense_type],"power_production_expenses")-I19 -> 162912941 | J23: =SUMIFS(tbl_FERC_Expense[dollar_value],tbl_FERC_Expense[utility_id_ferc1],CompanyId,tbl_FERC_Expense[report_year],J$4,tbl_FERC_Expense[expense_type],"power_production_expenses")-J19 -> 141931061 | K23: =SUMIFS(tbl_FERC_Expense[dollar_value],tbl_FERC_Expense[utility_id_ferc1],CompanyId,tbl_FERC_Expense[report_year],K$4,tbl_FERC_Expense[expense_type],"power_production_expenses")-K19 -> 131395452 | ... O23: =SUMIFS(tbl_FERC_Expense[dollar_value],tbl_FERC_Expense[utility_id_ferc1],CompanyId,tbl_FERC_Expense[report_year],O$4,tbl_FERC_Expense[expense_type],"power_production_expenses")-O19 -> 181565942 | P23: =IFERROR((INDEX($D23:$O23,MATCH(FercYear,$D$4:$O$4,0))/INDEX($D23:$O23,MATCH(BaseYear,$D$4:$O$4,0)))^(1/(FercYear-BaseYear))-1,0) -> 0.018231357 | Q23: =INDEX($D23:$O23,MATCH(FercYear,$D$4:$O$4,0))-INDEX($D23:$O23,MATCH(FercYear-1,$D$4:$O$4,0)) -> 5313745 | R23: {=SAFEDIV(Q23,ABS(INDEX($D23:$O23,MATCH(FercYear-1,$D$4:$O$4,0))))} -> 0.030148532
B24: Transmission | D24: =SUMIFS(tbl_FERC_Expense[dollar_value],tbl_FERC_Expense[utility_id_ferc1],CompanyId,tbl_FERC_Expense[report_year],D$4,tbl_FERC_Expense[expense_type],"transmission_expenses") -> 96567225 | E24: =SUMIFS(tbl_FERC_Expense[dollar_value],tbl_FERC_Expense[utility_id_ferc1],CompanyId,tbl_FERC_Expense[report_year],E$4,tbl_FERC_Expense[expense_type],"transmission_expenses") -> 98091925 | F24: =SUMIFS(tbl_FERC_Expense[dollar_value],tbl_FERC_Expense[utility_id_ferc1],CompanyId,tbl_FERC_Expense[report_year],F$4,tbl_FERC_Expense[expense_type],"transmission_expenses") -> 95364654 | G24: =SUMIFS(tbl_FERC_Expense[dollar_value],tbl_FERC_Expense[utility_id_ferc1],CompanyId,tbl_FERC_Expense[report_year],G$4,tbl_FERC_Expense[expense_type],"transmission_expenses") -> 104281769 | H24: =SUMIFS(tbl_FERC_Expense[dollar_value],tbl_FERC_Expense[utility_id_ferc1],CompanyId,tbl_FERC_Expense[report_year],H$4,tbl_FERC_Expense[expense_type],"transmission_expenses") -> 103337318 | I24: =SUMIFS(tbl_FERC_Expense[dollar_value],tbl_FERC_Expense[utility_id_ferc1],CompanyId,tbl_FERC_Expense[report_year],I$4,tbl_FERC_Expense[expense_type],"transmission_expenses") -> 108556686 | J24: =SUMIFS(tbl_FERC_Expense[dollar_value],tbl_FERC_Expense[utility_id_ferc1],CompanyId,tbl_FERC_Expense[report_year],J$4,tbl_FERC_Expense[expense_type],"transmission_expenses") -> 101525817 | K24: =SUMIFS(tbl_FERC_Expense[dollar_value],tbl_FERC_Expense[utility_id_ferc1],CompanyId,tbl_FERC_Expense[report_year],K$4,tbl_FERC_Expense[expense_type],"transmission_expenses") -> 111907966 | ... O24: =SUMIFS(tbl_FERC_Expense[dollar_value],tbl_FERC_Expense[utility_id_ferc1],CompanyId,tbl_FERC_Expense[report_year],O$4,tbl_FERC_Expense[expense_type],"transmission_expenses") -> 166944422 | P24: =IFERROR((INDEX($D24:$O24,MATCH(FercYear,$D$4:$O$4,0))/INDEX($D24:$O24,MATCH(BaseYear,$D$4:$O$4,0)))^(1/(FercYear-BaseYear))-1,0) -> 0.074366742 | Q24: =INDEX($D24:$O24,MATCH(FercYear,$D$4:$O$4,0))-INDEX($D24:$O24,MATCH(FercYear-1,$D$4:$O$4,0)) -> 8139744 | R24: {=SAFEDIV(Q24,ABS(INDEX($D24:$O24,MATCH(FercYear-1,$D$4:$O$4,0))))} -> 0.051256324
B25: Distribution | D25: =SUMIFS(tbl_FERC_Expense[dollar_value],tbl_FERC_Expense[utility_id_ferc1],CompanyId,tbl_FERC_Expense[report_year],D$4,tbl_FERC_Expense[expense_type],"distribution_expenses") -> 99839203 | E25: =SUMIFS(tbl_FERC_Expense[dollar_value],tbl_FERC_Expense[utility_id_ferc1],CompanyId,tbl_FERC_Expense[report_year],E$4,tbl_FERC_Expense[expense_type],"distribution_expenses") -> 101417432 | F25: =SUMIFS(tbl_FERC_Expense[dollar_value],tbl_FERC_Expense[utility_id_ferc1],CompanyId,tbl_FERC_Expense[report_year],F$4,tbl_FERC_Expense[expense_type],"distribution_expenses") -> 116611492 | G25: =SUMIFS(tbl_FERC_Expense[dollar_value],tbl_FERC_Expense[utility_id_ferc1],CompanyId,tbl_FERC_Expense[report_year],G$4,tbl_FERC_Expense[expense_type],"distribution_expenses") -> 127636822 | H25: =SUMIFS(tbl_FERC_Expense[dollar_value],tbl_FERC_Expense[utility_id_ferc1],CompanyId,tbl_FERC_Expense[report_year],H$4,tbl_FERC_Expense[expense_type],"distribution_expenses") -> 113588197 | I25: =SUMIFS(tbl_FERC_Expense[dollar_value],tbl_FERC_Expense[utility_id_ferc1],CompanyId,tbl_FERC_Expense[report_year],I$4,tbl_FERC_Expense[expense_type],"distribution_expenses") -> 134617893 | J25: =SUMIFS(tbl_FERC_Expense[dollar_value],tbl_FERC_Expense[utility_id_ferc1],CompanyId,tbl_FERC_Expense[report_year],J$4,tbl_FERC_Expense[expense_type],"distribution_expenses") -> 124006010 | K25: =SUMIFS(tbl_FERC_Expense[dollar_value],tbl_FERC_Expense[utility_id_ferc1],CompanyId,tbl_FERC_Expense[report_year],K$4,tbl_FERC_Expense[expense_type],"distribution_expenses") -> 159848932 | ... O25: =SUMIFS(tbl_FERC_Expense[dollar_value],tbl_FERC_Expense[utility_id_ferc1],CompanyId,tbl_FERC_Expense[report_year],O$4,tbl_FERC_Expense[expense_type],"distribution_expenses") -> 246386322 | P25: =IFERROR((INDEX($D25:$O25,MATCH(FercYear,$D$4:$O$4,0))/INDEX($D25:$O25,MATCH(BaseYear,$D$4:$O$4,0)))^(1/(FercYear-BaseYear))-1,0) -> 0.1059928 | Q25: =INDEX($D25:$O25,MATCH(FercYear,$D$4:$O$4,0))-INDEX($D25:$O25,MATCH(FercYear-1,$D$4:$O$4,0)) -> 18058364 | R25: {=SAFEDIV(Q25,ABS(INDEX($D25:$O25,MATCH(FercYear-1,$D$4:$O$4,0))))} -> 0.079089587
B26: Customer accounts, service and sales | D26: {=SUM(SUMIFS(tbl_FERC_Expense[dollar_value],tbl_FERC_Expense[utility_id_ferc1],CompanyId,tbl_FERC_Expense[report_year],D$4,tbl_FERC_Expense[expense_type],{"customer_account_expenses","customer_service_and_information_expenses","sales_expenses"}))} -> 66009525 | E26: {=SUM(SUMIFS(tbl_FERC_Expense[dollar_value],tbl_FERC_Expense[utility_id_ferc1],CompanyId,tbl_FERC_Expense[report_year],E$4,tbl_FERC_Expense[expense_type],{"customer_account_expenses","customer_service_and_information_expenses","sales_expenses"}))} -> 69758456 | F26: {=SUM(SUMIFS(tbl_FERC_Expense[dollar_value],tbl_FERC_Expense[utility_id_ferc1],CompanyId,tbl_FERC_Expense[report_year],F$4,tbl_FERC_Expense[expense_type],{"customer_account_expenses","customer_service_and_information_expenses","sales_expenses"}))} -> 70626752 | G26: {=SUM(SUMIFS(tbl_FERC_Expense[dollar_value],tbl_FERC_Expense[utility_id_ferc1],CompanyId,tbl_FERC_Expense[report_year],G$4,tbl_FERC_Expense[expense_type],{"customer_account_expenses","customer_service_and_information_expenses","sales_expenses"}))} -> 74189210 | H26: {=SUM(SUMIFS(tbl_FERC_Expense[dollar_value],tbl_FERC_Expense[utility_id_ferc1],CompanyId,tbl_FERC_Expense[report_year],H$4,tbl_FERC_Expense[expense_type],{"customer_account_expenses","customer_service_and_information_expenses","sales_expenses"}))} -> 86086288 | I26: {=SUM(SUMIFS(tbl_FERC_Expense[dollar_value],tbl_FERC_Expense[utility_id_ferc1],CompanyId,tbl_FERC_Expense[report_year],I$4,tbl_FERC_Expense[expense_type],{"customer_account_expenses","customer_service_and_information_expenses","sales_expenses"}))} -> 79987880 | J26: {=SUM(SUMIFS(tbl_FERC_Expense[dollar_value],tbl_FERC_Expense[utility_id_ferc1],CompanyId,tbl_FERC_Expense[report_year],J$4,tbl_FERC_Expense[expense_type],{"customer_account_expenses","customer_service_and_information_expenses","sales_expenses"}))} -> 80061690 | K26: {=SUM(SUMIFS(tbl_FERC_Expense[dollar_value],tbl_FERC_Expense[utility_id_ferc1],CompanyId,tbl_FERC_Expense[report_year],K$4,tbl_FERC_Expense[expense_type],{"customer_account_expenses","customer_service_and_information_expenses","sales_expenses"}))} -> 89416307 | ... O26: {=SUM(SUMIFS(tbl_FERC_Expense[dollar_value],tbl_FERC_Expense[utility_id_ferc1],CompanyId,tbl_FERC_Expense[report_year],O$4,tbl_FERC_Expense[expense_type],{"customer_account_expenses","customer_service_and_information_expenses","sales_expenses"}))} -> 82694489 | P26: =IFERROR((INDEX($D26:$O26,MATCH(FercYear,$D$4:$O$4,0))/INDEX($D26:$O26,MATCH(BaseYear,$D$4:$O$4,0)))^(1/(FercYear-BaseYear))-1,0) -> 0.0055617156 | Q26: =INDEX($D26:$O26,MATCH(FercYear,$D$4:$O$4,0))-INDEX($D26:$O26,MATCH(FercYear-1,$D$4:$O$4,0)) -> -31152394 | R26: {=SAFEDIV(Q26,ABS(INDEX($D26:$O26,MATCH(FercYear-1,$D$4:$O$4,0))))} -> -0.27363414
B27: Administrative and general | D27: =SUMIFS(tbl_FERC_Expense[dollar_value],tbl_FERC_Expense[utility_id_ferc1],CompanyId,tbl_FERC_Expense[report_year],D$4,tbl_FERC_Expense[expense_type],"administrative_and_general_expenses") -> 161772278 | E27: =SUMIFS(tbl_FERC_Expense[dollar_value],tbl_FERC_Expense[utility_id_ferc1],CompanyId,tbl_FERC_Expense[report_year],E$4,tbl_FERC_Expense[expense_type],"administrative_and_general_expenses") -> 171798280 | F27: =SUMIFS(tbl_FERC_Expense[dollar_value],tbl_FERC_Expense[utility_id_ferc1],CompanyId,tbl_FERC_Expense[report_year],F$4,tbl_FERC_Expense[expense_type],"administrative_and_general_expenses") -> 176470725 | G27: =SUMIFS(tbl_FERC_Expense[dollar_value],tbl_FERC_Expense[utility_id_ferc1],CompanyId,tbl_FERC_Expense[report_year],G$4,tbl_FERC_Expense[expense_type],"administrative_and_general_expenses") -> 190762897 | H27: =SUMIFS(tbl_FERC_Expense[dollar_value],tbl_FERC_Expense[utility_id_ferc1],CompanyId,tbl_FERC_Expense[report_year],H$4,tbl_FERC_Expense[expense_type],"administrative_and_general_expenses") -> 190551981 | I27: =SUMIFS(tbl_FERC_Expense[dollar_value],tbl_FERC_Expense[utility_id_ferc1],CompanyId,tbl_FERC_Expense[report_year],I$4,tbl_FERC_Expense[expense_type],"administrative_and_general_expenses") -> 210248968 | J27: =SUMIFS(tbl_FERC_Expense[dollar_value],tbl_FERC_Expense[utility_id_ferc1],CompanyId,tbl_FERC_Expense[report_year],J$4,tbl_FERC_Expense[expense_type],"administrative_and_general_expenses") -> 204695622 | K27: =SUMIFS(tbl_FERC_Expense[dollar_value],tbl_FERC_Expense[utility_id_ferc1],CompanyId,tbl_FERC_Expense[report_year],K$4,tbl_FERC_Expense[expense_type],"administrative_and_general_expenses") -> 242114888 | ... O27: =SUMIFS(tbl_FERC_Expense[dollar_value],tbl_FERC_Expense[utility_id_ferc1],CompanyId,tbl_FERC_Expense[report_year],O$4,tbl_FERC_Expense[expense_type],"administrative_and_general_expenses") -> 283831875 | P27: =IFERROR((INDEX($D27:$O27,MATCH(FercYear,$D$4:$O$4,0))/INDEX($D27:$O27,MATCH(BaseYear,$D$4:$O$4,0)))^(1/(FercYear-BaseYear))-1,0) -> 0.05128681 | Q27: =INDEX($D27:$O27,MATCH(FercYear,$D$4:$O$4,0))-INDEX($D27:$O27,MATCH(FercYear-1,$D$4:$O$4,0)) -> 20434095 | R27: {=SAFEDIV(Q27,ABS(INDEX($D27:$O27,MATCH(FercYear-1,$D$4:$O$4,0))))} -> 0.077578843
B28: Regional market and other | D28: =D29-SUM(D23:D27) -> 0 | E28: =E29-SUM(E23:E27) -> 0 | F28: =F29-SUM(F23:F27) -> 0 | G28: =G29-SUM(G23:G27) -> 0 | H28: =H29-SUM(H23:H27) -> 0 | I28: =I29-SUM(I23:I27) -> 0 | J28: =J29-SUM(J23:J27) -> 0 | K28: =K29-SUM(K23:K27) -> 0 | ... O28: =O29-SUM(O23:O27) -> 4183939 | P28: =IFERROR((INDEX($D28:$O28,MATCH(FercYear,$D$4:$O$4,0))/INDEX($D28:$O28,MATCH(BaseYear,$D$4:$O$4,0)))^(1/(FercYear-BaseYear))-1,0) -> 0 | Q28: =INDEX($D28:$O28,MATCH(FercYear,$D$4:$O$4,0))-INDEX($D28:$O28,MATCH(FercYear-1,$D$4:$O$4,0)) -> 4183939 | R28: {=SAFEDIV(Q28,ABS(INDEX($D28:$O28,MATCH(FercYear-1,$D$4:$O$4,0))))} -> 0
B29: Other O&M | D29: =SUMIFS(tbl_FERC_Expense[dollar_value],tbl_FERC_Expense[utility_id_ferc1],CompanyId,tbl_FERC_Expense[report_year],D$4,tbl_FERC_Expense[expense_type],"operations_and_maintenance_expenses_electric")-D19 -> 556588343 | E29: =SUMIFS(tbl_FERC_Expense[dollar_value],tbl_FERC_Expense[utility_id_ferc1],CompanyId,tbl_FERC_Expense[report_year],E$4,tbl_FERC_Expense[expense_type],"operations_and_maintenance_expenses_electric")-E19 -> 581874839 | F29: =SUMIFS(tbl_FERC_Expense[dollar_value],tbl_FERC_Expense[utility_id_ferc1],CompanyId,tbl_FERC_Expense[report_year],F$4,tbl_FERC_Expense[expense_type],"operations_and_maintenance_expenses_electric")-F19 -> 605520686 | G29: =SUMIFS(tbl_FERC_Expense[dollar_value],tbl_FERC_Expense[utility_id_ferc1],CompanyId,tbl_FERC_Expense[report_year],G$4,tbl_FERC_Expense[expense_type],"operations_and_maintenance_expenses_electric")-G19 -> 651229166 | H29: =SUMIFS(tbl_FERC_Expense[dollar_value],tbl_FERC_Expense[utility_id_ferc1],CompanyId,tbl_FERC_Expense[report_year],H$4,tbl_FERC_Expense[expense_type],"operations_and_maintenance_expenses_electric")-H19 -> 645493350 | I29: =SUMIFS(tbl_FERC_Expense[dollar_value],tbl_FERC_Expense[utility_id_ferc1],CompanyId,tbl_FERC_Expense[report_year],I$4,tbl_FERC_Expense[expense_type],"operations_and_maintenance_expenses_electric")-I19 -> 696324368 | J29: =SUMIFS(tbl_FERC_Expense[dollar_value],tbl_FERC_Expense[utility_id_ferc1],CompanyId,tbl_FERC_Expense[report_year],J$4,tbl_FERC_Expense[expense_type],"operations_and_maintenance_expenses_electric")-J19 -> 652220200 | K29: =SUMIFS(tbl_FERC_Expense[dollar_value],tbl_FERC_Expense[utility_id_ferc1],CompanyId,tbl_FERC_Expense[report_year],K$4,tbl_FERC_Expense[expense_type],"operations_and_maintenance_expenses_electric")-K19 -> 734683545 | ... O29: =SUMIFS(tbl_FERC_Expense[dollar_value],tbl_FERC_Expense[utility_id_ferc1],CompanyId,tbl_FERC_Expense[report_year],O$4,tbl_FERC_Expense[expense_type],"operations_and_maintenance_expenses_electric")-O19 -> 965606989 | P29: =IFERROR((INDEX($D29:$O29,MATCH(FercYear,$D$4:$O$4,0))/INDEX($D29:$O29,MATCH(BaseYear,$D$4:$O$4,0)))^(1/(FercYear-BaseYear))-1,0) -> 0.056002147 | Q29: =INDEX($D29:$O29,MATCH(FercYear,$D$4:$O$4,0))-INDEX($D29:$O29,MATCH(FercYear-1,$D$4:$O$4,0)) -> 24977493 | R29: {=SAFEDIV(Q29,ABS(INDEX($D29:$O29,MATCH(FercYear-1,$D$4:$O$4,0))))} -> 0.026554018
