Workbook

Sheet Summary
A1: Kestrel Bay Provisions: FY2027 budget cycle
A2: Synthetic BC food distributor. Every figure is a formula.
A4: The cycle
A5: V0 targets | B5: Leadership sets revenue growth and an EBITDA margin on the last twelve months.
A6: V1 submissions | B6: Sales submit channel volumes and category prices; procurement, cost inflation; logistics, freight; department heads, opex and hires. Phased on 2025's seasonality.
A7: Consolidation | B7: Bottom-up against top-down: the gap, in revenue and EBITDA.
A8: V2 challenge | B8: Foodservice price on beef and seafood, one hire deferred, warehouse non-pay cut, technology growth capped. V2 is the approved budget.
A9: Three statements | B9: Monthly P&L, balance sheet and cash flow for the approved budget, with a revolver.
A10: 3+9 reforecast | B10: After Q1: actuals, then nine months re-driven by Q1's run-rates, and the bridge.
A12: FY2027 | B12: Net revenue | C12: EBITDA | D12: EBITDA margin
A13: Last twelve months (base) | B13: =Consolidation!B6 -> 45878949 | C13: =Consolidation!B11 -> 2219484.5 | D13: =Consolidation!B12 -> 0.048376969
A14: V0 target | B14: =Consolidation!C6 -> 48631686 | C14: =Consolidation!C11 -> 2917901.2 | D14: =Consolidation!C12 -> 0.06
A15: V1 bottom-up | B15: =Consolidation!D6 -> 49557696 | C15: =Consolidation!D11 -> 1992057.8 | D15: =Consolidation!D12 -> 0.04019674
A16: V2 approved | B16: =Consolidation!E6 -> 49736612 | C16: =Consolidation!E11 -> 2326594.8 | D16: =Consolidation!E12 -> 0.046778313
A17: Reforecast 3+9 | B17: =Reforecast!C27 -> 49758340 | C17: =Reforecast!C30 -> 1656052.4 | D17: =C17/B17 -> 0.033281906
A19: Approved EBITDA still short of target by | B19: =-Consolidation!E16 -> 591306.39
A20: Further price needed from the effective month to close it | B20: =Consolidation!B27 -> 0.01282471
A21: Net income, approved budget | B21: =Statements!O17 -> 1286991.6
A22: Closing revolver / cash | B22: =Statements!O30 -> 0 | C22: =Statements!O23 -> 405081.23
A23: Checks passing | B23: =Checks!B21 -> 15 | C23: of 15

Sheet Assumptions
A1: Assumptions: every input to the FY2027 cycle
A2: Blue on yellow is an input. Every other number in the workbook is a formula over these and the data sheets.
B3: Fiscal year | C3: 2027
A4: V0 Top-down targets
B5: Revenue growth on the last twelve months | C5: 0.06
B6: EBITDA margin | C6: 0.06
A8: V1 Category submissions (sales and procurement); V2 challenge
A9: Category | B9: V1 price increase | C9: V1 cost inflation | D9: V2 extra price, foodservice
A10: Beef | B10: 0.04 | C10: 0.06 | D10: 0.015
A11: Pork | B11: 0.025 | C11: 0.03 | D11: 0
A12: Poultry | B12: 0.02 | C12: 0.025 | D12: 0
A13: Seafood | B13: 0.03 | C13: 0.035 | D13: 0.015
A14: Charcuterie | B14: 0.02 | C14: 0.02 | D14: 0
A15: Cheese & Dairy | B15: 0.015 | C15: 0.02 | D15: 0
A17: V1 Channel submissions (sales)
A18: Channel | B18: V1 volume growth | C18: Foodservice (1 = yes)
A19: Restaurants | B19: 0.02 | C19: 1
A20: Grocery Retail | B20: 0.09 | C20: 0
A21: Hotels & Institutions | B21: 0.01 | C21: 1
A22: Online Direct | B22: 0.18 | C22: 0
A24: V1 Department submissions; V2 challenge
A25: Department | B25: V1 opex growth | C25: V2 growth cap | D25: V2 cut to base
A26: Sales & Marketing | B26: 0.05
A27: Warehouse & Logistics | B27: 0.06 | D27: 0.03
A28: General & Admin | B28: 0.03
A29: Technology | B29: 0.08 | C29: 0.05
A31: V1 New hires; V2 timing
A32: Department | B32: FTE | C32: Annual loaded cost | D32: Start month V1 | E32: Start month V2 | F32: Start used in V2
A33: Sales & Marketing | B33: 1 | C33: 95000 | D33: 4 | E33: 7 | F33: =IF(E33="",D33,E33) -> 7
A34: Warehouse & Logistics | B34: 2 | C34: 68000 | D34: 3 | F34: =IF(E34="",D34,E34) -> 3
A36: Timing and freight
B37: Price increases take effect in month | C37: 2
B38: Freight inflation | C38: 0.04
A40: Balance sheet and financing
B41: Opening cash | C41: 500000
B42: Minimum cash | C42: 400000
B43: Opening revolver | C43: 1200000
B44: Revolver rate | C44: 0.072
B45: Opening PP&E, net | C45: 2400000
B46: D&A on existing assets, per month | C46: 38000
...

Sheet Consolidation
A1: Consolidation: top-down meets bottom-up
A2: V0 is what leadership asked for, V1 what the business submitted, V2 what the challenge round approved.
B5: Last 12 months | C5: V0 target | D5: V1 bottom-up | E5: V2 approved
A6: Net revenue | B6: =SUM(Data_Base!D5:D28) -> 45878949 | C6: =B6*(1+Assumptions!C5) -> 48631686 | D6: =SUM(Build!$J$5:$J$292) -> 49557696 | E6: =SUM(Build!$K$5:$K$292) -> 49736612
A7: COGS | B7: =SUM(Data_Base!E5:E28) -> 33883211 | D7: =SUM(Build!$M$5:$M$292) -> 37027966 | E7: =SUM(Build!$M$5:$M$292) -> 37027966
A8: Freight | B8: =SUM(Data_Base!F5:F28) -> 1053687.3 | D8: =SUM(Build!$O$5:$O$292) -> 1182087.4 | E8: =SUM(Build!$O$5:$O$292) -> 1182087.4
A9: Gross margin | B9: =B6-B7-B8 -> 10942051 | D9: =D6-D7-D8 -> 11347642 | E9: =E6-E7-E8 -> 11526558
A10: Opex | B10: =SUM(Data_Base!B41:B44) -> 8722566.4 | D10: =Opex!O10 -> 9355584.4 | E10: =Opex!O17 -> 9199963.4
A11: EBITDA | B11: =B9-B10 -> 2219484.5 | C11: =C6*Assumptions!C6 -> 2917901.2 | D11: =D9-D10 -> 1992057.8 | E11: =E9-E10 -> 2326594.8
A12: EBITDA margin | B12: =B11/B6 -> 0.048376969 | C12: =C11/C6 -> 0.06 | D12: =D11/D6 -> 0.04019674 | E12: =E11/E6 -> 0.046778313
A14: Gap to target
A15: Revenue | D15: =D6-$C$6 -> 926009.35 | E15: =E6-$C$6 -> 1104925.3
A16: EBITDA | D16: =D11-$C$11 -> -925843.39 | E16: =E11-$C$11 -> -591306.39
A18: Challenge round: V1 to V2 EBITDA
A19: Foodservice price on beef and seafood | B19: =E6-D6 -> 178915.93
A20: Opex: Sales & Marketing | B20: =Opex!O6-Opex!O13 -> 23750
A21: Opex: Warehouse & Logistics | B21: =Opex!O7-Opex!O14 -> 111107.4
A22: Opex: General & Admin | B22: =Opex!O8-Opex!O15 -> 0
A23: Opex: Technology | B23: =Opex!O9-Opex!O16 -> 20763.675
A24: V1 to V2, total | B24: =SUM(B19:B23) -> 334537
A26: What closing the rest would take
A27: Further price on every line from the effective month, to reach the EBITDA target | B27: =-E16/SUMIFS(Build!$K$5:$K$292,Build!$A$5:$A$292,">="&Assumptions!C37) -> 0.01282471

Sheet Statements
A1: Three statements: the approved budget (V2), monthly
A2: Interest accrues on the opening revolver, so there is no circular reference. The revolver draws to hold minimum cash and repays from any surplus.
B4: Opening | C4: =COLUMN()-2 -> 1 | D4: =COLUMN()-2 -> 2 | E4: =COLUMN()-2 -> 3 | F4: =COLUMN()-2 -> 4 | G4: =COLUMN()-2 -> 5 | H4: =COLUMN()-2 -> 6 | I4: =COLUMN()-2 -> 7 | J4: =COLUMN()-2 -> 8 | ... N4: =COLUMN()-2 -> 12 | O4: FY2027
A5: Income statement
A6: Net revenue | C6: =SUMIFS(Build!$K$5:$K$292,Build!$A$5:$A$292,C$4) -> 3629806.3 | D6: =SUMIFS(Build!$K$5:$K$292,Build!$A$5:$A$292,D$4) -> 3647778 | E6: =SUMIFS(Build!$K$5:$K$292,Build!$A$5:$A$292,E$4) -> 3881705.5 | F6: =SUMIFS(Build!$K$5:$K$292,Build!$A$5:$A$292,F$4) -> 4082496.7 | G6: =SUMIFS(Build!$K$5:$K$292,Build!$A$5:$A$292,G$4) -> 4397937.4 | H6: =SUMIFS(Build!$K$5:$K$292,Build!$A$5:$A$292,H$4) -> 4539444.5 | I6: =SUMIFS(Build!$K$5:$K$292,Build!$A$5:$A$292,I$4) -> 4496211.5 | J6: =SUMIFS(Build!$K$5:$K$292,Build!$A$5:$A$292,J$4) -> 4374070.2 | ... N6: =SUMIFS(Build!$K$5:$K$292,Build!$A$5:$A$292,N$4) -> 4462051.6 | O6: =SUM(C6:N6) -> 49736612
A7: COGS | C7: =SUMIFS(Build!$M$5:$M$292,Build!$A$5:$A$292,C$4) -> 2773697.3 | D7: =SUMIFS(Build!$M$5:$M$292,Build!$A$5:$A$292,D$4) -> 2708509.7 | E7: =SUMIFS(Build!$M$5:$M$292,Build!$A$5:$A$292,E$4) -> 2884041.3 | F7: =SUMIFS(Build!$M$5:$M$292,Build!$A$5:$A$292,F$4) -> 3037039.2 | G7: =SUMIFS(Build!$M$5:$M$292,Build!$A$5:$A$292,G$4) -> 3281472.5 | H7: =SUMIFS(Build!$M$5:$M$292,Build!$A$5:$A$292,H$4) -> 3395167.7 | I7: =SUMIFS(Build!$M$5:$M$292,Build!$A$5:$A$292,I$4) -> 3362378.6 | J7: =SUMIFS(Build!$M$5:$M$292,Build!$A$5:$A$292,J$4) -> 3266534.4 | ... N7: =SUMIFS(Build!$M$5:$M$292,Build!$A$5:$A$292,N$4) -> 3277630.1 | O7: =SUM(C7:N7) -> 37027966
A8: Freight | C8: =SUMIFS(Build!$O$5:$O$292,Build!$A$5:$A$292,C$4) -> 90280.503 | D8: =SUMIFS(Build!$O$5:$O$292,Build!$A$5:$A$292,D$4) -> 87782.28 | E8: =SUMIFS(Build!$O$5:$O$292,Build!$A$5:$A$292,E$4) -> 92834.643 | F8: =SUMIFS(Build!$O$5:$O$292,Build!$A$5:$A$292,F$4) -> 96753.285 | G8: =SUMIFS(Build!$O$5:$O$292,Build!$A$5:$A$292,G$4) -> 102937.84 | H8: =SUMIFS(Build!$O$5:$O$292,Build!$A$5:$A$292,H$4) -> 105482.13 | I8: =SUMIFS(Build!$O$5:$O$292,Build!$A$5:$A$292,I$4) -> 104704.14 | J8: =SUMIFS(Build!$O$5:$O$292,Build!$A$5:$A$292,J$4) -> 102393.93 | ... N8: =SUMIFS(Build!$O$5:$O$292,Build!$A$5:$A$292,N$4) -> 107442.06 | O8: =SUM(C8:N8) -> 1182087.4
A9: Gross margin | C9: =C6-C7-C8 -> 765828.4 | D9: =D6-D7-D8 -> 851485.97 | E9: =E6-E7-E8 -> 904829.55 | F9: =F6-F7-F8 -> 948704.16 | G9: =G6-G7-G8 -> 1013527.1 | H9: =H6-H7-H8 -> 1038794.6 | I9: =I6-I7-I8 -> 1029128.7 | J9: =J6-J7-J8 -> 1005141.9 | ... N9: =N6-N7-N8 -> 1076979.5 | O9: =SUM(C9:N9) -> 11526558
A10: Opex | C10: =INDEX(Opex!$C$17:$N$17,C$4) -> 753260.84 | D10: =INDEX(Opex!$C$17:$N$17,D$4) -> 753260.84 | E10: =INDEX(Opex!$C$17:$N$17,E$4) -> 764594.17 | F10: =INDEX(Opex!$C$17:$N$17,F$4) -> 764594.17 | G10: =INDEX(Opex!$C$17:$N$17,G$4) -> 764594.17 | H10: =INDEX(Opex!$C$17:$N$17,H$4) -> 764594.17 | I10: =INDEX(Opex!$C$17:$N$17,I$4) -> 772510.84 | J10: =INDEX(Opex!$C$17:$N$17,J$4) -> 772510.84 | ... N10: =INDEX(Opex!$C$17:$N$17,N$4) -> 772510.84 | O10: =SUM(C10:N10) -> 9199963.4
A11: EBITDA | C11: =C9-C10 -> 12567.568 | D11: =D9-D10 -> 98225.13 | E11: =E9-E10 -> 140235.38 | F11: =F9-F10 -> 184109.99 | G11: =G9-G10 -> 248932.94 | H11: =H9-H10 -> 274200.43 | I11: =I9-I10 -> 256617.86 | J11: =J9-J10 -> 232631.07 | ... N11: =N9-N10 -> 304468.7 | O11: =SUM(C11:N11) -> 2326594.8
A12: Depreciation & amortisation | C12: =Assumptions!$C$46+SUMIF(Assumptions!$B$54:$M$54,"<"&C$4,Assumptions!$B$55:$M$55)/Assumptions!$C$47 -> 38000 | D12: =Assumptions!$C$46+SUMIF(Assumptions!$B$54:$M$54,"<"&D$4,Assumptions!$B$55:$M$55)/Assumptions!$C$47 -> 38000 | E12: =Assumptions!$C$46+SUMIF(Assumptions!$B$54:$M$54,"<"&E$4,Assumptions!$B$55:$M$55)/Assumptions!$C$47 -> 38000 | F12: =Assumptions!$C$46+SUMIF(Assumptions!$B$54:$M$54,"<"&F$4,Assumptions!$B$55:$M$55)/Assumptions!$C$47 -> 42166.667 | G12: =Assumptions!$C$46+SUMIF(Assumptions!$B$54:$M$54,"<"&G$4,Assumptions!$B$55:$M$55)/Assumptions!$C$47 -> 42166.667 | H12: =Assumptions!$C$46+SUMIF(Assumptions!$B$54:$M$54,"<"&H$4,Assumptions!$B$55:$M$55)/Assumptions!$C$47 -> 42166.667 | I12: =Assumptions!$C$46+SUMIF(Assumptions!$B$54:$M$54,"<"&I$4,Assumptions!$B$55:$M$55)/Assumptions!$C$47 -> 44666.667 | J12: =Assumptions!$C$46+SUMIF(Assumptions!$B$54:$M$54,"<"&J$4,Assumptions!$B$55:$M$55)/Assumptions!$C$47 -> 44666.667 | ... N12: =Assumptions!$C$46+SUMIF(Assumptions!$B$54:$M$54,"<"&N$4,Assumptions!$B$55:$M$55)/Assumptions!$C$47 -> 48000 | O12: =SUM(C12:N12) -> 518500
A13: EBIT | C13: =C11-C12 -> -25432.432 | D13: =D11-D12 -> 60225.13 | E13: =E11-E12 -> 102235.38 | F13: =F11-F12 -> 141943.32 | G13: =G11-G12 -> 206766.28 | H13: =H11-H12 -> 232033.77 | I13: =I11-I12 -> 211951.19 | J13: =J11-J12 -> 187964.4 | ... N13: =N11-N12 -> 256468.7 | O13: =SUM(C13:N13) -> 1808094.8
A14: Interest | C14: =B30*Assumptions!$C$44/12 -> 7200 | D14: =C30*Assumptions!$C$44/12 -> 3006.1757 | E14: =D30*Assumptions!$C$44/12 -> 4608.0538 | F14: =E30*Assumptions!$C$44/12 -> 4730.612 | G14: =F30*Assumptions!$C$44/12 -> 5404.583 | H14: =G30*Assumptions!$C$44/12 -> 5061.8851 | I14: =H30*Assumptions!$C$44/12 -> 6026.9671 | J14: =I30*Assumptions!$C$44/12 -> 3972.2771 | ... N14: =M30*Assumptions!$C$44/12 -> 255.18067 | O14: =SUM(C14:N14) -> 45092.602
A15: Pre-tax income | C15: =C13-C14 -> -32632.432 | D15: =D13-D14 -> 57218.954 | E15: =E13-E14 -> 97627.329 | F15: =F13-F14 -> 137212.71 | G15: =G13-G14 -> 201361.7 | H15: =H13-H14 -> 226971.88 | I15: =I13-I14 -> 205924.22 | J15: =J13-J14 -> 183992.12 | ... N15: =N13-N14 -> 256213.52 | O15: =SUM(C15:N15) -> 1763002.2
A16: Tax | C16: =C15*Assumptions!$C$48 -> -8810.7566 | D16: =D15*Assumptions!$C$48 -> 15449.118 | E16: =E15*Assumptions!$C$48 -> 26359.379 | F16: =F15*Assumptions!$C$48 -> 37047.432 | G16: =G15*Assumptions!$C$48 -> 54367.658 | H16: =H15*Assumptions!$C$48 -> 61282.408 | I16: =I15*Assumptions!$C$48 -> 55599.54 | J16: =J15*Assumptions!$C$48 -> 49677.873 | ... N16: =N15*Assumptions!$C$48 -> 69177.65 | O16: =SUM(C16:N16) -> 476010.59
A17: Net income | C17: =C15-C16 -> -23821.675 | D17: =D15-D16 -> 41769.836 | E17: =E15-E16 -> 71267.95 | F17: =F15-F16 -> 100165.28 | G17: =G15-G16 -> 146994.04 | H17: =H15-H16 -> 165689.47 | I17: =I15-I16 -> 150324.68 | J17: =J15-J16 -> 134314.25 | ... N17: =N15-N16 -> 187035.87 | O17: =SUM(C17:N17) -> 1286991.6
A19: Capex | C19: =INDEX(Assumptions!$B$55:$M$55,C$4) -> 0 | D19: =INDEX(Assumptions!$B$55:$M$55,D$4) -> 0 | E19: =INDEX(Assumptions!$B$55:$M$55,E$4) -> 250000 | F19: =INDEX(Assumptions!$B$55:$M$55,F$4) -> 0 | G19: =INDEX(Assumptions!$B$55:$M$55,G$4) -> 0 | H19: =INDEX(Assumptions!$B$55:$M$55,H$4) -> 150000 | I19: =INDEX(Assumptions!$B$55:$M$55,I$4) -> 0 | J19: =INDEX(Assumptions!$B$55:$M$55,J$4) -> 0 | ... N19: =INDEX(Assumptions!$B$55:$M$55,N$4) -> 0 | O19: =SUM(C19:N19) -> 600000
A20: Days in month | C20: =DAY(EOMONTH(DATE(Assumptions!$C$3,C$4,1),0)) -> 31 | D20: =DAY(EOMONTH(DATE(Assumptions!$C$3,D$4,1),0)) -> 28 | E20: =DAY(EOMONTH(DATE(Assumptions!$C$3,E$4,1),0)) -> 31 | F20: =DAY(EOMONTH(DATE(Assumptions!$C$3,F$4,1),0)) -> 30 | G20: =DAY(EOMONTH(DATE(Assumptions!$C$3,G$4,1),0)) -> 31 | H20: =DAY(EOMONTH(DATE(Assumptions!$C$3,H$4,1),0)) -> 30 | I20: =DAY(EOMONTH(DATE(Assumptions!$C$3,I$4,1),0)) -> 31 | J20: =DAY(EOMONTH(DATE(Assumptions!$C$3,J$4,1),0)) -> 31 | ... N20: =DAY(EOMONTH(DATE(Assumptions!$C$3,N$4,1),0)) -> 31
A22: Balance sheet
A23: Cash | B23: =Assumptions!C41 -> 500000 | C23: =C42+C43 -> 400000 | D23: =D42+D43 -> 400000 | E23: =E42+E43 -> 400000 | F23: =F42+F43 -> 400000 | G23: =G42+G43 -> 400000 | H23: =H42+H43 -> 400000 | I23: =I42+I43 -> 400000 | J23: =J42+J43 -> 400000 | ... N23: =N42+N43 -> 405081.23 | O23: =N23 -> 405081.23
A24: Accounts receivable | B24: =INDEX(Data_Base!$B$48:$B$50,MATCH("Accounts receivable",Data_Base!$A$48:$A$50,0)) -> 4501878.4 | C24: =C6/C20*Assumptions!$C$49 -> 3981077.8 | D24: =D6/D20*Assumptions!$C$49 -> 4429444.7 | E24: =E6/E20*Assumptions!$C$49 -> 4257354.4 | F24: =F6/F20*Assumptions!$C$49 -> 4626829.6 | G24: =G6/G20*Assumptions!$C$49 -> 4823544.3 | H24: =H6/H20*Assumptions!$C$49 -> 5144703.7 | I24: =I6/I20*Assumptions!$C$49 -> 4931328.7 | J24: =J6/J20*Assumptions!$C$49 -> 4797367.4 | ... N24: =N6/N20*Assumptions!$C$49 -> 4893863.1 | O24: =N24 -> 4893863.1
A25: Inventory | B25: =INDEX(Data_Base!$B$48:$B$50,MATCH("Inventory",Data_Base!$A$48:$A$50,0)) -> 1715054.6 | C25: =C7/C20*Assumptions!$C$50 -> 1521059.8 | D25: =D7/D20*Assumptions!$C$50 -> 1644452.3 | E25: =E7/E20*Assumptions!$C$50 -> 1581571 | F25: =F7/F20*Assumptions!$C$50 -> 1720988.9 | G25: =G7/G20*Assumptions!$C$50 -> 1799517.2 | H25: =H7/H20*Assumptions!$C$50 -> 1923928.4 | I25: =I7/I20*Assumptions!$C$50 -> 1843885.1 | J25: =J7/J20*Assumptions!$C$50 -> 1791325.3 | ... N25: =N7/N20*Assumptions!$C$50 -> 1797410 | O25: =N25 -> 1797410
A26: PP&E, net | B26: =Assumptions!C45 -> 2400000 | C26: =B26+C19-C12 -> 2362000 | D26: =C26+D19-D12 -> 2324000 | E26: =D26+E19-E12 -> 2536000 | F26: =E26+F19-F12 -> 2493833.3 | G26: =F26+G19-G12 -> 2451666.7 | H26: =G26+H19-H12 -> 2559500 | I26: =H26+I19-I12 -> 2514833.3 | J26: =I26+J19-J12 -> 2470166.7 | ... N26: =M26+N19-N12 -> 2481500 | O26: =N26 -> 2481500
A27: Total assets | B27: =SUM(B23:B26) -> 9116933 | C27: =SUM(C23:C26) -> 8264137.7 | D27: =SUM(D23:D26) -> 8797897 | E27: =SUM(E23:E26) -> 8774925.4 | F27: =SUM(F23:F26) -> 9241651.8 | G27: =SUM(G23:G26) -> 9474728.1 | H27: =SUM(H23:H26) -> 10028132 | I27: =SUM(I23:I26) -> 9690047.1 | ... N27: =SUM(N23:N26) -> 9577854.4 | O27: =N27 -> 9577854.4
A28: Accounts payable | B28: =INDEX(Data_Base!$B$48:$B$50,MATCH("Accounts payable",Data_Base!$A$48:$A$50,0)) -> 2903700.3 | C28: =C7/C20*Assumptions!$C$51 -> 2773697.3 | D28: =D7/D20*Assumptions!$C$51 -> 2998707.2 | E28: =E7/E20*Assumptions!$C$51 -> 2884041.3 | F28: =F7/F20*Assumptions!$C$51 -> 3138273.9 | G28: =G7/G20*Assumptions!$C$51 -> 3281472.5 | H28: =H7/H20*Assumptions!$C$51 -> 3508340 | I28: =I7/I20*Assumptions!$C$51 -> 3362378.6 | J28: =J7/J20*Assumptions!$C$51 -> 3266534.4 | ... N28: =N7/N20*Assumptions!$C$51 -> 3277630.1 | O28: =N28 -> 3277630.1
A30: Revolver | B30: =Assumptions!C43 -> 1200000 | C30: =B30+C43 -> 501029.29 | D30: =C30+D43 -> 768008.97 | E30: =D30+E43 -> 788435.33 | F30: =E30+F43 -> 900763.84 | G30: =F30+G43 -> 843647.51 | H30: =G30+H43 -> 1004494.5 | I30: =H30+I43 -> 662046.18 | J30: =I30+J43 -> 392388.4 | ... N30: =M30+N43 -> 0 | O30: =N30 -> 0
A31: Equity | B31: =B27-B28-B30 -> 5013232.7 | C31: =B31+C17 -> 4989411 | D31: =C31+D17 -> 5031180.9 | E31: =D31+E17 -> 5102448.8 | F31: =E31+F17 -> 5202614.1 | G31: =F31+G17 -> 5349608.1 | H31: =G31+H17 -> 5515297.6 | I31: =H31+I17 -> 5665622.3 | J31: =I31+J17 -> 5799936.5 | ... N31: =M31+N17 -> 6300224.3 | O31: =N31 -> 6300224.3
A32: Total liabilities and equity | B32: =B28+B30+B31 -> 9116933 | C32: =C28+C30+C31 -> 8264137.7 | D32: =D28+D30+D31 -> 8797897 | E32: =E28+E30+E31 -> 8774925.4 | F32: =F28+F30+F31 -> 9241651.8 | G32: =G28+G30+G31 -> 9474728.1 | H32: =H28+H30+H31 -> 10028132 | I32: =I28+I30+I31 -> 9690047.1 | ... N32: =N28+N30+N31 -> 9577854.4 | O32: =N32 -> 9577854.4
A33: Balance check (assets - L&E) | B33: =B27-B32 -> 0 | C33: =C27-C32 -> 0 | D33: =D27-D32 -> 0 | E33: =E27-E32 -> 0 | F33: =F27-F32 -> 0 | G33: =G27-G32 -> 0 | H33: =H27-H32 -> 0 | I33: =I27-I32 -> 0 | ... N33: =N27-N32 -> 0
A34: Cash flow
A35: Net income | C35: =C17 -> -23821.675 | D35: =D17 -> 41769.836 | E35: =E17 -> 71267.95 | F35: =F17 -> 100165.28 | G35: =G17 -> 146994.04 | H35: =H17 -> 165689.47 | I35: =I17 -> 150324.68 | J35: =J17 -> 134314.25 | ... N35: =N17 -> 187035.87 | O35: =SUM(C35:N35) -> 1286991.6
A36: D&A | C36: =C12 -> 38000 | D36: =D12 -> 38000 | E36: =E12 -> 38000 | F36: =F12 -> 42166.667 | G36: =G12 -> 42166.667 | H36: =H12 -> 42166.667 | I36: =I12 -> 44666.667 | J36: =J12 -> 44666.667 | ... N36: =N12 -> 48000 | O36: =SUM(C36:N36) -> 518500
A37: (Increase) in receivables | C37: =-(C24-B24) -> 520800.56 | D37: =-(D24-C24) -> -448366.88 | E37: =-(E24-D24) -> 172090.31 | F37: =-(F24-E24) -> -369475.17 | G37: =-(G24-F24) -> -196714.72 | H37: =-(H24-G24) -> -321159.42 | I37: =-(I24-H24) -> 213375.01 | J37: =-(J24-I24) -> 133961.36 | ... N37: =-(N24-M24) -> -264625.96 | O37: =SUM(C37:N37) -> -391984.71
A38: (Increase) in inventory | C38: =-(C25-B25) -> 193994.79 | D38: =-(D25-C25) -> -123392.51 | E38: =-(E25-D25) -> 62881.319 | F38: =-(F25-E25) -> -139417.87 | G38: =-(G25-F25) -> -78528.271 | H38: =-(H25-G25) -> -124411.2 | I38: =-(I25-H25) -> 80043.32 | J38: =-(J25-I25) -> 52559.74 | ... N38: =-(N25-M25) -> -93744.609 | O38: =SUM(C38:N38) -> -82355.409
A39: Increase in payables | C39: =C28-B28 -> -130002.96 | D39: =D28-C28 -> 225009.88 | E39: =E28-D28 -> -114665.93 | F39: =F28-E28 -> 254232.59 | G39: =G28-F28 -> 143198.61 | H39: =H28-G28 -> 226867.49 | I39: =I28-H28 -> -145961.35 | J39: =J28-I28 -> -95844.231 | ... N39: =N28-M28 -> 170946.05 | O39: =SUM(C39:N39) -> 373929.75
A40: Cash from operations | C40: =SUM(C35:C39) -> 598970.71 | D40: =SUM(D35:D39) -> -266979.68 | E40: =SUM(E35:E39) -> 229573.64 | F40: =SUM(F35:F39) -> -112328.51 | G40: =SUM(G35:G39) -> 57116.323 | H40: =SUM(H35:H39) -> -10846.996 | I40: =SUM(I35:I39) -> 342448.33 | J40: =SUM(J35:J39) -> 269657.78 | ... N40: =SUM(N35:N39) -> 47611.345 | O40: =SUM(C40:N40) -> 1705081.2
A41: Capex | C41: =-C19 -> 0 | D41: =-D19 -> 0 | E41: =-E19 -> -250000 | F41: =-F19 -> 0 | G41: =-G19 -> 0 | H41: =-H19 -> -150000 | I41: =-I19 -> 0 | J41: =-J19 -> 0 | ... N41: =-N19 -> 0 | O41: =SUM(C41:N41) -> -600000
A42: Cash before financing | C42: =B23+C40+C41 -> 1098970.7 | D42: =C23+D40+D41 -> 133020.32 | E42: =D23+E40+E41 -> 379573.64 | F42: =E23+F40+F41 -> 287671.49 | G42: =F23+G40+G41 -> 457116.32 | H42: =G23+H40+H41 -> 239153 | I42: =H23+I40+I41 -> 742448.33 | J42: =I23+J40+J41 -> 669657.78 | ... N42: =M23+N40+N41 -> 447611.35
A43: Revolver draw / (repayment) | C43: =MAX(Assumptions!$C$42-C42,-B30) -> -698970.71 | D43: =MAX(Assumptions!$C$42-D42,-C30) -> 266979.68 | E43: =MAX(Assumptions!$C$42-E42,-D30) -> 20426.358 | F43: =MAX(Assumptions!$C$42-F42,-E30) -> 112328.51 | G43: =MAX(Assumptions!$C$42-G42,-F30) -> -57116.323 | H43: =MAX(Assumptions!$C$42-H42,-G30) -> 160847 | I43: =MAX(Assumptions!$C$42-I42,-H30) -> -342448.33 | J43: =MAX(Assumptions!$C$42-J42,-I30) -> -269657.78 | ... N43: =MAX(Assumptions!$C$42-N42,-M30) -> -42530.111 | O43: =SUM(C43:N43) -> -1200000
A44: Net change in cash | C44: =C40+C41+C43 -> -100000 | D44: =D40+D41+D43 -> 0 | E44: =E40+E41+E43 -> 0 | F44: =F40+F41+F43 -> 0 | G44: =G40+G41+G43 -> 0 | H44: =H40+H41+H43 -> 0 | I44: =I40+I41+I43 -> 0 | J44: =J40+J41+J43 -> 0 | ... N44: =N40+N41+N43 -> 5081.2343 | O44: =SUM(C44:N44) -> -94918.766
...

Sheet Reforecast
A1: Reforecast 3+9: Q1 actuals, then nine months re-driven
A2: Apr-Dec take Q1's volume run-rate by channel, unit cost by category and opex by department; prices stay at budget.
A5: Channel | B5: Q1 budget cases | C5: Q1 actual cases | D5: Volume ratio
A6: Restaurants | B6: =SUMIFS(Build!$F$5:$F$292,Build!$D$5:$D$292,A6,Build!$A$5:$A$292,"<=3") -> 32022.068 | C6: =SUMIFS(Data_Q1!$D$5:$D$76,Data_Q1!$C$5:$C$76,A6) -> 30678.4 | D6: =C6/B6 -> 0.95803931
A7: Grocery Retail | B7: =SUMIFS(Build!$F$5:$F$292,Build!$D$5:$D$292,A7,Build!$A$5:$A$292,"<=3") -> 26093.921 | C7: =SUMIFS(Data_Q1!$D$5:$D$76,Data_Q1!$C$5:$C$76,A7) -> 27656.8 | D7: =C7/B7 -> 1.0598944
A8: Hotels & Institutions | B8: =SUMIFS(Build!$F$5:$F$292,Build!$D$5:$D$292,A8,Build!$A$5:$A$292,"<=3") -> 12974.341 | C8: =SUMIFS(Data_Q1!$D$5:$D$76,Data_Q1!$C$5:$C$76,A8) -> 12989.5 | D8: =C8/B8 -> 1.0011684
A9: Online Direct | B9: =SUMIFS(Build!$F$5:$F$292,Build!$D$5:$D$292,A9,Build!$A$5:$A$292,"<=3") -> 6722.6885 | C9: =SUMIFS(Data_Q1!$D$5:$D$76,Data_Q1!$C$5:$C$76,A9) -> 6738.5 | D9: =C9/B9 -> 1.002352
A11: Category | B11: Q1 budget cost / case | C11: Q1 actual cost / case | D11: Cost ratio
A12: Beef | B12: =SUMIFS(Build!$M$5:$M$292,Build!$C$5:$C$292,A12,Build!$A$5:$A$292,"<=3")/SUMIFS(Build!$F$5:$F$292,Build!$C$5:$C$292,A12,Build!$A$5:$A$292,"<=3") -> 158.79117 | C12: =SUMIFS(Data_Q1!$F$5:$F$76,Data_Q1!$B$5:$B$76,A12)/SUMIFS(Data_Q1!$D$5:$D$76,Data_Q1!$B$5:$B$76,A12) -> 163.16253 | D12: =C12/B12 -> 1.027529
A13: Pork | B13: =SUMIFS(Build!$M$5:$M$292,Build!$C$5:$C$292,A13,Build!$A$5:$A$292,"<=3")/SUMIFS(Build!$F$5:$F$292,Build!$C$5:$C$292,A13,Build!$A$5:$A$292,"<=3") -> 88.76956 | C13: =SUMIFS(Data_Q1!$F$5:$F$76,Data_Q1!$B$5:$B$76,A13)/SUMIFS(Data_Q1!$D$5:$D$76,Data_Q1!$B$5:$B$76,A13) -> 88.946568 | D13: =C13/B13 -> 1.001994
A14: Poultry | B14: =SUMIFS(Build!$M$5:$M$292,Build!$C$5:$C$292,A14,Build!$A$5:$A$292,"<=3")/SUMIFS(Build!$F$5:$F$292,Build!$C$5:$C$292,A14,Build!$A$5:$A$292,"<=3") -> 80.425764 | C14: =SUMIFS(Data_Q1!$F$5:$F$76,Data_Q1!$B$5:$B$76,A14)/SUMIFS(Data_Q1!$D$5:$D$76,Data_Q1!$B$5:$B$76,A14) -> 80.412307 | D14: =C14/B14 -> 0.99983268
A15: Seafood | B15: =SUMIFS(Build!$M$5:$M$292,Build!$C$5:$C$292,A15,Build!$A$5:$A$292,"<=3")/SUMIFS(Build!$F$5:$F$292,Build!$C$5:$C$292,A15,Build!$A$5:$A$292,"<=3") -> 155.74611 | C15: =SUMIFS(Data_Q1!$F$5:$F$76,Data_Q1!$B$5:$B$76,A15)/SUMIFS(Data_Q1!$D$5:$D$76,Data_Q1!$B$5:$B$76,A15) -> 156.05085 | D15: =C15/B15 -> 1.0019566
A16: Charcuterie | B16: =SUMIFS(Build!$M$5:$M$292,Build!$C$5:$C$292,A16,Build!$A$5:$A$292,"<=3")/SUMIFS(Build!$F$5:$F$292,Build!$C$5:$C$292,A16,Build!$A$5:$A$292,"<=3") -> 97.966965 | C16: =SUMIFS(Data_Q1!$F$5:$F$76,Data_Q1!$B$5:$B$76,A16)/SUMIFS(Data_Q1!$D$5:$D$76,Data_Q1!$B$5:$B$76,A16) -> 97.971989 | D16: =C16/B16 -> 1.0000513
A17: Cheese & Dairy | B17: =SUMIFS(Build!$M$5:$M$292,Build!$C$5:$C$292,A17,Build!$A$5:$A$292,"<=3")/SUMIFS(Build!$F$5:$F$292,Build!$C$5:$C$292,A17,Build!$A$5:$A$292,"<=3") -> 85.188347 | C17: =SUMIFS(Data_Q1!$F$5:$F$76,Data_Q1!$B$5:$B$76,A17)/SUMIFS(Data_Q1!$D$5:$D$76,Data_Q1!$B$5:$B$76,A17) -> 85.39057 | D17: =C17/B17 -> 1.0023738
A19: Department | B19: Q1 budget opex | C19: Q1 actual opex | D19: Opex ratio | E19: Apr-Dec budget | F19: Apr-Dec reforecast
A20: Sales & Marketing | B20: =SUMPRODUCT((Opex!$A$13:$A$16=A20)*(Opex!$C$5:$N$5<=3)*Opex!$C$13:$N$16) -> 621249.57 | C20: =SUMIFS(Data_Q1!$C$80:$C$91,Data_Q1!$B$80:$B$91,A20) -> 620486.96 | D20: =C20/B20 -> 0.99877247 | E20: =SUMPRODUCT((Opex!$A$13:$A$16=A20)*(Opex!$C$5:$N$5>3)*Opex!$C$13:$N$16) -> 1911248.7 | F20: =E20*D20 -> 1908902.6
A21: Warehouse & Logistics | B21: =SUMPRODUCT((Opex!$A$13:$A$16=A21)*(Opex!$C$5:$N$5<=3)*Opex!$C$13:$N$16) -> 909451.47 | C21: =SUMIFS(Data_Q1!$C$80:$C$91,Data_Q1!$B$80:$B$91,A21) -> 960950.49 | D21: =C21/B21 -> 1.0566265 | E21: =SUMPRODUCT((Opex!$A$13:$A$16=A21)*(Opex!$C$5:$N$5>3)*Opex!$C$13:$N$16) -> 2796354.4 | F21: =E21*D21 -> 2954702.1
A22: General & Admin | B22: =SUMPRODUCT((Opex!$A$13:$A$16=A22)*(Opex!$C$5:$N$5<=3)*Opex!$C$13:$N$16) -> 558732.66 | C22: =SUMIFS(Data_Q1!$C$80:$C$91,Data_Q1!$B$80:$B$91,A22) -> 559633.08 | D22: =C22/B22 -> 1.0016115 | E22: =SUMPRODUCT((Opex!$A$13:$A$16=A22)*(Opex!$C$5:$N$5>3)*Opex!$C$13:$N$16) -> 1676198 | F22: =E22*D22 -> 1678899.2
A23: Technology | B23: =SUMPRODUCT((Opex!$A$13:$A$16=A23)*(Opex!$C$5:$N$5<=3)*Opex!$C$13:$N$16) -> 181682.15 | C23: =SUMIFS(Data_Q1!$C$80:$C$91,Data_Q1!$B$80:$B$91,A23) -> 181791.51 | D23: =C23/B23 -> 1.0006019 | E23: =SUMPRODUCT((Opex!$A$13:$A$16=A23)*(Opex!$C$5:$N$5>3)*Opex!$C$13:$N$16) -> 545046.46 | F23: =E23*D23 -> 545374.53
A26: FY2027 | B26: Budget (V2) | C26: Reforecast 3+9 | D26: Variance
A27: Net revenue | B27: =Consolidation!E6 -> 49736612 | C27: =SUM(Build!$Q$5:$Q$292) -> 49758340 | D27: =C27-B27 -> 21728.503
A28: Gross margin | B28: =Consolidation!E9 -> 11526558 | C28: =SUM(Build!$Q$5:$Q$292)-SUM(Build!$R$5:$R$292)-SUM(Build!$S$5:$S$292) -> 11066793 | D28: =C28-B28 -> -459765.34
A29: Opex | B29: =Consolidation!E10 -> 9199963.4 | C29: =SUM(Data_Q1!$C$80:$C$91)+SUM(F20:F23) -> 9410740.5 | D29: =C29-B29 -> 210777.07
A30: EBITDA | B30: =B28-B29 -> 2326594.8 | C30: =C28-C29 -> 1656052.4 | D30: =C30-B30 -> -670542.41
A32: EBITDA bridge: budget to reforecast
A33: Q1: actual against budget | B33: =(SUMIFS(Build!$Q$5:$Q$292,Build!$A$5:$A$292,"<=3")-SUMIFS(Build!$R$5:$R$292,Build!$A$5:$A$292,"<=3")-SUMIFS(Build!$S$5:$S$292,Build!$A$5:$A$292,"<=3")-SUM(C20:C23))-(SUMIFS(Build!$K$5:$K$292,Build!$A$5:$A$292,"<=3")-SUMIFS(Build!$M$5:$M$292,Build!$A$5:$A$292,"<=3")-SUMIFS(Build!$O$5:$O$292,Build!$A$5:$A$292,"<=3")-SUM(B20:B23)) -> -155469.52
A34: Apr-Dec: volume, at budget margin per case | B34: =SUMPRODUCT((Build!$A$5:$A$292>3)*(Build!$P$5:$P$292-Build!$F$5:$F$292)*(Build!$G$5:$G$292*(1+Build!$H$5:$H$292)*(1+Build!$I$5:$I$292)-Build!$L$5:$L$292-Build!$N$5:$N$292)) -> -75048.644
A35: Apr-Dec: unit cost | B35: =-SUMPRODUCT((Build!$A$5:$A$292>3)*(Build!$R$5:$R$292-Build!$P$5:$P$292*Build!$L$5:$L$292)) -> -280993.37
A36: Apr-Dec: opex run-rate | B36: =-(SUM(F20:F23)-SUM(E20:E23)) -> -159030.88
A37: Budget to reforecast, total | B37: =SUM(B33:B36) -> -670542.41

Sheet Build
A1: Build: segment x month, every version
A2: 24 category x channel segments x 12 months. V1 and V2 share volumes and costs; V2 adds the challenge-round price. Columns P:S are the 3+9 reforecast.
A4: Month | B4: Segment | C4: Category | D4: Channel | E4: Season share | F4: Cases | G4: Base price / case | H4: V1 price uplift | I4: V2 extra price | J4: Revenue V1 | K4: Revenue V2 | L4: Cost / case | M4: COGS | N4: Freight / case | O4: Freight | P4: RF cases | Q4: RF revenue | R4: RF COGS | S4: RF freight
A5: =MOD(ROW()-5,12)+1 -> 1 | B5: =INT((ROW()-5)/12)+1 -> 1 | C5: =INDEX(Data_Base!$A$5:$A$28,B5) -> Beef | D5: =INDEX(Data_Base!$B$5:$B$28,B5) -> Restaurants | E5: =INDEX(Data_Base!$B$32:$M$37,MATCH(C5,Data_Base!$A$32:$A$37,0),A5) -> 0.071097 | F5: =INDEX(Data_Base!$C$5:$C$28,B5)*(1+INDEX(Assumptions!$B$19:$B$22,MATCH(D5,Assumptions!$A$19:$A$22,0)))*E5 -> 2199.4995 | G5: =INDEX(Data_Base!$D$5:$D$28,B5)/INDEX(Data_Base!$C$5:$C$28,B5) -> 196.05735 | H5: =IF(A5>=Assumptions!$C$37,INDEX(Assumptions!$B$10:$B$15,MATCH(C5,Assumptions!$A$10:$A$15,0)),0) -> 0 | I5: =IF(AND(A5>=Assumptions!$C$37,INDEX(Assumptions!$C$19:$C$22,MATCH(D5,Assumptions!$A$19:$A$22,0))=1),INDEX(Assumptions!$D$10:$D$15,MATCH(C5,Assumptions!$A$10:$A$15,0)),0) -> 0 | J5: =F5*G5*(1+H5) -> 431228.04 | K5: =J5*(1+I5) -> 431228.04 | L5: =INDEX(Data_Base!$E$5:$E$28,B5)/INDEX(Data_Base!$C$5:$C$28,B5)*(1+INDEX(Assumptions!$C$10:$C$15,MATCH(C5,Assumptions!$A$10:$A$15,0))) -> 158.57735 | M5: =F5*L5 -> 348790.79 | N5: =INDEX(Data_Base!$F$5:$F$28,B5)/INDEX(Data_Base!$C$5:$C$28,B5)*(1+Assumptions!$C$38) -> 2.7235008 | O5: =F5*N5 -> 5990.3384 | P5: =IF(A5<=3,SUMIFS(Data_Q1!$D$5:$D$76,Data_Q1!$A$5:$A$76,A5,Data_Q1!$B$5:$B$76,C5,Data_Q1!$C$5:$C$76,D5),F5*INDEX(Reforecast!$D$6:$D$9,MATCH(D5,Reforecast!$A$6:$A$9,0))) -> 2113.9 | Q5: =IF(A5<=3,SUMIFS(Data_Q1!$E$5:$E$76,Data_Q1!$A$5:$A$76,A5,Data_Q1!$B$5:$B$76,C5,Data_Q1!$C$5:$C$76,D5),P5*G5*(1+H5)*(1+I5)) -> 414351.28 | R5: =IF(A5<=3,SUMIFS(Data_Q1!$F$5:$F$76,Data_Q1!$A$5:$A$76,A5,Data_Q1!$B$5:$B$76,C5,Data_Q1!$C$5:$C$76,D5),P5*L5*INDEX(Reforecast!$D$12:$D$17,MATCH(C5,Reforecast!$A$12:$A$17,0))) -> 343878.6 | S5: =IF(A5<=3,SUMIFS(Data_Q1!$G$5:$G$76,Data_Q1!$A$5:$A$76,A5,Data_Q1!$B$5:$B$76,C5,Data_Q1!$C$5:$C$76,D5),P5*N5) -> 5757.1
A6: =MOD(ROW()-5,12)+1 -> 2 | B6: =INT((ROW()-5)/12)+1 -> 1 | C6: =INDEX(Data_Base!$A$5:$A$28,B6) -> Beef | D6: =INDEX(Data_Base!$B$5:$B$28,B6) -> Restaurants | E6: =INDEX(Data_Base!$B$32:$M$37,MATCH(C6,Data_Base!$A$32:$A$37,0),A6) -> 0.071356 | F6: =INDEX(Data_Base!$C$5:$C$28,B6)*(1+INDEX(Assumptions!$B$19:$B$22,MATCH(D6,Assumptions!$A$19:$A$22,0)))*E6 -> 2207.512 | G6: =INDEX(Data_Base!$D$5:$D$28,B6)/INDEX(Data_Base!$C$5:$C$28,B6) -> 196.05735 | H6: =IF(A6>=Assumptions!$C$37,INDEX(Assumptions!$B$10:$B$15,MATCH(C6,Assumptions!$A$10:$A$15,0)),0) -> 0.04 | I6: =IF(AND(A6>=Assumptions!$C$37,INDEX(Assumptions!$C$19:$C$22,MATCH(D6,Assumptions!$A$19:$A$22,0))=1),INDEX(Assumptions!$D$10:$D$15,MATCH(C6,Assumptions!$A$10:$A$15,0)),0) -> 0.015 | J6: =F6*G6*(1+H6) -> 450110.92 | K6: =J6*(1+I6) -> 456862.59 | L6: =INDEX(Data_Base!$E$5:$E$28,B6)/INDEX(Data_Base!$C$5:$C$28,B6)*(1+INDEX(Assumptions!$C$10:$C$15,MATCH(C6,Assumptions!$A$10:$A$15,0))) -> 158.57735 | M6: =F6*L6 -> 350061.4 | N6: =INDEX(Data_Base!$F$5:$F$28,B6)/INDEX(Data_Base!$C$5:$C$28,B6)*(1+Assumptions!$C$38) -> 2.7235008 | O6: =F6*N6 -> 6012.1607 | P6: =IF(A6<=3,SUMIFS(Data_Q1!$D$5:$D$76,Data_Q1!$A$5:$A$76,A6,Data_Q1!$B$5:$B$76,C6,Data_Q1!$C$5:$C$76,D6),F6*INDEX(Reforecast!$D$6:$D$9,MATCH(D6,Reforecast!$A$6:$A$9,0))) -> 2073.6 | Q6: =IF(A6<=3,SUMIFS(Data_Q1!$E$5:$E$76,Data_Q1!$A$5:$A$76,A6,Data_Q1!$B$5:$B$76,C6,Data_Q1!$C$5:$C$76,D6),P6*G6*(1+H6)*(1+I6)) -> 430449.14 | R6: =IF(A6<=3,SUMIFS(Data_Q1!$F$5:$F$76,Data_Q1!$A$5:$A$76,A6,Data_Q1!$B$5:$B$76,C6,Data_Q1!$C$5:$C$76,D6),P6*L6*INDEX(Reforecast!$D$12:$D$17,MATCH(C6,Reforecast!$A$12:$A$17,0))) -> 337875.04 | S6: =IF(A6<=3,SUMIFS(Data_Q1!$G$5:$G$76,Data_Q1!$A$5:$A$76,A6,Data_Q1!$B$5:$B$76,C6,Data_Q1!$C$5:$C$76,D6),P6*N6) -> 5647.46
A7: =MOD(ROW()-5,12)+1 -> 3 | B7: =INT((ROW()-5)/12)+1 -> 1 | C7: =INDEX(Data_Base!$A$5:$A$28,B7) -> Beef | D7: =INDEX(Data_Base!$B$5:$B$28,B7) -> Restaurants | E7: =INDEX(Data_Base!$B$32:$M$37,MATCH(C7,Data_Base!$A$32:$A$37,0),A7) -> 0.076229 | F7: =INDEX(Data_Base!$C$5:$C$28,B7)*(1+INDEX(Assumptions!$B$19:$B$22,MATCH(D7,Assumptions!$A$19:$A$22,0)))*E7 -> 2358.2661 | G7: =INDEX(Data_Base!$D$5:$D$28,B7)/INDEX(Data_Base!$C$5:$C$28,B7) -> 196.05735 | H7: =IF(A7>=Assumptions!$C$37,INDEX(Assumptions!$B$10:$B$15,MATCH(C7,Assumptions!$A$10:$A$15,0)),0) -> 0.04 | I7: =IF(AND(A7>=Assumptions!$C$37,INDEX(Assumptions!$C$19:$C$22,MATCH(D7,Assumptions!$A$19:$A$22,0))=1),INDEX(Assumptions!$D$10:$D$15,MATCH(C7,Assumptions!$A$10:$A$15,0)),0) -> 0.015 | J7: =F7*G7*(1+H7) -> 480849.62 | K7: =J7*(1+I7) -> 488062.36 | L7: =INDEX(Data_Base!$E$5:$E$28,B7)/INDEX(Data_Base!$C$5:$C$28,B7)*(1+INDEX(Assumptions!$C$10:$C$15,MATCH(C7,Assumptions!$A$10:$A$15,0))) -> 158.57735 | M7: =F7*L7 -> 373967.58 | N7: =INDEX(Data_Base!$F$5:$F$28,B7)/INDEX(Data_Base!$C$5:$C$28,B7)*(1+Assumptions!$C$38) -> 2.7235008 | O7: =F7*N7 -> 6422.7395 | P7: =IF(A7<=3,SUMIFS(Data_Q1!$D$5:$D$76,Data_Q1!$A$5:$A$76,A7,Data_Q1!$B$5:$B$76,C7,Data_Q1!$C$5:$C$76,D7),F7*INDEX(Reforecast!$D$6:$D$9,MATCH(D7,Reforecast!$A$6:$A$9,0))) -> 2259.5 | Q7: =IF(A7<=3,SUMIFS(Data_Q1!$E$5:$E$76,Data_Q1!$A$5:$A$76,A7,Data_Q1!$B$5:$B$76,C7,Data_Q1!$C$5:$C$76,D7),P7*G7*(1+H7)*(1+I7)) -> 466595.31 | R7: =IF(A7<=3,SUMIFS(Data_Q1!$F$5:$F$76,Data_Q1!$A$5:$A$76,A7,Data_Q1!$B$5:$B$76,C7,Data_Q1!$C$5:$C$76,D7),P7*L7*INDEX(Reforecast!$D$12:$D$17,MATCH(C7,Reforecast!$A$12:$A$17,0))) -> 367982.65 | S7: =IF(A7<=3,SUMIFS(Data_Q1!$G$5:$G$76,Data_Q1!$A$5:$A$76,A7,Data_Q1!$B$5:$B$76,C7,Data_Q1!$C$5:$C$76,D7),P7*N7) -> 6153.82
A8: =MOD(ROW()-5,12)+1 -> 4 | B8: =INT((ROW()-5)/12)+1 -> 1 | C8: =INDEX(Data_Base!$A$5:$A$28,B8) -> Beef | D8: =INDEX(Data_Base!$B$5:$B$28,B8) -> Restaurants | E8: =INDEX(Data_Base!$B$32:$M$37,MATCH(C8,Data_Base!$A$32:$A$37,0),A8) -> 0.082956 | F8: =INDEX(Data_Base!$C$5:$C$28,B8)*(1+INDEX(Assumptions!$B$19:$B$22,MATCH(D8,Assumptions!$A$19:$A$22,0)))*E8 -> 2566.3766 | G8: =INDEX(Data_Base!$D$5:$D$28,B8)/INDEX(Data_Base!$C$5:$C$28,B8) -> 196.05735 | H8: =IF(A8>=Assumptions!$C$37,INDEX(Assumptions!$B$10:$B$15,MATCH(C8,Assumptions!$A$10:$A$15,0)),0) -> 0.04 | I8: =IF(AND(A8>=Assumptions!$C$37,INDEX(Assumptions!$C$19:$C$22,MATCH(D8,Assumptions!$A$19:$A$22,0))=1),INDEX(Assumptions!$D$10:$D$15,MATCH(C8,Assumptions!$A$10:$A$15,0)),0) -> 0.015 | J8: =F8*G8*(1+H8) -> 523283.28 | K8: =J8*(1+I8) -> 531132.53 | L8: =INDEX(Data_Base!$E$5:$E$28,B8)/INDEX(Data_Base!$C$5:$C$28,B8)*(1+INDEX(Assumptions!$C$10:$C$15,MATCH(C8,Assumptions!$A$10:$A$15,0))) -> 158.57735 | M8: =F8*L8 -> 406969.19 | N8: =INDEX(Data_Base!$F$5:$F$28,B8)/INDEX(Data_Base!$C$5:$C$28,B8)*(1+Assumptions!$C$38) -> 2.7235008 | O8: =F8*N8 -> 6989.5286 | P8: =IF(A8<=3,SUMIFS(Data_Q1!$D$5:$D$76,Data_Q1!$A$5:$A$76,A8,Data_Q1!$B$5:$B$76,C8,Data_Q1!$C$5:$C$76,D8),F8*INDEX(Reforecast!$D$6:$D$9,MATCH(D8,Reforecast!$A$6:$A$9,0))) -> 2458.6897 | Q8: =IF(A8<=3,SUMIFS(Data_Q1!$E$5:$E$76,Data_Q1!$A$5:$A$76,A8,Data_Q1!$B$5:$B$76,C8,Data_Q1!$C$5:$C$76,D8),P8*G8*(1+H8)*(1+I8)) -> 508845.84 | R8: =IF(A8<=3,SUMIFS(Data_Q1!$F$5:$F$76,Data_Q1!$A$5:$A$76,A8,Data_Q1!$B$5:$B$76,C8,Data_Q1!$C$5:$C$76,D8),P8*L8*INDEX(Reforecast!$D$12:$D$17,MATCH(C8,Reforecast!$A$12:$A$17,0))) -> 400625.84 | S8: =IF(A8<=3,SUMIFS(Data_Q1!$G$5:$G$76,Data_Q1!$A$5:$A$76,A8,Data_Q1!$B$5:$B$76,C8,Data_Q1!$C$5:$C$76,D8),P8*N8) -> 6696.2432
A9: =MOD(ROW()-5,12)+1 -> 5 | B9: =INT((ROW()-5)/12)+1 -> 1 | C9: =INDEX(Data_Base!$A$5:$A$28,B9) -> Beef | D9: =INDEX(Data_Base!$B$5:$B$28,B9) -> Restaurants | E9: =INDEX(Data_Base!$B$32:$M$37,MATCH(C9,Data_Base!$A$32:$A$37,0),A9) -> 0.090704 | F9: =INDEX(Data_Base!$C$5:$C$28,B9)*(1+INDEX(Assumptions!$B$19:$B$22,MATCH(D9,Assumptions!$A$19:$A$22,0)))*E9 -> 2806.0734 | G9: =INDEX(Data_Base!$D$5:$D$28,B9)/INDEX(Data_Base!$C$5:$C$28,B9) -> 196.05735 | H9: =IF(A9>=Assumptions!$C$37,INDEX(Assumptions!$B$10:$B$15,MATCH(C9,Assumptions!$A$10:$A$15,0)),0) -> 0.04 | I9: =IF(AND(A9>=Assumptions!$C$37,INDEX(Assumptions!$C$19:$C$22,MATCH(D9,Assumptions!$A$19:$A$22,0))=1),INDEX(Assumptions!$D$10:$D$15,MATCH(C9,Assumptions!$A$10:$A$15,0)),0) -> 0.015 | J9: =F9*G9*(1+H9) -> 572157.37 | K9: =J9*(1+I9) -> 580739.73 | L9: =INDEX(Data_Base!$E$5:$E$28,B9)/INDEX(Data_Base!$C$5:$C$28,B9)*(1+INDEX(Assumptions!$C$10:$C$15,MATCH(C9,Assumptions!$A$10:$A$15,0))) -> 158.57735 | M9: =F9*L9 -> 444979.67 | N9: =INDEX(Data_Base!$F$5:$F$28,B9)/INDEX(Data_Base!$C$5:$C$28,B9)*(1+Assumptions!$C$38) -> 2.7235008 | O9: =F9*N9 -> 7642.343 | P9: =IF(A9<=3,SUMIFS(Data_Q1!$D$5:$D$76,Data_Q1!$A$5:$A$76,A9,Data_Q1!$B$5:$B$76,C9,Data_Q1!$C$5:$C$76,D9),F9*INDEX(Reforecast!$D$6:$D$9,MATCH(D9,Reforecast!$A$6:$A$9,0))) -> 2688.3286 | Q9: =IF(A9<=3,SUMIFS(Data_Q1!$E$5:$E$76,Data_Q1!$A$5:$A$76,A9,Data_Q1!$B$5:$B$76,C9,Data_Q1!$C$5:$C$76,D9),P9*G9*(1+H9)*(1+I9)) -> 556371.49 | R9: =IF(A9<=3,SUMIFS(Data_Q1!$F$5:$F$76,Data_Q1!$A$5:$A$76,A9,Data_Q1!$B$5:$B$76,C9,Data_Q1!$C$5:$C$76,D9),P9*L9*INDEX(Reforecast!$D$12:$D$17,MATCH(C9,Reforecast!$A$12:$A$17,0))) -> 438043.86 | S9: =IF(A9<=3,SUMIFS(Data_Q1!$G$5:$G$76,Data_Q1!$A$5:$A$76,A9,Data_Q1!$B$5:$B$76,C9,Data_Q1!$C$5:$C$76,D9),P9*N9) -> 7321.665
A10: =MOD(ROW()-5,12)+1 -> 6 | B10: =INT((ROW()-5)/12)+1 -> 1 | C10: =INDEX(Data_Base!$A$5:$A$28,B10) -> Beef | D10: =INDEX(Data_Base!$B$5:$B$28,B10) -> Restaurants | E10: =INDEX(Data_Base!$B$32:$M$37,MATCH(C10,Data_Base!$A$32:$A$37,0),A10) -> 0.098481 | F10: =INDEX(Data_Base!$C$5:$C$28,B10)*(1+INDEX(Assumptions!$B$19:$B$22,MATCH(D10,Assumptions!$A$19:$A$22,0)))*E10 -> 3046.6673 | G10: =INDEX(Data_Base!$D$5:$D$28,B10)/INDEX(Data_Base!$C$5:$C$28,B10) -> 196.05735 | H10: =IF(A10>=Assumptions!$C$37,INDEX(Assumptions!$B$10:$B$15,MATCH(C10,Assumptions!$A$10:$A$15,0)),0) -> 0.04 | I10: =IF(AND(A10>=Assumptions!$C$37,INDEX(Assumptions!$C$19:$C$22,MATCH(D10,Assumptions!$A$19:$A$22,0))=1),INDEX(Assumptions!$D$10:$D$15,MATCH(C10,Assumptions!$A$10:$A$15,0)),0) -> 0.015 | J10: =F10*G10*(1+H10) -> 621214.39 | K10: =J10*(1+I10) -> 630532.6 | L10: =INDEX(Data_Base!$E$5:$E$28,B10)/INDEX(Data_Base!$C$5:$C$28,B10)*(1+INDEX(Assumptions!$C$10:$C$15,MATCH(C10,Assumptions!$A$10:$A$15,0))) -> 158.57735 | M10: =F10*L10 -> 483132.42 | N10: =INDEX(Data_Base!$F$5:$F$28,B10)/INDEX(Data_Base!$C$5:$C$28,B10)*(1+Assumptions!$C$38) -> 2.7235008 | O10: =F10*N10 -> 8297.6008 | P10: =IF(A10<=3,SUMIFS(Data_Q1!$D$5:$D$76,Data_Q1!$A$5:$A$76,A10,Data_Q1!$B$5:$B$76,C10,Data_Q1!$C$5:$C$76,D10),F10*INDEX(Reforecast!$D$6:$D$9,MATCH(D10,Reforecast!$A$6:$A$9,0))) -> 2918.827 | Q10: =IF(A10<=3,SUMIFS(Data_Q1!$E$5:$E$76,Data_Q1!$A$5:$A$76,A10,Data_Q1!$B$5:$B$76,C10,Data_Q1!$C$5:$C$76,D10),P10*G10*(1+H10)*(1+I10)) -> 604075.02 | R10: =IF(A10<=3,SUMIFS(Data_Q1!$F$5:$F$76,Data_Q1!$A$5:$A$76,A10,Data_Q1!$B$5:$B$76,C10,Data_Q1!$C$5:$C$76,D10),P10*L10*INDEX(Reforecast!$D$12:$D$17,MATCH(C10,Reforecast!$A$12:$A$17,0))) -> 475601.93 | S10: =IF(A10<=3,SUMIFS(Data_Q1!$G$5:$G$76,Data_Q1!$A$5:$A$76,A10,Data_Q1!$B$5:$B$76,C10,Data_Q1!$C$5:$C$76,D10),P10*N10) -> 7949.4277
A11: =MOD(ROW()-5,12)+1 -> 7 | B11: =INT((ROW()-5)/12)+1 -> 1 | C11: =INDEX(Data_Base!$A$5:$A$28,B11) -> Beef | D11: =INDEX(Data_Base!$B$5:$B$28,B11) -> Restaurants | E11: =INDEX(Data_Base!$B$32:$M$37,MATCH(C11,Data_Base!$A$32:$A$37,0),A11) -> 0.098998 | F11: =INDEX(Data_Base!$C$5:$C$28,B11)*(1+INDEX(Assumptions!$B$19:$B$22,MATCH(D11,Assumptions!$A$19:$A$22,0)))*E11 -> 3062.6615 | G11: =INDEX(Data_Base!$D$5:$D$28,B11)/INDEX(Data_Base!$C$5:$C$28,B11) -> 196.05735 | H11: =IF(A11>=Assumptions!$C$37,INDEX(Assumptions!$B$10:$B$15,MATCH(C11,Assumptions!$A$10:$A$15,0)),0) -> 0.04 | I11: =IF(AND(A11>=Assumptions!$C$37,INDEX(Assumptions!$C$19:$C$22,MATCH(D11,Assumptions!$A$19:$A$22,0))=1),INDEX(Assumptions!$D$10:$D$15,MATCH(C11,Assumptions!$A$10:$A$15,0)),0) -> 0.015 | J11: =F11*G11*(1+H11) -> 624475.6 | K11: =J11*(1+I11) -> 633842.74 | L11: =INDEX(Data_Base!$E$5:$E$28,B11)/INDEX(Data_Base!$C$5:$C$28,B11)*(1+INDEX(Assumptions!$C$10:$C$15,MATCH(C11,Assumptions!$A$10:$A$15,0))) -> 158.57735 | M11: =F11*L11 -> 485668.74 | N11: =INDEX(Data_Base!$F$5:$F$28,B11)/INDEX(Data_Base!$C$5:$C$28,B11)*(1+Assumptions!$C$38) -> 2.7235008 | O11: =F11*N11 -> 8341.161 | P11: =IF(A11<=3,SUMIFS(Data_Q1!$D$5:$D$76,Data_Q1!$A$5:$A$76,A11,Data_Q1!$B$5:$B$76,C11,Data_Q1!$C$5:$C$76,D11),F11*INDEX(Reforecast!$D$6:$D$9,MATCH(D11,Reforecast!$A$6:$A$9,0))) -> 2934.1501 | Q11: =IF(A11<=3,SUMIFS(Data_Q1!$E$5:$E$76,Data_Q1!$A$5:$A$76,A11,Data_Q1!$B$5:$B$76,C11,Data_Q1!$C$5:$C$76,D11),P11*G11*(1+H11)*(1+I11)) -> 607246.26 | R11: =IF(A11<=3,SUMIFS(Data_Q1!$F$5:$F$76,Data_Q1!$A$5:$A$76,A11,Data_Q1!$B$5:$B$76,C11,Data_Q1!$C$5:$C$76,D11),P11*L11*INDEX(Reforecast!$D$12:$D$17,MATCH(C11,Reforecast!$A$12:$A$17,0))) -> 478098.72 | S11: =IF(A11<=3,SUMIFS(Data_Q1!$G$5:$G$76,Data_Q1!$A$5:$A$76,A11,Data_Q1!$B$5:$B$76,C11,Data_Q1!$C$5:$C$76,D11),P11*N11) -> 7991.1601
A12: =MOD(ROW()-5,12)+1 -> 8 | B12: =INT((ROW()-5)/12)+1 -> 1 | C12: =INDEX(Data_Base!$A$5:$A$28,B12) -> Beef | D12: =INDEX(Data_Base!$B$5:$B$28,B12) -> Restaurants | E12: =INDEX(Data_Base!$B$32:$M$37,MATCH(C12,Data_Base!$A$32:$A$37,0),A12) -> 0.095376 | F12: =INDEX(Data_Base!$C$5:$C$28,B12)*(1+INDEX(Assumptions!$B$19:$B$22,MATCH(D12,Assumptions!$A$19:$A$22,0)))*E12 -> 2950.6092 | G12: =INDEX(Data_Base!$D$5:$D$28,B12)/INDEX(Data_Base!$C$5:$C$28,B12) -> 196.05735 | H12: =IF(A12>=Assumptions!$C$37,INDEX(Assumptions!$B$10:$B$15,MATCH(C12,Assumptions!$A$10:$A$15,0)),0) -> 0.04 | I12: =IF(AND(A12>=Assumptions!$C$37,INDEX(Assumptions!$C$19:$C$22,MATCH(D12,Assumptions!$A$19:$A$22,0))=1),INDEX(Assumptions!$D$10:$D$15,MATCH(C12,Assumptions!$A$10:$A$15,0)),0) -> 0.015 | J12: =F12*G12*(1+H12) -> 601628.17 | K12: =J12*(1+I12) -> 610652.59 | L12: =INDEX(Data_Base!$E$5:$E$28,B12)/INDEX(Data_Base!$C$5:$C$28,B12)*(1+INDEX(Assumptions!$C$10:$C$15,MATCH(C12,Assumptions!$A$10:$A$15,0))) -> 158.57735 | M12: =F12*L12 -> 467899.77 | N12: =INDEX(Data_Base!$F$5:$F$28,B12)/INDEX(Data_Base!$C$5:$C$28,B12)*(1+Assumptions!$C$38) -> 2.7235008 | O12: =F12*N12 -> 8035.9863 | P12: =IF(A12<=3,SUMIFS(Data_Q1!$D$5:$D$76,Data_Q1!$A$5:$A$76,A12,Data_Q1!$B$5:$B$76,C12,Data_Q1!$C$5:$C$76,D12),F12*INDEX(Reforecast!$D$6:$D$9,MATCH(D12,Reforecast!$A$6:$A$9,0))) -> 2826.7996 | Q12: =IF(A12<=3,SUMIFS(Data_Q1!$E$5:$E$76,Data_Q1!$A$5:$A$76,A12,Data_Q1!$B$5:$B$76,C12,Data_Q1!$C$5:$C$76,D12),P12*G12*(1+H12)*(1+I12)) -> 585029.18 | R12: =IF(A12<=3,SUMIFS(Data_Q1!$F$5:$F$76,Data_Q1!$A$5:$A$76,A12,Data_Q1!$B$5:$B$76,C12,Data_Q1!$C$5:$C$76,D12),P12*L12*INDEX(Reforecast!$D$12:$D$17,MATCH(C12,Reforecast!$A$12:$A$17,0))) -> 460606.71 | S12: =IF(A12<=3,SUMIFS(Data_Q1!$G$5:$G$76,Data_Q1!$A$5:$A$76,A12,Data_Q1!$B$5:$B$76,C12,Data_Q1!$C$5:$C$76,D12),P12*N12) -> 7698.7908
A13: =MOD(ROW()-5,12)+1 -> 9 | B13: =INT((ROW()-5)/12)+1 -> 1 | C13: =INDEX(Data_Base!$A$5:$A$28,B13) -> Beef | D13: =INDEX(Data_Base!$B$5:$B$28,B13) -> Restaurants | E13: =INDEX(Data_Base!$B$32:$M$37,MATCH(C13,Data_Base!$A$32:$A$37,0),A13) -> 0.08195 | F13: =INDEX(Data_Base!$C$5:$C$28,B13)*(1+INDEX(Assumptions!$B$19:$B$22,MATCH(D13,Assumptions!$A$19:$A$22,0)))*E13 -> 2535.2544 | G13: =INDEX(Data_Base!$D$5:$D$28,B13)/INDEX(Data_Base!$C$5:$C$28,B13) -> 196.05735 | H13: =IF(A13>=Assumptions!$C$37,INDEX(Assumptions!$B$10:$B$15,MATCH(C13,Assumptions!$A$10:$A$15,0)),0) -> 0.04 | I13: =IF(AND(A13>=Assumptions!$C$37,INDEX(Assumptions!$C$19:$C$22,MATCH(D13,Assumptions!$A$19:$A$22,0))=1),INDEX(Assumptions!$D$10:$D$15,MATCH(C13,Assumptions!$A$10:$A$15,0)),0) -> 0.015 | J13: =F13*G13*(1+H13) -> 516937.47 | K13: =J13*(1+I13) -> 524691.53 | L13: =INDEX(Data_Base!$E$5:$E$28,B13)/INDEX(Data_Base!$C$5:$C$28,B13)*(1+INDEX(Assumptions!$C$10:$C$15,MATCH(C13,Assumptions!$A$10:$A$15,0))) -> 158.57735 | M13: =F13*L13 -> 402033.91 | N13: =INDEX(Data_Base!$F$5:$F$28,B13)/INDEX(Data_Base!$C$5:$C$28,B13)*(1+Assumptions!$C$38) -> 2.7235008 | O13: =F13*N13 -> 6904.7672 | P13: =IF(A13<=3,SUMIFS(Data_Q1!$D$5:$D$76,Data_Q1!$A$5:$A$76,A13,Data_Q1!$B$5:$B$76,C13,Data_Q1!$C$5:$C$76,D13),F13*INDEX(Reforecast!$D$6:$D$9,MATCH(D13,Reforecast!$A$6:$A$9,0))) -> 2428.8733 | Q13: =IF(A13<=3,SUMIFS(Data_Q1!$E$5:$E$76,Data_Q1!$A$5:$A$76,A13,Data_Q1!$B$5:$B$76,C13,Data_Q1!$C$5:$C$76,D13),P13*G13*(1+H13)*(1+I13)) -> 502675.11 | R13: =IF(A13<=3,SUMIFS(Data_Q1!$F$5:$F$76,Data_Q1!$A$5:$A$76,A13,Data_Q1!$B$5:$B$76,C13,Data_Q1!$C$5:$C$76,D13),P13*L13*INDEX(Reforecast!$D$12:$D$17,MATCH(C13,Reforecast!$A$12:$A$17,0))) -> 395767.49 | S13: =IF(A13<=3,SUMIFS(Data_Q1!$G$5:$G$76,Data_Q1!$A$5:$A$76,A13,Data_Q1!$B$5:$B$76,C13,Data_Q1!$C$5:$C$76,D13),P13*N13) -> 6615.0384
A14: =MOD(ROW()-5,12)+1 -> 10 | B14: =INT((ROW()-5)/12)+1 -> 1 | C14: =INDEX(Data_Base!$A$5:$A$28,B14) -> Beef | D14: =INDEX(Data_Base!$B$5:$B$28,B14) -> Restaurants | E14: =INDEX(Data_Base!$B$32:$M$37,MATCH(C14,Data_Base!$A$32:$A$37,0),A14) -> 0.079492 | F14: =INDEX(Data_Base!$C$5:$C$28,B14)*(1+INDEX(Assumptions!$B$19:$B$22,MATCH(D14,Assumptions!$A$19:$A$22,0)))*E14 -> 2459.2122 | G14: =INDEX(Data_Base!$D$5:$D$28,B14)/INDEX(Data_Base!$C$5:$C$28,B14) -> 196.05735 | H14: =IF(A14>=Assumptions!$C$37,INDEX(Assumptions!$B$10:$B$15,MATCH(C14,Assumptions!$A$10:$A$15,0)),0) -> 0.04 | I14: =IF(AND(A14>=Assumptions!$C$37,INDEX(Assumptions!$C$19:$C$22,MATCH(D14,Assumptions!$A$19:$A$22,0))=1),INDEX(Assumptions!$D$10:$D$15,MATCH(C14,Assumptions!$A$10:$A$15,0)),0) -> 0.015 | J14: =F14*G14*(1+H14) -> 501432.5 | K14: =J14*(1+I14) -> 508953.99 | L14: =INDEX(Data_Base!$E$5:$E$28,B14)/INDEX(Data_Base!$C$5:$C$28,B14)*(1+INDEX(Assumptions!$C$10:$C$15,MATCH(C14,Assumptions!$A$10:$A$15,0))) -> 158.57735 | M14: =F14*L14 -> 389975.35 | N14: =INDEX(Data_Base!$F$5:$F$28,B14)/INDEX(Data_Base!$C$5:$C$28,B14)*(1+Assumptions!$C$38) -> 2.7235008 | O14: =F14*N14 -> 6697.6663 | P14: =IF(A14<=3,SUMIFS(Data_Q1!$D$5:$D$76,Data_Q1!$A$5:$A$76,A14,Data_Q1!$B$5:$B$76,C14,Data_Q1!$C$5:$C$76,D14),F14*INDEX(Reforecast!$D$6:$D$9,MATCH(D14,Reforecast!$A$6:$A$9,0))) -> 2356.022 | Q14: =IF(A14<=3,SUMIFS(Data_Q1!$E$5:$E$76,Data_Q1!$A$5:$A$76,A14,Data_Q1!$B$5:$B$76,C14,Data_Q1!$C$5:$C$76,D14),P14*G14*(1+H14)*(1+I14)) -> 487597.93 | R14: =IF(A14<=3,SUMIFS(Data_Q1!$F$5:$F$76,Data_Q1!$A$5:$A$76,A14,Data_Q1!$B$5:$B$76,C14,Data_Q1!$C$5:$C$76,D14),P14*L14*INDEX(Reforecast!$D$12:$D$17,MATCH(C14,Reforecast!$A$12:$A$17,0))) -> 383896.88 | S14: =IF(A14<=3,SUMIFS(Data_Q1!$G$5:$G$76,Data_Q1!$A$5:$A$76,A14,Data_Q1!$B$5:$B$76,C14,Data_Q1!$C$5:$C$76,D14),P14*N14) -> 6416.6276
A15: =MOD(ROW()-5,12)+1 -> 11 | B15: =INT((ROW()-5)/12)+1 -> 1 | C15: =INDEX(Data_Base!$A$5:$A$28,B15) -> Beef | D15: =INDEX(Data_Base!$B$5:$B$28,B15) -> Restaurants | E15: =INDEX(Data_Base!$B$32:$M$37,MATCH(C15,Data_Base!$A$32:$A$37,0),A15) -> 0.075165 | F15: =INDEX(Data_Base!$C$5:$C$28,B15)*(1+INDEX(Assumptions!$B$19:$B$22,MATCH(D15,Assumptions!$A$19:$A$22,0)))*E15 -> 2325.3495 | G15: =INDEX(Data_Base!$D$5:$D$28,B15)/INDEX(Data_Base!$C$5:$C$28,B15) -> 196.05735 | H15: =IF(A15>=Assumptions!$C$37,INDEX(Assumptions!$B$10:$B$15,MATCH(C15,Assumptions!$A$10:$A$15,0)),0) -> 0.04 | I15: =IF(AND(A15>=Assumptions!$C$37,INDEX(Assumptions!$C$19:$C$22,MATCH(D15,Assumptions!$A$19:$A$22,0))=1),INDEX(Assumptions!$D$10:$D$15,MATCH(C15,Assumptions!$A$10:$A$15,0)),0) -> 0.015 | J15: =F15*G15*(1+H15) -> 474137.95 | K15: =J15*(1+I15) -> 481250.02 | L15: =INDEX(Data_Base!$E$5:$E$28,B15)/INDEX(Data_Base!$C$5:$C$28,B15)*(1+INDEX(Assumptions!$C$10:$C$15,MATCH(C15,Assumptions!$A$10:$A$15,0))) -> 158.57735 | M15: =F15*L15 -> 368747.76 | N15: =INDEX(Data_Base!$F$5:$F$28,B15)/INDEX(Data_Base!$C$5:$C$28,B15)*(1+Assumptions!$C$38) -> 2.7235008 | O15: =F15*N15 -> 6333.0913 | P15: =IF(A15<=3,SUMIFS(Data_Q1!$D$5:$D$76,Data_Q1!$A$5:$A$76,A15,Data_Q1!$B$5:$B$76,C15,Data_Q1!$C$5:$C$76,D15),F15*INDEX(Reforecast!$D$6:$D$9,MATCH(D15,Reforecast!$A$6:$A$9,0))) -> 2227.7763 | Q15: =IF(A15<=3,SUMIFS(Data_Q1!$E$5:$E$76,Data_Q1!$A$5:$A$76,A15,Data_Q1!$B$5:$B$76,C15,Data_Q1!$C$5:$C$76,D15),P15*G15*(1+H15)*(1+I15)) -> 461056.43 | R15: =IF(A15<=3,SUMIFS(Data_Q1!$F$5:$F$76,Data_Q1!$A$5:$A$76,A15,Data_Q1!$B$5:$B$76,C15,Data_Q1!$C$5:$C$76,D15),P15*L15*INDEX(Reforecast!$D$12:$D$17,MATCH(C15,Reforecast!$A$12:$A$17,0))) -> 363000.16 | S15: =IF(A15<=3,SUMIFS(Data_Q1!$G$5:$G$76,Data_Q1!$A$5:$A$76,A15,Data_Q1!$B$5:$B$76,C15,Data_Q1!$C$5:$C$76,D15),P15*N15) -> 6067.3504
A16: =MOD(ROW()-5,12)+1 -> 12 | B16: =INT((ROW()-5)/12)+1 -> 1 | C16: =INDEX(Data_Base!$A$5:$A$28,B16) -> Beef | D16: =INDEX(Data_Base!$B$5:$B$28,B16) -> Restaurants | E16: =INDEX(Data_Base!$B$32:$M$37,MATCH(C16,Data_Base!$A$32:$A$37,0),A16) -> 0.078196 | F16: =INDEX(Data_Base!$C$5:$C$28,B16)*(1+INDEX(Assumptions!$B$19:$B$22,MATCH(D16,Assumptions!$A$19:$A$22,0)))*E16 -> 2419.1184 | G16: =INDEX(Data_Base!$D$5:$D$28,B16)/INDEX(Data_Base!$C$5:$C$28,B16) -> 196.05735 | H16: =IF(A16>=Assumptions!$C$37,INDEX(Assumptions!$B$10:$B$15,MATCH(C16,Assumptions!$A$10:$A$15,0)),0) -> 0.04 | I16: =IF(AND(A16>=Assumptions!$C$37,INDEX(Assumptions!$C$19:$C$22,MATCH(D16,Assumptions!$A$19:$A$22,0))=1),INDEX(Assumptions!$D$10:$D$15,MATCH(C16,Assumptions!$A$10:$A$15,0)),0) -> 0.015 | J16: =F16*G16*(1+H16) -> 493257.38 | K16: =J16*(1+I16) -> 500656.24 | L16: =INDEX(Data_Base!$E$5:$E$28,B16)/INDEX(Data_Base!$C$5:$C$28,B16)*(1+INDEX(Assumptions!$C$10:$C$15,MATCH(C16,Assumptions!$A$10:$A$15,0))) -> 158.57735 | M16: =F16*L16 -> 383617.37 | N16: =INDEX(Data_Base!$F$5:$F$28,B16)/INDEX(Data_Base!$C$5:$C$28,B16)*(1+Assumptions!$C$38) -> 2.7235008 | O16: =F16*N16 -> 6588.4708 | P16: =IF(A16<=3,SUMIFS(Data_Q1!$D$5:$D$76,Data_Q1!$A$5:$A$76,A16,Data_Q1!$B$5:$B$76,C16,Data_Q1!$C$5:$C$76,D16),F16*INDEX(Reforecast!$D$6:$D$9,MATCH(D16,Reforecast!$A$6:$A$9,0))) -> 2317.6105 | Q16: =IF(A16<=3,SUMIFS(Data_Q1!$E$5:$E$76,Data_Q1!$A$5:$A$76,A16,Data_Q1!$B$5:$B$76,C16,Data_Q1!$C$5:$C$76,D16),P16*G16*(1+H16)*(1+I16)) -> 479648.36 | R16: =IF(A16<=3,SUMIFS(Data_Q1!$F$5:$F$76,Data_Q1!$A$5:$A$76,A16,Data_Q1!$B$5:$B$76,C16,Data_Q1!$C$5:$C$76,D16),P16*L16*INDEX(Reforecast!$D$12:$D$17,MATCH(C16,Reforecast!$A$12:$A$17,0))) -> 377638 | S16: =IF(A16<=3,SUMIFS(Data_Q1!$G$5:$G$76,Data_Q1!$A$5:$A$76,A16,Data_Q1!$B$5:$B$76,C16,Data_Q1!$C$5:$C$76,D16),P16*N16) -> 6312.014
... A292: =MOD(ROW()-5,12)+1 -> 12 | B292: =INT((ROW()-5)/12)+1 -> 24 | C292: =INDEX(Data_Base!$A$5:$A$28,B292) -> Cheese & Dairy | D292: =INDEX(Data_Base!$B$5:$B$28,B292) -> Online Direct | E292: =INDEX(Data_Base!$B$32:$M$37,MATCH(C292,Data_Base!$A$32:$A$37,0),A292) -> 0.10759 | F292: =INDEX(Data_Base!$C$5:$C$28,B292)*(1+INDEX(Assumptions!$B$19:$B$22,MATCH(D292,Assumptions!$A$19:$A$22,0)))*E292 -> 365.5069 | G292: =INDEX(Data_Base!$D$5:$D$28,B292)/INDEX(Data_Base!$C$5:$C$28,B292) -> 150.94383 | H292: =IF(A292>=Assumptions!$C$37,INDEX(Assumptions!$B$10:$B$15,MATCH(C292,Assumptions!$A$10:$A$15,0)),0) -> 0.015 | I292: =IF(AND(A292>=Assumptions!$C$37,INDEX(Assumptions!$C$19:$C$22,MATCH(D292,Assumptions!$A$19:$A$22,0))=1),INDEX(Assumptions!$D$10:$D$15,MATCH(C292,Assumptions!$A$10:$A$15,0)),0) -> 0 | J292: =F292*G292*(1+H292) -> 55998.577 | K292: =J292*(1+I292) -> 55998.577 | L292: =INDEX(Data_Base!$E$5:$E$28,B292)/INDEX(Data_Base!$C$5:$C$28,B292)*(1+INDEX(Assumptions!$C$10:$C$15,MATCH(C292,Assumptions!$A$10:$A$15,0))) -> 85.200961 | M292: =F292*L292 -> 31141.539 | N292: =INDEX(Data_Base!$F$5:$F$28,B292)/INDEX(Data_Base!$C$5:$C$28,B292)*(1+Assumptions!$C$38) -> 11.544679 | O292: =F292*N292 -> 4219.6599 | P292: =IF(A292<=3,SUMIFS(Data_Q1!$D$5:$D$76,Data_Q1!$A$5:$A$76,A292,Data_Q1!$B$5:$B$76,C292,Data_Q1!$C$5:$C$76,D292),F292*INDEX(Reforecast!$D$6:$D$9,MATCH(D292,Reforecast!$A$6:$A$9,0))) -> 366.36656 | Q292: =IF(A292<=3,SUMIFS(Data_Q1!$E$5:$E$76,Data_Q1!$A$5:$A$76,A292,Data_Q1!$B$5:$B$76,C292,Data_Q1!$C$5:$C$76,D292),P292*G292*(1+H292)*(1+I292)) -> 56130.284 | R292: =IF(A292<=3,SUMIFS(Data_Q1!$F$5:$F$76,Data_Q1!$A$5:$A$76,A292,Data_Q1!$B$5:$B$76,C292,Data_Q1!$C$5:$C$76,D292),P292*L292*INDEX(Reforecast!$D$12:$D$17,MATCH(C292,Reforecast!$A$12:$A$17,0))) -> 31288.882 | S292: =IF(A292<=3,SUMIFS(Data_Q1!$G$5:$G$76,Data_Q1!$A$5:$A$76,A292,Data_Q1!$B$5:$B$76,C292,Data_Q1!$C$5:$C$76,D292),P292*N292) -> 4229.5844

Sheet Opex
A1: Opex: department submissions by month
A2: Base = last twelve months / 12 x (1 + growth) [x (1 - cut) in V2], plus hires from their start month.
A5: V1 bottom-up | B5: Base / month | C5: =COLUMN()-2 -> 1 | D5: =COLUMN()-2 -> 2 | E5: =COLUMN()-2 -> 3 | F5: =COLUMN()-2 -> 4 | G5: =COLUMN()-2 -> 5 | H5: =COLUMN()-2 -> 6 | I5: =COLUMN()-2 -> 7 | J5: =COLUMN()-2 -> 8 | ... N5: =COLUMN()-2 -> 12 | O5: FY
A6: Sales & Marketing | B6: =INDEX(Data_Base!$B$41:$B$44,MATCH($A6,Data_Base!$A$41:$A$44,0))/12*(1+INDEX(Assumptions!$B$26:$B$29,MATCH($A6,Assumptions!$A$26:$A$29,0))) -> 207083.19 | C6: =$B6+SUMPRODUCT((Assumptions!$A$33:$A$34=$A6)*(Assumptions!$D$33:$D$34<=C$5)*Assumptions!$B$33:$B$34*Assumptions!$C$33:$C$34)/12 -> 207083.19 | D6: =$B6+SUMPRODUCT((Assumptions!$A$33:$A$34=$A6)*(Assumptions!$D$33:$D$34<=D$5)*Assumptions!$B$33:$B$34*Assumptions!$C$33:$C$34)/12 -> 207083.19 | E6: =$B6+SUMPRODUCT((Assumptions!$A$33:$A$34=$A6)*(Assumptions!$D$33:$D$34<=E$5)*Assumptions!$B$33:$B$34*Assumptions!$C$33:$C$34)/12 -> 207083.19 | F6: =$B6+SUMPRODUCT((Assumptions!$A$33:$A$34=$A6)*(Assumptions!$D$33:$D$34<=F$5)*Assumptions!$B$33:$B$34*Assumptions!$C$33:$C$34)/12 -> 214999.86 | G6: =$B6+SUMPRODUCT((Assumptions!$A$33:$A$34=$A6)*(Assumptions!$D$33:$D$34<=G$5)*Assumptions!$B$33:$B$34*Assumptions!$C$33:$C$34)/12 -> 214999.86 | H6: =$B6+SUMPRODUCT((Assumptions!$A$33:$A$34=$A6)*(Assumptions!$D$33:$D$34<=H$5)*Assumptions!$B$33:$B$34*Assumptions!$C$33:$C$34)/12 -> 214999.86 | I6: =$B6+SUMPRODUCT((Assumptions!$A$33:$A$34=$A6)*(Assumptions!$D$33:$D$34<=I$5)*Assumptions!$B$33:$B$34*Assumptions!$C$33:$C$34)/12 -> 214999.86 | J6: =$B6+SUMPRODUCT((Assumptions!$A$33:$A$34=$A6)*(Assumptions!$D$33:$D$34<=J$5)*Assumptions!$B$33:$B$34*Assumptions!$C$33:$C$34)/12 -> 214999.86 | ... N6: =$B6+SUMPRODUCT((Assumptions!$A$33:$A$34=$A6)*(Assumptions!$D$33:$D$34<=N$5)*Assumptions!$B$33:$B$34*Assumptions!$C$33:$C$34)/12 -> 214999.86 | O6: =SUM(C6:N6) -> 2556248.3
A7: Warehouse & Logistics | B7: =INDEX(Data_Base!$B$41:$B$44,MATCH($A7,Data_Base!$A$41:$A$44,0))/12*(1+INDEX(Assumptions!$B$26:$B$29,MATCH($A7,Assumptions!$A$26:$A$29,0))) -> 308631.66 | C7: =$B7+SUMPRODUCT((Assumptions!$A$33:$A$34=$A7)*(Assumptions!$D$33:$D$34<=C$5)*Assumptions!$B$33:$B$34*Assumptions!$C$33:$C$34)/12 -> 308631.66 | D7: =$B7+SUMPRODUCT((Assumptions!$A$33:$A$34=$A7)*(Assumptions!$D$33:$D$34<=D$5)*Assumptions!$B$33:$B$34*Assumptions!$C$33:$C$34)/12 -> 308631.66 | E7: =$B7+SUMPRODUCT((Assumptions!$A$33:$A$34=$A7)*(Assumptions!$D$33:$D$34<=E$5)*Assumptions!$B$33:$B$34*Assumptions!$C$33:$C$34)/12 -> 319964.99 | F7: =$B7+SUMPRODUCT((Assumptions!$A$33:$A$34=$A7)*(Assumptions!$D$33:$D$34<=F$5)*Assumptions!$B$33:$B$34*Assumptions!$C$33:$C$34)/12 -> 319964.99 | G7: =$B7+SUMPRODUCT((Assumptions!$A$33:$A$34=$A7)*(Assumptions!$D$33:$D$34<=G$5)*Assumptions!$B$33:$B$34*Assumptions!$C$33:$C$34)/12 -> 319964.99 | H7: =$B7+SUMPRODUCT((Assumptions!$A$33:$A$34=$A7)*(Assumptions!$D$33:$D$34<=H$5)*Assumptions!$B$33:$B$34*Assumptions!$C$33:$C$34)/12 -> 319964.99 | I7: =$B7+SUMPRODUCT((Assumptions!$A$33:$A$34=$A7)*(Assumptions!$D$33:$D$34<=I$5)*Assumptions!$B$33:$B$34*Assumptions!$C$33:$C$34)/12 -> 319964.99 | J7: =$B7+SUMPRODUCT((Assumptions!$A$33:$A$34=$A7)*(Assumptions!$D$33:$D$34<=J$5)*Assumptions!$B$33:$B$34*Assumptions!$C$33:$C$34)/12 -> 319964.99 | ... N7: =$B7+SUMPRODUCT((Assumptions!$A$33:$A$34=$A7)*(Assumptions!$D$33:$D$34<=N$5)*Assumptions!$B$33:$B$34*Assumptions!$C$33:$C$34)/12 -> 319964.99 | O7: =SUM(C7:N7) -> 3816913.3
A8: General & Admin | B8: =INDEX(Data_Base!$B$41:$B$44,MATCH($A8,Data_Base!$A$41:$A$44,0))/12*(1+INDEX(Assumptions!$B$26:$B$29,MATCH($A8,Assumptions!$A$26:$A$29,0))) -> 186244.22 | C8: =$B8+SUMPRODUCT((Assumptions!$A$33:$A$34=$A8)*(Assumptions!$D$33:$D$34<=C$5)*Assumptions!$B$33:$B$34*Assumptions!$C$33:$C$34)/12 -> 186244.22 | D8: =$B8+SUMPRODUCT((Assumptions!$A$33:$A$34=$A8)*(Assumptions!$D$33:$D$34<=D$5)*Assumptions!$B$33:$B$34*Assumptions!$C$33:$C$34)/12 -> 186244.22 | E8: =$B8+SUMPRODUCT((Assumptions!$A$33:$A$34=$A8)*(Assumptions!$D$33:$D$34<=E$5)*Assumptions!$B$33:$B$34*Assumptions!$C$33:$C$34)/12 -> 186244.22 | F8: =$B8+SUMPRODUCT((Assumptions!$A$33:$A$34=$A8)*(Assumptions!$D$33:$D$34<=F$5)*Assumptions!$B$33:$B$34*Assumptions!$C$33:$C$34)/12 -> 186244.22 | G8: =$B8+SUMPRODUCT((Assumptions!$A$33:$A$34=$A8)*(Assumptions!$D$33:$D$34<=G$5)*Assumptions!$B$33:$B$34*Assumptions!$C$33:$C$34)/12 -> 186244.22 | H8: =$B8+SUMPRODUCT((Assumptions!$A$33:$A$34=$A8)*(Assumptions!$D$33:$D$34<=H$5)*Assumptions!$B$33:$B$34*Assumptions!$C$33:$C$34)/12 -> 186244.22 | I8: =$B8+SUMPRODUCT((Assumptions!$A$33:$A$34=$A8)*(Assumptions!$D$33:$D$34<=I$5)*Assumptions!$B$33:$B$34*Assumptions!$C$33:$C$34)/12 -> 186244.22 | J8: =$B8+SUMPRODUCT((Assumptions!$A$33:$A$34=$A8)*(Assumptions!$D$33:$D$34<=J$5)*Assumptions!$B$33:$B$34*Assumptions!$C$33:$C$34)/12 -> 186244.22 | ... N8: =$B8+SUMPRODUCT((Assumptions!$A$33:$A$34=$A8)*(Assumptions!$D$33:$D$34<=N$5)*Assumptions!$B$33:$B$34*Assumptions!$C$33:$C$34)/12 -> 186244.22 | O8: =SUM(C8:N8) -> 2234930.6
A9: Technology | B9: =INDEX(Data_Base!$B$41:$B$44,MATCH($A9,Data_Base!$A$41:$A$44,0))/12*(1+INDEX(Assumptions!$B$26:$B$29,MATCH($A9,Assumptions!$A$26:$A$29,0))) -> 62291.024 | C9: =$B9+SUMPRODUCT((Assumptions!$A$33:$A$34=$A9)*(Assumptions!$D$33:$D$34<=C$5)*Assumptions!$B$33:$B$34*Assumptions!$C$33:$C$34)/12 -> 62291.024 | D9: =$B9+SUMPRODUCT((Assumptions!$A$33:$A$34=$A9)*(Assumptions!$D$33:$D$34<=D$5)*Assumptions!$B$33:$B$34*Assumptions!$C$33:$C$34)/12 -> 62291.024 | E9: =$B9+SUMPRODUCT((Assumptions!$A$33:$A$34=$A9)*(Assumptions!$D$33:$D$34<=E$5)*Assumptions!$B$33:$B$34*Assumptions!$C$33:$C$34)/12 -> 62291.024 | F9: =$B9+SUMPRODUCT((Assumptions!$A$33:$A$34=$A9)*(Assumptions!$D$33:$D$34<=F$5)*Assumptions!$B$33:$B$34*Assumptions!$C$33:$C$34)/12 -> 62291.024 | G9: =$B9+SUMPRODUCT((Assumptions!$A$33:$A$34=$A9)*(Assumptions!$D$33:$D$34<=G$5)*Assumptions!$B$33:$B$34*Assumptions!$C$33:$C$34)/12 -> 62291.024 | H9: =$B9+SUMPRODUCT((Assumptions!$A$33:$A$34=$A9)*(Assumptions!$D$33:$D$34<=H$5)*Assumptions!$B$33:$B$34*Assumptions!$C$33:$C$34)/12 -> 62291.024 | I9: =$B9+SUMPRODUCT((Assumptions!$A$33:$A$34=$A9)*(Assumptions!$D$33:$D$34<=I$5)*Assumptions!$B$33:$B$34*Assumptions!$C$33:$C$34)/12 -> 62291.024 | J9: =$B9+SUMPRODUCT((Assumptions!$A$33:$A$34=$A9)*(Assumptions!$D$33:$D$34<=J$5)*Assumptions!$B$33:$B$34*Assumptions!$C$33:$C$34)/12 -> 62291.024 | ... N9: =$B9+SUMPRODUCT((Assumptions!$A$33:$A$34=$A9)*(Assumptions!$D$33:$D$34<=N$5)*Assumptions!$B$33:$B$34*Assumptions!$C$33:$C$34)/12 -> 62291.024 | O9: =SUM(C9:N9) -> 747492.29
A10: Total V1 | C10: =SUM(C6:C9) -> 764250.09 | D10: =SUM(D6:D9) -> 764250.09 | E10: =SUM(E6:E9) -> 775583.43 | F10: =SUM(F6:F9) -> 783500.09 | G10: =SUM(G6:G9) -> 783500.09 | H10: =SUM(H6:H9) -> 783500.09 | I10: =SUM(I6:I9) -> 783500.09 | J10: =SUM(J6:J9) -> 783500.09 | ... O10: =SUM(O6:O9) -> 9355584.4
A12: V2 approved | B12: Base / month
